Workbook
Name A: 'TH KẾ TOÁN'!$E$11

Sheet CMC-ND1B-NĐ
A1: ='FRIT FV 090.540 - FTA'!#REF! -> #REF!
A2: ='FRIT FV 090.540 - FTA'!#REF! -> #REF! | K2: ='FRIT FV 090.540 - FTA'!#REF! -> #REF!
A3: THẺ KHO
D4: Tên hàng hóa: | E4: CMC-ND1B | I4: Mã hàng: | J4: CMC-NB1B-NĐ
B5: ='FRIT FV 090.540 - FTA'!#REF! -> #REF! | C5: ='FRIT FV 090.540 - FTA'!#REF! -> #REF! | D5: ='FRIT FV 090.540 - FTA'!#REF! -> #REF! | E5: 18 | F5: ='FRIT FV 090.540 - FTA'!#REF! -> #REF! | G5: ='FRIT FV 090.540 - FTA'!#REF! -> #REF! | H5: ='FRIT FV 090.540 - FTA'!#REF! -> #REF! | I5: ='FRIT FV 090.540 - FTA'!#REF! -> #REF!
L6: Đơn vị tính: Kg | M6: ='FRIT FV 090.540 - FTA'!#REF! -> #REF!
A7: STT | B7: NGÀY | C7: DIỄN GIẢI | D7: SL NHẬP KHO | F7: SL XUẤT KHO | H7: SL XUẤT TRUNG BÌNH | J7: SL TỒN | L7: SỐ NGÀY CÒN SỬ DỤNG | N7: ĐỘ ẨM
D8: Quy khô | E8: Thực tế | F8: Quy khô | G8: Quy ướt | H8: Quy khô | I8: Quy ướt | J8: Quy khô | K8: Quy ướt | L8: Quy khô | M8: Quy ướt
A9: Tồn đầu kì | D9: =J9 -> 0 | E9: =K9 -> 0 | F9: =F41 -> 0 | G9: =G41 -> 0 | J9: =K9-K9*N9 -> 0 | K9: 0
A10: 1 | B10: ='FRIT FV 090.540 - FTA'!B9 -> 46235 | C10: ='FRIT FV 090.540 - FTA'!C9 -> Không nhập - xuất | D10: =E10 -> 0 | G10: =F10 -> 0 | H10: =SUM($F$10:F10)/A10 -> 0 | I10: =SUM($G$10:G10)/A10 -> 0 | J10: =J9+D10-F10 -> 0 | K10: =K9+E10-G10 -> 0 | L10: =J10/H10 -> #DIV/0! | M10: =K10/I10 -> #DIV/0!
A11: 2 | B11: ='FRIT FV 090.540 - FTA'!B10 -> 46236 | C11: ='FRIT FV 090.540 - FTA'!C10 -> Không nhập - xuất | D11: =E11 -> 0 | G11: =F11 -> 0 | H11: =SUM($F$10:F11)/A11 -> 0 | I11: =SUM($G$10:G11)/A11 -> 0 | J11: =J10+D11-F11 -> 0 | K11: =K10+E11-G11 -> 0 | L11: =J11/H11 -> #DIV/0! | M11: =K11/I11 -> #DIV/0!
A12: 3 | B12: ='FRIT FV 090.540 - FTA'!B11 -> 46237 | C12: ='FRIT FV 090.540 - FTA'!C11 -> Không nhập - xuất | D12: =E12 -> 0 | G12: =F12 -> 0 | H12: =SUM($F$10:F12)/A12 -> 0 | I12: =SUM($G$10:G12)/A12 -> 0 | J12: =J11+D12-F12 -> 0 | K12: =K11+E12-G12 -> 0 | L12: =J12/H12 -> #DIV/0! | M12: =K12/I12 -> #DIV/0!
A13: 4 | B13: ='FRIT FV 090.540 - FTA'!B12 -> 46238 | C13: ='FRIT FV 090.540 - FTA'!C12 -> Không nhập - xuất | D13: =E13 -> 0 | G13: =F13 -> 0 | H13: =SUM($F$10:F13)/A13 -> 0 | I13: =SUM($G$10:G13)/A13 -> 0 | J13: =J12+D13-F13 -> 0 | K13: =K12+E13-G13 -> 0 | L13: =J13/H13 -> #DIV/0! | M13: =K13/I13 -> #DIV/0!
A14: 5 | B14: ='FRIT FV 090.540 - FTA'!B13 -> 46239 | C14: ='FRIT FV 090.540 - FTA'!C13 -> Không nhập - xuất | D14: =E14 -> 0 | G14: =F14 -> 0 | H14: =SUM($F$10:F14)/A14 -> 0 | I14: =SUM($G$10:G14)/A14 -> 0 | J14: =J13+D14-F14 -> 0 | K14: =K13+E14-G14 -> 0 | L14: =J14/H14 -> #DIV/0! | M14: =K14/I14 -> #DIV/0!
A15: 6 | B15: ='FRIT FV 090.540 - FTA'!B14 -> 46240 | C15: ='FRIT FV 090.540 - FTA'!C14 -> xuất | D15: =E15 -> 0 | G15: =F15 -> 0 | H15: =SUM($F$10:F15)/A15 -> 0 | I15: =SUM($G$10:G15)/A15 -> 0 | J15: =J14+D15-F15 -> 0 | K15: =K14+E15-G15 -> 0 | L15: =J15/H15 -> #DIV/0! | M15: =K15/I15 -> #DIV/0!
A16: 7 | B16: ='FRIT FV 090.540 - FTA'!B15 -> 46241 | C16: ='FRIT FV 090.540 - FTA'!C15 -> Không nhập - xuất | D16: =E16 -> 0 | G16: =F16 -> 0 | H16: =SUM($F$10:F16)/A16 -> 0 | I16: =SUM($G$10:G16)/A16 -> 0 | J16: =J15+D16-F16 -> 0 | K16: =K15+E16-G16 -> 0 | L16: =J16/H16 -> #DIV/0! | M16: =K16/I16 -> #DIV/0!
A17: 8 | B17: ='FRIT FV 090.540 - FTA'!B16 -> 46242 | C17: ='FRIT FV 090.540 - FTA'!C16 -> Không nhập - xuất | D17: =E17 -> 0 | G17: =F17 -> 0 | H17: =SUM($F$10:F17)/A17 -> 0 | I17: =SUM($G$10:G17)/A17 -> 0 | J17: =J16+D17-F17 -> 0 | K17: =K16+E17-G17 -> 0 | L17: =J17/H17 -> #DIV/0! | M17: =K17/I17 -> #DIV/0!
A18: 9 | B18: ='FRIT FV 090.540 - FTA'!B17 -> 46243 | C18: Không xuất | D18: =E18 -> 0 | G18: =F18 -> 0 | H18: =SUM($F$10:F18)/A18 -> 0 | I18: =SUM($G$10:G18)/A18 -> 0 | J18: =J17+D18-F18 -> 0 | K18: =K17+E18-G18 -> 0 | L18: =J18/H18 -> #DIV/0! | M18: =K18/I18 -> #DIV/0!
A19: 10 | B19: ='FRIT FV 090.540 - FTA'!B18 -> 46244 | C19: Không xuất | D19: =E19 -> 0 | G19: =F19 -> 0 | H19: =SUM($F$10:F19)/A19 -> 0 | I19: =SUM($G$10:G19)/A19 -> 0 | J19: =J18+D19-F19 -> 0 | K19: =K18+E19-G19 -> 0 | L19: =J19/H19 -> #DIV/0! | M19: =K19/I19 -> #DIV/0!
A20: 11 | B20: ='FRIT FV 090.540 - FTA'!B19 -> 46245 | C20: Không xuất | D20: =E20 -> 0 | G20: =F20 -> 0 | H20: =SUM($F$10:F20)/A20 -> 0 | I20: =SUM($G$10:G20)/A20 -> 0 | J20: =J19+D20-F20 -> 0 | K20: =K19+E20-G20 -> 0 | L20: =J20/H20 -> #DIV/0! | M20: =K20/I20 -> #DIV/0!
A21: 12 | B21: ='FRIT FV 090.540 - FTA'!B20 -> 46246 | C21: Không xuất | D21: =E21 -> 0 | G21: =F21 -> 0 | H21: =SUM($F$10:F21)/A21 -> 0 | I21: =SUM($G$10:G21)/A21 -> 0 | J21: =J20+D21-F21 -> 0 | K21: =K20+E21-G21 -> 0 | L21: =J21/H21 -> #DIV/0! | M21: =K21/I21 -> #DIV/0!
A22: 13 | B22: ='FRIT FV 090.540 - FTA'!B21 -> 46247 | C22: Không xuất | D22: =E22 -> 0 | G22: =F22 -> 0 | H22: =SUM($F$10:F22)/A22 -> 0 | I22: =SUM($G$10:G22)/A22 -> 0 | J22: =J21+D22-F22 -> 0 | K22: =K21+E22-G22 -> 0 | L22: =J22/H22 -> #DIV/0! | M22: =K22/I22 -> #DIV/0!
A23: 14 | B23: ='FRIT FV 090.540 - FTA'!B22 -> 46248 | C23: Không xuất | D23: =E23 -> 0 | G23: =F23 -> 0 | H23: =SUM($F$10:F23)/A23 -> 0 | I23: =SUM($G$10:G23)/A23 -> 0 | J23: =J22+D23-F23 -> 0 | K23: =K22+E23-G23 -> 0 | L23: =J23/H23 -> #DIV/0! | M23: =K23/I23 -> #DIV/0!
A24: 15 | B24: ='FRIT FV 090.540 - FTA'!B23 -> 46249 | C24: Không xuất | D24: =E24 -> 0 | G24: =F24 -> 0 | H24: =SUM($F$10:F24)/A24 -> 0 | I24: =SUM($G$10:G24)/A24 -> 0 | J24: =J23+D24-F24 -> 0 | K24: =K23+E24-G24 -> 0 | L24: =J24/H24 -> #DIV/0! | M24: =K24/I24 -> #DIV/0!
A25: 16 | B25: ='FRIT FV 090.540 - FTA'!B24 -> 46250 | C25: Không xuất | D25: =E25 -> 0 | G25: =F25 -> 0 | H25: =SUM($F$10:F25)/A25 -> 0 | I25: =SUM($G$10:G25)/A25 -> 0 | J25: =J24+D25-F25 -> 0 | K25: =K24+E25-G25 -> 0 | L25: =J25/H25 -> #DIV/0! | M25: =K25/I25 -> #DIV/0!
A26: 17 | B26: ='FRIT FV 090.540 - FTA'!B25 -> 46251 | C26: Không xuất | D26: =E26 -> 0 | G26: =F26 -> 0 | H26: =SUM($F$10:F26)/A26 -> 0 | I26: =SUM($G$10:G26)/A26 -> 0 | J26: =J25+D26-F26 -> 0 | K26: =K25+E26-G26 -> 0 | L26: =J26/H26 -> #DIV/0! | M26: =K26/I26 -> #DIV/0!
A27: 18 | B27: ='FRIT FV 090.540 - FTA'!B26 -> 46252 | C27: Không xuất | D27: =E27 -> 0 | G27: =F27 -> 0 | H27: =SUM($F$10:F27)/A27 -> 0 | I27: =SUM($G$10:G27)/A27 -> 0 | J27: =J26+D27-F27 -> 0 | K27: =K26+E27-G27 -> 0 | L27: =J27/H27 -> #DIV/0! | M27: =K27/I27 -> #DIV/0!
A28: 19 | B28: ='FRIT FV 090.540 - FTA'!B27 -> 46253 | C28: Không xuất | D28: =E28 -> 0 | G28: =F28 -> 0 | H28: =SUM($F$10:F28)/A28 -> 0 | I28: =SUM($G$10:G28)/A28 -> 0 | J28: =J27+D28-F28 -> 0 | K28: =K27+E28-G28 -> 0 | L28: =J28/H28 -> #DIV/0! | M28: =K28/I28 -> #DIV/0!
A29: 20 | B29: ='FRIT FV 090.540 - FTA'!B28 -> 46254 | C29: Không xuất | D29: =E29 -> 0 | G29: =F29 -> 0 | H29: =SUM($F$10:F29)/A29 -> 0 | I29: =SUM($G$10:G29)/A29 -> 0 | J29: =J28+D29-F29 -> 0 | K29: =K28+E29-G29 -> 0 | L29: =J29/H29 -> #DIV/0! | M29: =K29/I29 -> #DIV/0!
... A40: 31 | B40: ='FRIT FV 090.540 - FTA'!B39 -> 46265 | C40: Không xuất | D40: =E40 -> 0 | G40: =F40 -> 0 | H40: =SUM($F$10:F40)/A40 -> 0 | I40: =SUM($G$10:G40)/A40 -> 0 | J40: =J39+D40-F40 -> 0 | K40: =K39+E40-G40 -> 0 | L40: =J40/H40 -> #DIV/0! | M40: =K40/I40 -> #DIV/0!
A41: Cộng nhập xuất | D41: =SUM(D10:D40) -> 0 | E41: =SUM(E10:E40) -> 0 | F41: =SUM(F10:F40) -> 0 | G41: =SUM(G10:G40) -> 0 | J41: =J40 -> 0 | K41: =K40 -> 0
A42: Tổng cộng | D42: =D9+D41 -> 0 | E42: =E9+E41 -> 0 | F42: =F41 -> 0 | G42: =G41 -> 0 | J42: =D42-F42 -> 0 | K42: =E42-G42 -> 0
K44: Người Lập
K48: Mai Thúy Hoa

Sheet QUARTZ VH004-FTA
A1: ='FRIT FV 090.540 - FTA'!#REF! -> #REF!
A2: ='FRIT FV 090.540 - FTA'!#REF! -> #REF! | K2: ='FRIT FV 090.540 - FTA'!#REF! -> #REF!
A3: THẺ KHO
D4: Tên hàng hóa: | E4: THẠCH ANH (QUARTZ) | I4: Mã hàng: | J4: SILICA VH004-FTA
B5: ='FRIT FV 090.540 - FTA'!#REF! -> #REF! | C5: ='FRIT FV 090.540 - FTA'!#REF! -> #REF! | D5: ='FRIT FV 090.540 - FTA'!#REF! -> #REF! | E5: ='FRIT FV 090.540 - FTA'!#REF! -> #REF! | F5: ='FRIT FV 090.540 - FTA'!#REF! -> #REF! | G5: ='FRIT FV 090.540 - FTA'!#REF! -> #REF! | H5: ='FRIT FV 090.540 - FTA'!#REF! -> #REF! | I5: ='FRIT FV 090.540 - FTA'!#REF! -> #REF!
L6: Đơn vị tính: Kg | M6: ='FRIT FV 090.540 - FTA'!#REF! -> #REF!
A7: STT | B7: NGÀY | C7: DIỄN GIẢI | D7: SL NHẬP KHO | F7: SL XUẤT KHO | H7: SL XUẤT TRUNG BÌNH | J7: SL TỒN | L7: SỐ NGÀY TRUNG BÌNH CÒN SỬ DỤNG | N7: ĐỘ ẨM
D8: Quy khô | E8: Thực tế | F8: Quy khô | G8: Quy ướt | H8: Quy khô | I8: Quy ướt | J8: Quy khô | K8: Quy ướt | L8: Quy khô | M8: Quy ướt
A9: Tồn đầu kì | D9: =J9 -> 0 | E9: =K9 -> 0 | F9: =F41 -> 0 | G9: =G41 -> 0 | J9: =K9-K9*N9 -> 0 | K9: 0
A10: 1 | B10: ='FRIT FV 090.540 - FTA'!B9 -> 46235 | C10: KHÔNG PHÁT SINH | D10: =E10-(E10*N10) -> 0 | G10: =F10 -> 0 | H10: =SUM($F$10:F10)/A10 -> 0 | I10: =SUM($G$10:G10)/A10 -> 0 | J10: =J9+D10-F10 -> 0 | K10: =K9+E10-G10 -> 0 | L10: =J10/H10 -> #DIV/0! | M10: =K10/I10 -> #DIV/0!
A11: 2 | B11: ='FRIT FV 090.540 - FTA'!B10 -> 46236 | C11: KHÔNG PHÁT SINH | D11: =E11-(E11*N11) -> 0 | G11: =F11 -> 0 | H11: =SUM($F$10:F11)/A11 -> 0 | I11: =SUM($G$10:G11)/A11 -> 0 | J11: =J10+D11-F11 -> 0 | K11: =K10+E11-G11 -> 0 | L11: =J11/H11 -> #DIV/0! | M11: =K11/I11 -> #DIV/0!
A12: 3 | B12: ='FRIT FV 090.540 - FTA'!B11 -> 46237 | C12: KHÔNG PHÁT SINH | D12: =E12-(E12*N12) -> 0 | G12: =F12 -> 0 | H12: =SUM($F$10:F12)/A12 -> 0 | I12: =SUM($G$10:G12)/A12 -> 0 | J12: =J11+D12-F12 -> 0 | K12: =K11+E12-G12 -> 0 | L12: =J12/H12 -> #DIV/0! | M12: =K12/I12 -> #DIV/0!
A13: 4 | B13: ='FRIT FV 090.540 - FTA'!B12 -> 46238 | C13: KHÔNG PHÁT SINH | D13: =E13-(E13*N13) -> 0 | G13: =F13 -> 0 | H13: =SUM($F$10:F13)/A13 -> 0 | I13: =SUM($G$10:G13)/A13 -> 0 | J13: =J12+D13-F13 -> 0 | K13: =K12+E13-G13 -> 0 | L13: =J13/H13 -> #DIV/0! | M13: =K13/I13 -> #DIV/0!
A14: 5 | B14: ='FRIT FV 090.540 - FTA'!B13 -> 46239 | C14: KHÔNG PHÁT SINH | D14: =E14-(E14*N14) -> 0 | G14: =F14 -> 0 | H14: =SUM($F$10:F14)/A14 -> 0 | I14: =SUM($G$10:G14)/A14 -> 0 | J14: =J13+D14-F14 -> 0 | K14: =K13+E14-G14 -> 0 | L14: =J14/H14 -> #DIV/0! | M14: =K14/I14 -> #DIV/0!
A15: 6 | B15: ='FRIT FV 090.540 - FTA'!B14 -> 46240 | C15: KHÔNG PHÁT SINH | D15: =E15-(E15*N15) -> 0 | G15: =F15 -> 0 | H15: =SUM($F$10:F15)/A15 -> 0 | I15: =SUM($G$10:G15)/A15 -> 0 | J15: =J14+D15-F15 -> 0 | K15: =K14+E15-G15 -> 0 | L15: =J15/H15 -> #DIV/0! | M15: =K15/I15 -> #DIV/0!
A16: 7 | B16: ='FRIT FV 090.540 - FTA'!B15 -> 46241 | C16: KHÔNG PHÁT SINH | D16: =E16-(E16*N16) -> 0 | G16: =F16 -> 0 | H16: =SUM($F$10:F16)/A16 -> 0 | I16: =SUM($G$10:G16)/A16 -> 0 | J16: =J15+D16-F16 -> 0 | K16: =K15+E16-G16 -> 0 | L16: =J16/H16 -> #DIV/0! | M16: =K16/I16 -> #DIV/0!
A17: 8 | B17: ='FRIT FV 090.540 - FTA'!B16 -> 46242 | C17: KHÔNG PHÁT SINH | D17: =E17-(E17*N17) -> 0 | G17: =F17 -> 0 | H17: =SUM($F$10:F17)/A17 -> 0 | I17: =SUM($G$10:G17)/A17 -> 0 | J17: =J16+D17-F17 -> 0 | K17: =K16+E17-G17 -> 0 | L17: =J17/H17 -> #DIV/0! | M17: =K17/I17 -> #DIV/0!
A18: 9 | B18: ='FRIT FV 090.540 - FTA'!B17 -> 46243 | C18: KHÔNG PHÁT SINH | D18: =E18-(E18*N18) -> 0 | G18: =F18 -> 0 | H18: =SUM($F$10:F18)/A18 -> 0 | I18: =SUM($G$10:G18)/A18 -> 0 | J18: =J17+D18-F18 -> 0 | K18: =K17+E18-G18 -> 0 | L18: =J18/H18 -> #DIV/0! | M18: =K18/I18 -> #DIV/0!
A19: 10 | B19: ='FRIT FV 090.540 - FTA'!B18 -> 46244 | C19: KHÔNG PHÁT SINH | D19: =E19-(E19*N19) -> 0 | G19: =F19 -> 0 | H19: =SUM($F$10:F19)/A19 -> 0 | I19: =SUM($G$10:G19)/A19 -> 0 | J19: =J18+D19-F19 -> 0 | K19: =K18+E19-G19 -> 0 | L19: =J19/H19 -> #DIV/0! | M19: =K19/I19 -> #DIV/0!
A20: 11 | B20: ='FRIT FV 090.540 - FTA'!B19 -> 46245 | C20: KHÔNG PHÁT SINH | D20: =E20-(E20*N20) -> 0 | G20: =F20 -> 0 | H20: =SUM($F$10:F20)/A20 -> 0 | I20: =SUM($G$10:G20)/A20 -> 0 | J20: =J19+D20-F20 -> 0 | K20: =K19+E20-G20 -> 0 | L20: =J20/H20 -> #DIV/0! | M20: =K20/I20 -> #DIV/0!
A21: 12 | B21: ='FRIT FV 090.540 - FTA'!B20 -> 46246 | C21: KHÔNG PHÁT SINH | D21: =E21-(E21*N21) -> 0 | G21: =F21 -> 0 | H21: =SUM($F$10:F21)/A21 -> 0 | I21: =SUM($G$10:G21)/A21 -> 0 | J21: =J20+D21-F21 -> 0 | K21: =K20+E21-G21 -> 0 | L21: =J21/H21 -> #DIV/0! | M21: =K21/I21 -> #DIV/0!
... A40: 31 | B40: ='FRIT FV 090.540 - FTA'!B39 -> 46265 | C40: KHÔNG PHÁT SINH | D40: =E40-(E40*N40) -> 0 | G40: =F40 -> 0 | H40: =SUM($F$10:F40)/A40 -> 0 | I40: =SUM($G$10:G40)/A40 -> 0 | J40: =J39+D40-F40 -> 0 | K40: =K39+E40-G40 -> 0 | L40: =J40/H40 -> #DIV/0! | M40: =K40/I40 -> #DIV/0!
A41: Cộng nhập xuất | D41: =SUM(D10:D40) -> 0 | E41: =SUM(E10:E40) -> 0 | F41: =F40 -> 0 | G41: =G40 -> 0 | J41: =J40 -> 0 | K41: =K40 -> 0
A42: Tổng cộng | D42: =D9+D41 -> 0 | E42: =E9+E41 -> 0 | F42: =F41 -> 0 | G42: =G41 -> 0 | J42: =D42-F42 -> 0 | K42: =E42-G42 -> 0
K44: Người Lập
K48: Mai Thúy Hoa

Sheet FRIT FO102-FHU
A1: ='FRIT FV 090.540 - FTA'!#REF! -> #REF!
A2: ='FRIT FV 090.540 - FTA'!#REF! -> #REF! | K2: ='FRIT FV 090.540 - FTA'!#REF! -> #REF!
A3: THẺ KHO
D4: Tên hàng hóa: | E4: FRIT | I4: Mã hàng: | J4: FRIT FO102-FHU
B5: ='FRIT FV 090.540 - FTA'!#REF! -> #REF! | C5: ='FRIT FV 090.540 - FTA'!#REF! -> #REF! | D5: ='FRIT FV 090.540 - FTA'!#REF! -> #REF! | E5: ='FRIT FV 090.540 - FTA'!#REF! -> #REF! | F5: ='FRIT FV 090.540 - FTA'!#REF! -> #REF! | G5: ='FRIT FV 090.540 - FTA'!#REF! -> #REF! | H5: ='FRIT FV 090.540 - FTA'!#REF! -> #REF! | I5: ='FRIT FV 090.540 - FTA'!#REF! -> #REF!
L6: Đơn vị tính: Kg | M6: ='FRIT FV 090.540 - FTA'!#REF! -> #REF!
A7: STT | B7: NGÀY | C7: DIỄN GIẢI | D7: SL NHẬP KHO | F7: SL XUẤT KHO | H7: SL XUẤT TRUNG BÌNH | J7: SL TỒN | L7: SỐ NGÀY TRUNG BÌNH CÒN SỬ DỤNG | N7: ĐỘ ẨM
D8: Quy khô | E8: Thực tế | F8: Quy khô | G8: Quy ướt | H8: Quy khô | I8: Quy ướt | J8: Quy khô | K8: Quy ướt | L8: Quy khô | M8: Quy ướt
A9: Tồn đầu kì | D9: =J9 -> 0 | E9: =K9 -> 0 | F9: =F41 -> 0 | G9: =G41 -> 0 | J9: =K9-K9*N9 -> 0 | K9: 0 | N9: 0.012
A10: 1 | B10: ='FRIT FV 090.540 - FTA'!B9 -> 46235 | C10: ='FRIT FV 090.540 - FTA'!C9 -> Không nhập - xuất | D10: =E10-(E10*N10) -> 0 | H10: =SUM($F$10:F10)/A10 -> 0 | I10: =SUM($G$10:G10)/A10 -> 0 | J10: =J9+D10-F10 -> 0 | K10: =K9+E10-G10 -> 0 | L10: =J10/H10 -> #DIV/0! | M10: =K10/I10 -> #DIV/0!
A11: 2 | B11: ='FRIT FV 090.540 - FTA'!B10 -> 46236 | C11: ='FRIT FV 090.540 - FTA'!C10 -> Không nhập - xuất | D11: =E11-(E11*N11) -> 0 | H11: =SUM($F$10:F11)/A11 -> 0 | I11: =SUM($G$10:G11)/A11 -> 0 | J11: =J10+D11-F11 -> 0 | K11: =K10+E11-G11 -> 0 | L11: =J11/H11 -> #DIV/0! | M11: =K11/I11 -> #DIV/0!
A12: 3 | B12: ='FRIT FV 090.540 - FTA'!B11 -> 46237 | C12: ='FRIT FV 090.540 - FTA'!C11 -> Không nhập - xuất | D12: =E12-(E12*N12) -> 0 | H12: =SUM($F$10:F12)/A12 -> 0 | I12: =SUM($G$10:G12)/A12 -> 0 | J12: =J11+D12-F12 -> 0 | K12: =K11+E12-G12 -> 0 | L12: =J12/H12 -> #DIV/0! | M12: =K12/I12 -> #DIV/0!
A13: 4 | B13: ='FRIT FV 090.540 - FTA'!B12 -> 46238 | C13: ='FRIT FV 090.540 - FTA'!C12 -> Không nhập - xuất | D13: =E13-(E13*N13) -> 0 | H13: =SUM($F$10:F13)/A13 -> 0 | I13: =SUM($G$10:G13)/A13 -> 0 | J13: =J12+D13-F13 -> 0 | K13: =K12+E13-G13 -> 0 | L13: =J13/H13 -> #DIV/0! | M13: =K13/I13 -> #DIV/0!
A14: 5 | B14: ='FRIT FV 090.540 - FTA'!B13 -> 46239 | C14: ='FRIT FV 090.540 - FTA'!C13 -> Không nhập - xuất | D14: =E14-(E14*N14) -> 0 | H14: =SUM($F$10:F14)/A14 -> 0 | I14: =SUM($G$10:G14)/A14 -> 0 | J14: =J13+D14-F14 -> 0 | K14: =K13+E14-G14 -> 0 | L14: =J14/H14 -> #DIV/0! | M14: =K14/I14 -> #DIV/0!
A15: 6 | B15: ='FRIT FV 090.540 - FTA'!B14 -> 46240 | C15: ='FRIT FV 090.540 - FTA'!C14 -> xuất | D15: =E15-(E15*N15) -> 0 | H15: =SUM($F$10:F15)/A15 -> 0 | I15: =SUM($G$10:G15)/A15 -> 0 | J15: =J14+D15-F15 -> 0 | K15: =K14+E15-G15 -> 0 | L15: =J15/H15 -> #DIV/0! | M15: =K15/I15 -> #DIV/0!
A16: 7 | B16: ='FRIT FV 090.540 - FTA'!B15 -> 46241 | C16: ='FRIT FV 090.540 - FTA'!C15 -> Không nhập - xuất | D16: =E16-(E16*N16) -> 0 | H16: =SUM($F$10:F16)/A16 -> 0 | I16: =SUM($G$10:G16)/A16 -> 0 | J16: =J15+D16-F16 -> 0 | K16: =K15+E16-G16 -> 0 | L16: =J16/H16 -> #DIV/0! | M16: =K16/I16 -> #DIV/0!
A17: 8 | B17: ='FRIT FV 090.540 - FTA'!B16 -> 46242 | C17: ='FRIT FV 090.540 - FTA'!C16 -> Không nhập - xuất | D17: =E17-(E17*N17) -> 0 | H17: =SUM($F$10:F17)/A17 -> 0 | I17: =SUM($G$10:G17)/A17 -> 0 | J17: =J16+D17-F17 -> 0 | K17: =K16+E17-G17 -> 0 | L17: =J17/H17 -> #DIV/0! | M17: =K17/I17 -> #DIV/0!
A18: 9 | B18: ='FRIT FV 090.540 - FTA'!B17 -> 46243 | C18: ='FRIT FV 090.540 - FTA'!C17 -> Không nhập - xuất | D18: =E18-(E18*N18) -> 0 | H18: =SUM($F$10:F18)/A18 -> 0 | I18: =SUM($G$10:G18)/A18 -> 0 | J18: =J17+D18-F18 -> 0 | K18: =K17+E18-G18 -> 0 | L18: =J18/H18 -> #DIV/0! | M18: =K18/I18 -> #DIV/0!
A19: 10 | B19: ='FRIT FV 090.540 - FTA'!B18 -> 46244 | C19: ='FRIT FV 090.540 - FTA'!C18 -> xuất | D19: =E19-(E19*N19) -> 0 | H19: =SUM($F$10:F19)/A19 -> 0 | I19: =SUM($G$10:G19)/A19 -> 0 | J19: =J18+D19-F19 -> 0 | K19: =K18+E19-G19 -> 0 | L19: =J19/H19 -> #DIV/0! | M19: =K19/I19 -> #DIV/0!
A20: 11 | B20: ='FRIT FV 090.540 - FTA'!B19 -> 46245 | C20: ='FRIT FV 090.540 - FTA'!C19 -> xuất | D20: =E20-(E20*N20) -> 0 | H20: =SUM($F$10:F20)/A20 -> 0 | I20: =SUM($G$10:G20)/A20 -> 0 | J20: =J19+D20-F20 -> 0 | K20: =K19+E20-G20 -> 0 | L20: =J20/H20 -> #DIV/0! | M20: =K20/I20 -> #DIV/0!
A21: 12 | B21: ='FRIT FV 090.540 - FTA'!B20 -> 46246 | C21: ='FRIT FV 090.540 - FTA'!C20 -> xuất | D21: =E21-(E21*N21) -> 0 | H21: =SUM($F$10:F21)/A21 -> 0 | I21: =SUM($G$10:G21)/A21 -> 0 | J21: =J20+D21-F21 -> 0 | K21: =K20+E21-G21 -> 0 | L21: =J21/H21 -> #DIV/0! | M21: =K21/I21 -> #DIV/0!
... A40: 31 | B40: ='FRIT FV 090.540 - FTA'!B39 -> 46265 | C40: ='FRIT FV 090.540 - FTA'!C39 -> Không nhập - xuất | D40: =E40-(E40*N40) -> 0 | H40: =SUM($F$10:F40)/A40 -> 0 | I40: =SUM($G$10:G40)/A40 -> 0 | J40: =J39+D40-F40 -> 0 | K40: =K39+E40-G40 -> 0 | L40: =J40/H40 -> #DIV/0! | M40: =K40/I40 -> #DIV/0!
A41: Cộng nhập xuất | D41: =SUM(D10:D40) -> 0 | E41: =SUM(E10:E40) -> 0 | F41: =SUM(F10:F40) -> 0 | G41: =SUM(G10:G40) -> 0 | J41: =J40 -> 0 | K41: =K40 -> 0
A42: Tổng cộng | D42: =D9+D41 -> 0 | E42: =E9+E41 -> 0 | F42: =F41 -> 0 | G42: =G41 -> 0 | J42: =D42-F42 -> 0 | K42: =E42-G42 -> 0
K43: Người Lập
K47: Mai Thúy Hoa

Sheet ZIRCON K1#
A1: ='FRIT FV 090.540 - FTA'!#REF! -> #REF!
A2: ='FRIT FV 090.540 - FTA'!#REF! -> #REF! | K2: ='FRIT FV 090.540 - FTA'!#REF! -> #REF!
A3: THẺ KHO
D4: Tên hàng hóa: | E4: ZIRCON | I4: Mã hàng: | J4: ZIRCON K1#-
B5: ='FRIT FV 090.540 - FTA'!#REF! -> #REF! | C5: ='FRIT FV 090.540 - FTA'!#REF! -> #REF! | D5: ='FRIT FV 090.540 - FTA'!#REF! -> #REF! | E5: ='FRIT FV 090.540 - FTA'!#REF! -> #REF! | F5: ='FRIT FV 090.540 - FTA'!#REF! -> #REF! | G5: ='FRIT FV 090.540 - FTA'!#REF! -> #REF! | H5: ='FRIT FV 090.540 - FTA'!#REF! -> #REF! | I5: ='FRIT FV 090.540 - FTA'!#REF! -> #REF!
L6: Đơn vị tính: Kg | M6: ='FRIT FV 090.540 - FTA'!#REF! -> #REF!
A7: STT | B7: NGÀY | C7: DIỄN GIẢI | D7: SL NHẬP KHO | F7: SL XUẤT KHO | H7: SL XUẤT TRUNG BÌNH | J7: SL TỒN | L7: SỐ NGÀY CÒN SỬ DỤNG
D8: Quy khô | E8: Thực tế | F8: Quy khô | G8: Quy ướt | H8: Quy khô | I8: Quy ướt | J8: Quy khô | K8: Quy ướt | L8: Quy khô | M8: Quy ướt
A9: Tồn đầu kì | D9: =J9 -> 0 | E9: =K9 -> 0 | F9: =F41 -> 0 | G9: =G41 -> 0 | J9: =K9 -> 0 | K9: 0
A10: 1 | B10: ='FRIT FV 090.540 - FTA'!B9 -> 46235 | C10: ='FRIT FV 090.540 - FTA'!C9 -> Không nhập - xuất | G10: =F10 -> 0 | H10: =SUM($F$10:F10)/A10 -> 0 | I10: =SUM($G$10:G10)/A10 -> 0 | J10: =J9+D10-F10 -> 0 | K10: =K9+E10-G10 -> 0 | L10: =J10/H10 -> #DIV/0! | M10: =K10/I10 -> #DIV/0!
A11: 2 | B11: ='FRIT FV 090.540 - FTA'!B10 -> 46236 | C11: ='FRIT FV 090.540 - FTA'!C10 -> Không nhập - xuất | G11: =F11 -> 0 | H11: =SUM($F$10:F11)/A11 -> 0 | I11: =SUM($G$10:G11)/A11 -> 0 | J11: =J10+D11-F11 -> 0 | K11: =K10+E11-G11 -> 0 | L11: =J11/H11 -> #DIV/0! | M11: =K11/I11 -> #DIV/0!
A12: 3 | B12: ='FRIT FV 090.540 - FTA'!B11 -> 46237 | C12: ='FRIT FV 090.540 - FTA'!C11 -> Không nhập - xuất | G12: =F12 -> 0 | H12: =SUM($F$10:F12)/A12 -> 0 | I12: =SUM($G$10:G12)/A12 -> 0 | J12: =J11+D12-F12 -> 0 | K12: =K11+E12-G12 -> 0 | L12: =J12/H12 -> #DIV/0! | M12: =K12/I12 -> #DIV/0!
A13: 4 | B13: ='FRIT FV 090.540 - FTA'!B12 -> 46238 | C13: ='FRIT FV 090.540 - FTA'!C12 -> Không nhập - xuất | G13: =F13 -> 0 | H13: =SUM($F$10:F13)/A13 -> 0 | I13: =SUM($G$10:G13)/A13 -> 0 | J13: =J12+D13-F13 -> 0 | K13: =K12+E13-G13 -> 0 | L13: =J13/H13 -> #DIV/0! | M13: =K13/I13 -> #DIV/0!
A14: 5 | B14: ='FRIT FV 090.540 - FTA'!B13 -> 46239 | C14: ='FRIT FV 090.540 - FTA'!C13 -> Không nhập - xuất | G14: =F14 -> 0 | H14: =SUM($F$10:F14)/A14 -> 0 | I14: =SUM($G$10:G14)/A14 -> 0 | J14: =J13+D14-F14 -> 0 | K14: =K13+E14-G14 -> 0 | L14: =J14/H14 -> #DIV/0! | M14: =K14/I14 -> #DIV/0!
A15: 6 | B15: ='FRIT FV 090.540 - FTA'!B14 -> 46240 | C15: ='FRIT FV 090.540 - FTA'!C14 -> xuất | G15: =F15 -> 0 | H15: =SUM($F$10:F15)/A15 -> 0 | I15: =SUM($G$10:G15)/A15 -> 0 | J15: =J14+D15-F15 -> 0 | K15: =K14+E15-G15 -> 0 | L15: =J15/H15 -> #DIV/0! | M15: =K15/I15 -> #DIV/0!
A16: 7 | B16: ='FRIT FV 090.540 - FTA'!B15 -> 46241 | C16: ='FRIT FV 090.540 - FTA'!C15 -> Không nhập - xuất | G16: =F16 -> 0 | H16: =SUM($F$10:F16)/A16 -> 0 | I16: =SUM($G$10:G16)/A16 -> 0 | J16: =J15+D16-F16 -> 0 | K16: =K15+E16-G16 -> 0 | L16: =J16/H16 -> #DIV/0! | M16: =K16/I16 -> #DIV/0!
A17: 8 | B17: ='FRIT FV 090.540 - FTA'!B16 -> 46242 | C17: ='FRIT FV 090.540 - FTA'!C16 -> Không nhập - xuất | G17: =F17 -> 0 | H17: =SUM($F$10:F17)/A17 -> 0 | I17: =SUM($G$10:G17)/A17 -> 0 | J17: =J16+D17-F17 -> 0 | K17: =K16+E17-G17 -> 0 | L17: =J17/H17 -> #DIV/0! | M17: =K17/I17 -> #DIV/0!
A18: 9 | B18: ='FRIT FV 090.540 - FTA'!B17 -> 46243 | C18: =C10 -> Không nhập - xuất | G18: =F18 -> 0 | H18: =SUM($F$10:F18)/A18 -> 0 | I18: =SUM($G$10:G18)/A18 -> 0 | J18: =J17+D18-F18 -> 0 | K18: =K17+E18-G18 -> 0 | L18: =J18/H18 -> #DIV/0! | M18: =K18/I18 -> #DIV/0!
A19: 10 | B19: ='FRIT FV 090.540 - FTA'!B18 -> 46244 | C19: ='FRIT FV 090.540 - FTA'!C18 -> xuất | G19: =F19 -> 0 | H19: =SUM($F$10:F19)/A19 -> 0 | I19: =SUM($G$10:G19)/A19 -> 0 | J19: =J18+D19-F19 -> 0 | K19: =K18+E19-G19 -> 0 | L19: =J19/H19 -> #DIV/0! | M19: =K19/I19 -> #DIV/0!
A20: 11 | B20: ='FRIT FV 090.540 - FTA'!B19 -> 46245 | C20: ='FRIT FV 090.540 - FTA'!C19 -> xuất | G20: =F20 -> 0 | H20: =SUM($F$10:F20)/A20 -> 0 | I20: =SUM($G$10:G20)/A20 -> 0 | J20: =J19+D20-F20 -> 0 | K20: =K19+E20-G20 -> 0 | L20: =J20/H20 -> #DIV/0! | M20: =K20/I20 -> #DIV/0!
A21: 12 | B21: ='FRIT FV 090.540 - FTA'!B20 -> 46246 | C21: ='FRIT FV 090.540 - FTA'!C20 -> xuất | G21: =F21 -> 0 | H21: =SUM($F$10:F21)/A21 -> 0 | I21: =SUM($G$10:G21)/A21 -> 0 | J21: =J20+D21-F21 -> 0 | K21: =K20+E21-G21 -> 0 | L21: =J21/H21 -> #DIV/0! | M21: =K21/I21 -> #DIV/0!
A22: 13 | B22: ='FRIT FV 090.540 - FTA'!B21 -> 46247 | C22: Xuất | G22: =F22 -> 0 | H22: =SUM($F$10:F22)/A22 -> 0 | I22: =SUM($G$10:G22)/A22 -> 0 | J22: =J21+D22-F22 -> 0 | K22: =K21+E22-G22 -> 0 | L22: =J22/H22 -> #DIV/0! | M22: =K22/I22 -> #DIV/0!
A23: 14 | B23: ='FRIT FV 090.540 - FTA'!B22 -> 46248 | C23: =C10 -> Không nhập - xuất | G23: =F23 -> 0 | H23: =SUM($F$10:F23)/A23 -> 0 | I23: =SUM($G$10:G23)/A23 -> 0 | J23: =J22+D23-F23 -> 0 | K23: =K22+E23-G23 -> 0 | L23: =J23/H23 -> #DIV/0! | M23: =K23/I23 -> #DIV/0!
A24: 15 | B24: ='FRIT FV 090.540 - FTA'!B23 -> 46249 | C24: ='FRIT FV 090.540 - FTA'!C23 -> xuất | G24: =F24 -> 0 | H24: =SUM($F$10:F24)/A24 -> 0 | I24: =SUM($G$10:G24)/A24 -> 0 | J24: =J23+D24-F24 -> 0 | K24: =K23+E24-G24 -> 0 | L24: =J24/H24 -> #DIV/0! | M24: =K24/I24 -> #DIV/0!
A25: 16 | B25: ='FRIT FV 090.540 - FTA'!B24 -> 46250 | C25: ='FRIT FV 090.540 - FTA'!C24 -> xuất | G25: =F25 -> 0 | H25: =SUM($F$10:F25)/A25 -> 0 | I25: =SUM($G$10:G25)/A25 -> 0 | J25: =J24+D25-F25 -> 0 | K25: =K24+E25-G25 -> 0 | L25: =J25/H25 -> #DIV/0! | M25: =K25/I25 -> #DIV/0!
A26: 17 | B26: ='FRIT FV 090.540 - FTA'!B25 -> 46251 | C26: ='FRIT FV 090.540 - FTA'!C25 -> xuất | G26: =F26 -> 0 | H26: =SUM($F$10:F26)/A26 -> 0 | I26: =SUM($G$10:G26)/A26 -> 0 | J26: =J25+D26-F26 -> 0 | K26: =K25+E26-G26 -> 0 | L26: =J26/H26 -> #DIV/0! | M26: =K26/I26 -> #DIV/0!
A27: 18 | B27: ='FRIT FV 090.540 - FTA'!B26 -> 46252 | C27: ='FRIT FV 090.540 - FTA'!C26 -> xuất | G27: =F27 -> 0 | H27: =SUM($F$10:F27)/A27 -> 0 | I27: =SUM($G$10:G27)/A27 -> 0 | J27: =J26+D27-F27 -> 0 | K27: =K26+E27-G27 -> 0 | L27: =J27/H27 -> #DIV/0! | M27: =K27/I27 -> #DIV/0!
A28: 19 | B28: ='FRIT FV 090.540 - FTA'!B27 -> 46253 | C28: ='FRIT FV 090.540 - FTA'!C27 -> xuất | G28: =F28 -> 0 | H28: =SUM($F$10:F28)/A28 -> 0 | I28: =SUM($G$10:G28)/A28 -> 0 | J28: =J27+D28-F28 -> 0 | K28: =K27+E28-G28 -> 0 | L28: =J28/H28 -> #DIV/0! | M28: =K28/I28 -> #DIV/0!
A29: 20 | B29: ='FRIT FV 090.540 - FTA'!B28 -> 46254 | C29: ='FRIT FV 090.540 - FTA'!C28 -> xuất | G29: =F29 -> 0 | H29: =SUM($F$10:F29)/A29 -> 0 | I29: =SUM($G$10:G29)/A29 -> 0 | J29: =J28+D29-F29 -> 0 | K29: =K28+E29-G29 -> 0 | L29: =J29/H29 -> #DIV/0! | M29: =K29/I29 -> #DIV/0!
A30: 21 | B30: ='FRIT FV 090.540 - FTA'!B29 -> 46255 | C30: ='FRIT FV 090.540 - FTA'!C29 -> xuất | G30: =F30 -> 0 | H30: =SUM($F$10:F30)/A30 -> 0 | I30: =SUM($G$10:G30)/A30 -> 0 | J30: =J29+D30-F30 -> 0 | K30: =K29+E30-G30 -> 0 | L30: =J30/H30 -> #DIV/0! | M30: =K30/I30 -> #DIV/0!
A31: 22 | B31: ='FRIT FV 090.540 - FTA'!B30 -> 46256 | C31: ='FRIT FV 090.540 - FTA'!C30 -> xuất | G31: =F31 -> 0 | H31: =SUM($F$10:F31)/A31 -> 0 | I31: =SUM($G$10:G31)/A31 -> 0 | J31: =J30+D31-F31 -> 0 | K31: =K30+E31-G31 -> 0 | L31: =J31/H31 -> #DIV/0! | M31: =K31/I31 -> #DIV/0!
A32: 23 | B32: ='FRIT FV 090.540 - FTA'!B31 -> 46257 | C32: ='FRIT FV 090.540 - FTA'!C31 -> xuất | G32: =F32 -> 0 | H32: =SUM($F$10:F32)/A32 -> 0 | I32: =SUM($G$10:G32)/A32 -> 0 | J32: =J31+D32-F32 -> 0 | K32: =K31+E32-G32 -> 0 | L32: =J32/H32 -> #DIV/0! | M32: =K32/I32 -> #DIV/0!
A33: 24 | B33: ='FRIT FV 090.540 - FTA'!B32 -> 46258 | C33: ='FRIT FV 090.540 - FTA'!C32 -> xuất | G33: =F33 -> 0 | H33: =SUM($F$10:F33)/A33 -> 0 | I33: =SUM($G$10:G33)/A33 -> 0 | J33: =J32+D33-F33 -> 0 | K33: =K32+E33-G33 -> 0 | L33: =J33/H33 -> #DIV/0! | M33: =K33/I33 -> #DIV/0!
A34: 25 | B34: ='FRIT FV 090.540 - FTA'!B33 -> 46259 | C34: ='FRIT FV 090.540 - FTA'!C33 -> xuất | G34: =F34 -> 0 | H34: =SUM($F$10:F34)/A34 -> 0 | I34: =SUM($G$10:G34)/A34 -> 0 | J34: =J33+D34-F34 -> 0 | K34: =K33+E34-G34 -> 0 | L34: =J34/H34 -> #DIV/0! | M34: =K34/I34 -> #DIV/0!
A35: 26 | B35: ='FRIT FV 090.540 - FTA'!B34 -> 46260 | C35: ='FRIT FV 090.540 - FTA'!C34 -> xuất | G35: =F35 -> 0 | H35: =SUM($F$10:F35)/A35 -> 0 | I35: =SUM($G$10:G35)/A35 -> 0 | J35: =J34+D35-F35 -> 0 | K35: =K34+E35-G35 -> 0 | L35: =J35/H35 -> #DIV/0! | M35: =K35/I35 -> #DIV/0!
... A40: 31 | B40: ='FRIT FV 090.540 - FTA'!B39 -> 46265 | C40: ='FRIT FV 090.540 - FTA'!C39 -> Không nhập - xuất | G40: =F40 -> 0 | H40: =SUM($F$10:F40)/A40 -> 0 | I40: =SUM($G$10:G40)/A40 -> 0 | J40: =J39+D40-F40 -> 0 | K40: =K39+E40-G40 -> 0 | L40: =J40/H40 -> #DIV/0! | M40: =K40/I40 -> #DIV/0!
A41: Cộng nhập xuất | D41: =SUM(D10:D40) -> 0 | E41: =SUM(E10:E40) -> 0 | F41: =SUM(F10:F40) -> 0 | G41: =SUM(G10:G40) -> 0 | J41: =J40 -> 0 | K41: =K40 -> 0
A42: Tổng cộng | D42: =D9+D41 -> 0 | E42: =E9+E41 -> 0 | F42: =F41 -> 0 | G42: =G41 -> 0 | J42: =D42-F42 -> 0 | K42: =E42-G42 -> 0
K43: Người Lập
K47: Mai Thúy Hoa

Sheet HT082
A1: ='FRIT FV 090.540 - FTA'!#REF! -> #REF!
A2: ='FRIT FV 090.540 - FTA'!#REF! -> #REF! | K2: ='FRIT FV 090.540 - FTA'!#REF! -> #REF!
A3: THẺ KHO
D4: Tên hàng hóa: | E4: FRIT | H4: Mã hàng: | I4: Frit HT082
B5: ='FRIT FV 090.540 - FTA'!#REF! -> #REF! | C5: ='FRIT FV 090.540 - FTA'!#REF! -> #REF! | D5: ='FRIT FV 090.540 - FTA'!#REF! -> #REF! | E5: ='FRIT FV 090.540 - FTA'!#REF! -> #REF! | F5: ='FRIT FV 090.540 - FTA'!#REF! -> #REF! | G5: ='FRIT FV 090.540 - FTA'!#REF! -> #REF! | H5: ='FRIT FV 090.540 - FTA'!#REF! -> #REF! | I5: ='FRIT FV 090.540 - FTA'!#REF! -> #REF!
L6: Đơn vị tính: Kg | M6: THA1
A7: STT | B7: NGÀY | C7: DIỄN GIẢI | D7: SL NHẬP KHO | F7: SL XUẤT KHO | H7: SL XUẤT TRUNG BÌNH | J7: SL TỒN | L7: SỐ NGÀY CÒN SỬ DỤNG | N7: ĐỘ ẨM
D8: Quy khô | E8: Thực tế | F8: Quy khô | G8: Quy ướt | H8: Quy khô | I8: Quy ướt | J8: Quy khô | K8: Quy ướt | L8: Quy khô | M8: Quy ướt
A9: Tồn đầu kì | D9: =J9 -> 0 | E9: =K9 -> 0 | J9: =K9-K9*N9 -> 0 | K9: 0
A10: 1 | B10: ='FRIT FV 090.540 - FTA'!B9 -> 46235 | C10: XUẤT | H10: =SUM($F$9:F10)/A10 -> 0 | I10: =SUM($G$9:G10)/A10 -> 0 | J10: =J9+D10-F10 -> 0 | K10: =K9+E10-G10 -> 0 | L10: =J10/H10 -> #DIV/0! | M10: =K10/I10 -> #DIV/0!
A11: 2 | B11: ='FRIT FV 090.540 - FTA'!B10 -> 46236 | C11: XUẤT | H11: =SUM($F$9:F11)/A11 -> 0 | I11: =SUM($G$9:G11)/A11 -> 0 | J11: =J10+D11-F11 -> 0 | K11: =K10+E11-G11 -> 0 | L11: =J11/H11 -> #DIV/0! | M11: =K11/I11 -> #DIV/0!
A12: 3 | B12: ='FRIT FV 090.540 - FTA'!B11 -> 46237 | C12: XUẤT | H12: =SUM($F$9:F12)/A12 -> 0 | I12: =SUM($G$9:G12)/A12 -> 0 | J12: =J11+D12-F12 -> 0 | K12: =K11+E12-G12 -> 0 | L12: =J12/H12 -> #DIV/0! | M12: =K12/I12 -> #DIV/0!
A13: 4 | B13: ='FRIT FV 090.540 - FTA'!B12 -> 46238 | C13: KHÔNG XUẤT | H13: =SUM($F$9:F13)/A13 -> 0 | I13: =SUM($G$9:G13)/A13 -> 0 | J13: =J12+D13-F13 -> 0 | K13: =K12+E13-G13 -> 0 | L13: =J13/H13 -> #DIV/0! | M13: =K13/I13 -> #DIV/0!
A14: 5 | B14: ='FRIT FV 090.540 - FTA'!B13 -> 46239 | C14: KHÔNG XUẤT | H14: =SUM($F$9:F14)/A14 -> 0 | I14: =SUM($G$9:G14)/A14 -> 0 | J14: =J13+D14-F14 -> 0 | K14: =K13+E14-G14 -> 0 | L14: =J14/H14 -> #DIV/0! | M14: =K14/I14 -> #DIV/0!
A15: 6 | B15: ='FRIT FV 090.540 - FTA'!B14 -> 46240 | C15: KHÔNG XUẤT | H15: =SUM($F$9:F15)/A15 -> 0 | I15: =SUM($G$9:G15)/A15 -> 0 | J15: =J14+D15-F15 -> 0 | K15: =K14+E15-G15 -> 0 | L15: =J15/H15 -> #DIV/0! | M15: =K15/I15 -> #DIV/0!
A16: 7 | B16: ='FRIT FV 090.540 - FTA'!B15 -> 46241 | C16: KHÔNG XUẤT | H16: =SUM($F$9:F16)/A16 -> 0 | I16: =SUM($G$9:G16)/A16 -> 0 | J16: =J15+D16-F16 -> 0 | K16: =K15+E16-G16 -> 0 | L16: =J16/H16 -> #DIV/0! | M16: =K16/I16 -> #DIV/0!
A17: 8 | B17: ='FRIT FV 090.540 - FTA'!B16 -> 46242 | C17: KHÔNG XUẤT | H17: =SUM($F$9:F17)/A17 -> 0 | I17: =SUM($G$9:G17)/A17 -> 0 | J17: =J16+D17-F17 -> 0 | K17: =K16+E17-G17 -> 0 | L17: =J17/H17 -> #DIV/0! | M17: =K17/I17 -> #DIV/0!
A18: 9 | B18: ='FRIT FV 090.540 - FTA'!B17 -> 46243 | C18: KHÔNG XUẤT | H18: =SUM($F$9:F18)/A18 -> 0 | I18: =SUM($G$9:G18)/A18 -> 0 | J18: =J17+D18-F18 -> 0 | K18: =K17+E18-G18 -> 0 | L18: =J18/H18 -> #DIV/0! | M18: =K18/I18 -> #DIV/0!
A19: 10 | B19: ='FRIT FV 090.540 - FTA'!B18 -> 46244 | C19: KHÔNG XUẤT | H19: =SUM($F$9:F19)/A19 -> 0 | I19: =SUM($G$9:G19)/A19 -> 0 | J19: =J18+D19-F19 -> 0 | K19: =K18+E19-G19 -> 0 | L19: =J19/H19 -> #DIV/0! | M19: =K19/I19 -> #DIV/0!
A20: 11 | B20: ='FRIT FV 090.540 - FTA'!B19 -> 46245 | C20: KHÔNG XUẤT | H20: =SUM($F$9:F20)/A20 -> 0 | I20: =SUM($G$9:G20)/A20 -> 0 | J20: =J19+D20-F20 -> 0 | K20: =K19+E20-G20 -> 0 | L20: =J20/H20 -> #DIV/0! | M20: =K20/I20 -> #DIV/0!
A21: 12 | B21: ='FRIT FV 090.540 - FTA'!B20 -> 46246 | C21: KHÔNG XUẤT | H21: =SUM($F$9:F21)/A21 -> 0 | I21: =SUM($G$9:G21)/A21 -> 0 | J21: =J20+D21-F21 -> 0 | K21: =K20+E21-G21 -> 0 | L21: =J21/H21 -> #DIV/0! | M21: =K21/I21 -> #DIV/0!
... A40: 31 | B40: ='FRIT FV 090.540 - FTA'!B39 -> 46265 | C40: KHÔNG XUẤT | H40: =SUM($F$9:F40)/A40 -> 0 | I40: =SUM($G$9:G40)/A40 -> 0 | J40: =J39+D40-F40 -> 0 | K40: =K39+E40-G40 -> 0 | L40: =J40/H40 -> #DIV/0! | M40: =K40/I40 -> #DIV/0!
A41: Cộng nhập xuất | D41: =SUM(D10:D40) -> 0 | E41: =SUM(E10:E40) -> 0 | F41: =SUM(F10:F40) -> 0 | G41: =SUM(G10:G40) -> 0 | J41: =J40 -> 0 | K41: =K40 -> 0
A42: Tổng cộng | D42: =D9+D41 -> 0 | E42: =E9+E41 -> 0 | F42: =F9+F41 -> 0 | G42: =G9+G41 -> 0 | J42: =D42-F42 -> 0 | K42: =E42-G42 -> 0
K44: Người Lập
K48: Mai Thúy Hoa

Sheet STTP LTP
A2: THẺ KHO
G3: Tên hàng hóa: | H3: STTP LTP
B4: ='FRIT FV 090.540 - FTA'!#REF! -> #REF! | C4: ='FRIT FV 090.540 - FTA'!#REF! -> #REF! | D4: ='FRIT FV 090.540 - FTA'!#REF! -> #REF! | E4: ='FRIT FV 090.540 - FTA'!#REF! -> #REF! | F4: ='FRIT FV 090.540 - FTA'!#REF! -> #REF! | G4: ='FRIT FV 090.540 - FTA'!#REF! -> #REF! | H4: ='FRIT FV 090.540 - FTA'!#REF! -> #REF! | I4: ='FRIT FV 090.540 - FTA'!#REF! -> #REF!
L5: Đơn vị tính: Kg | M5: YN!A1
A6: STT | B6: NGÀY | C6: DIỄN GIẢI | D6: SL NHẬP KHO | F6: SL XUẤT KHO | H6: SL XUẤT TRUNG BÌNH | J6: SL TỒN | L6: SỐ NGÀY CÒN SỬ DỤNG
D7: Quy khô | E7: Thực tế | F7: Quy khô | G7: Quy ướt | H7: Quy khô | I7: Quy ướt | J7: Quy khô | K7: Quy ướt | L7: Quy khô | M7: Quy ướt
A8: Tồn đầu kì | D8: =J8 -> 0 | E8: =K8 -> 0
A9: 1 | B9: ='FRIT FV 090.540 - FTA'!B9 -> 46235 | C9: Xuất | G9: =F9 -> 0 | H9: =SUM($F$8:F9)/A9 -> 0 | I9: =SUM($G$8:G9)/A9 -> 0 | J9: =J8+D9-F9 -> 0 | K9: =K8+E9-G9 -> 0 | L9: =J9/H9 -> #DIV/0! | M9: =K9/I9 -> #DIV/0!
A10: 2 | B10: ='FRIT FV 090.540 - FTA'!B10 -> 46236 | C10: Không | G10: =F10 -> 0 | H10: =SUM($F$8:F10)/A10 -> 0 | I10: =SUM($G$8:G10)/A10 -> 0 | J10: =J9+D10-F10 -> 0 | K10: =K9+E10-G10 -> 0 | L10: =J10/H10 -> #DIV/0! | M10: =K10/I10 -> #DIV/0!
A11: 3 | B11: ='FRIT FV 090.540 - FTA'!B11 -> 46237 | C11: Xuất | G11: =F11 -> 0 | H11: =SUM($F$8:F11)/A11 -> 0 | I11: =SUM($G$8:G11)/A11 -> 0 | J11: =J10+D11-F11 -> 0 | K11: =K10+E11-G11 -> 0 | L11: =J11/H11 -> #DIV/0! | M11: =K11/I11 -> #DIV/0!
A12: 4 | B12: ='FRIT FV 090.540 - FTA'!B12 -> 46238 | C12: Xuất | G12: =F12 -> 0 | H12: =SUM($F$8:F12)/A12 -> 0 | I12: =SUM($G$8:G12)/A12 -> 0 | J12: =J11+D12-F12 -> 0 | K12: =K11+E12-G12 -> 0 | L12: =J12/H12 -> #DIV/0! | M12: =K12/I12 -> #DIV/0!
A13: 5 | B13: ='FRIT FV 090.540 - FTA'!B13 -> 46239 | C13: Xuất | G13: =F13 -> 0 | H13: =SUM($F$8:F13)/A13 -> 0 | I13: =SUM($G$8:G13)/A13 -> 0 | J13: =J12+D13-F13 -> 0 | K13: =K12+E13-G13 -> 0 | L13: =J13/H13 -> #DIV/0! | M13: =K13/I13 -> #DIV/0!
A14: 6 | B14: ='FRIT FV 090.540 - FTA'!B14 -> 46240 | C14: Không | G14: =F14 -> 0 | H14: =SUM($F$8:F14)/A14 -> 0 | I14: =SUM($G$8:G14)/A14 -> 0 | J14: =J13+D14-F14 -> 0 | K14: =K13+E14-G14 -> 0 | L14: =J14/H14 -> #DIV/0! | M14: =K14/I14 -> #DIV/0!
A15: 7 | B15: ='FRIT FV 090.540 - FTA'!B15 -> 46241 | C15: Không | G15: =F15 -> 0 | H15: =SUM($F$8:F15)/A15 -> 0 | I15: =SUM($G$8:G15)/A15 -> 0 | J15: =J14+D15-F15 -> 0 | K15: =K14+E15-G15 -> 0 | L15: =J15/H15 -> #DIV/0! | M15: =K15/I15 -> #DIV/0!
A16: 8 | B16: ='FRIT FV 090.540 - FTA'!B16 -> 46242 | C16: Không | G16: =F16 -> 0 | H16: =SUM($F$8:F16)/A16 -> 0 | I16: =SUM($G$8:G16)/A16 -> 0 | J16: =J15+D16-F16 -> 0 | K16: =K15+E16-G16 -> 0 | L16: =J16/H16 -> #DIV/0! | M16: =K16/I16 -> #DIV/0!
A17: 9 | B17: ='FRIT FV 090.540 - FTA'!B17 -> 46243 | C17: Không | G17: =F17 -> 0 | H17: =SUM($F$8:F17)/A17 -> 0 | I17: =SUM($G$8:G17)/A17 -> 0 | J17: =J16+D17-F17 -> 0 | K17: =K16+E17-G17 -> 0 | L17: =J17/H17 -> #DIV/0! | M17: =K17/I17 -> #DIV/0!
A18: 10 | B18: ='FRIT FV 090.540 - FTA'!B18 -> 46244 | C18: Không | G18: =F18 -> 0 | H18: =SUM($F$8:F18)/A18 -> 0 | I18: =SUM($G$8:G18)/A18 -> 0 | J18: =J17+D18-F18 -> 0 | K18: =K17+E18-G18 -> 0 | L18: =J18/H18 -> #DIV/0! | M18: =K18/I18 -> #DIV/0!
A19: 11 | B19: ='FRIT FV 090.540 - FTA'!B19 -> 46245 | C19: Không | G19: =F19 -> 0 | H19: =SUM($F$8:F19)/A19 -> 0 | I19: =SUM($G$8:G19)/A19 -> 0 | J19: =J18+D19-F19 -> 0 | K19: =K18+E19-G19 -> 0 | L19: =J19/H19 -> #DIV/0! | M19: =K19/I19 -> #DIV/0!
A20: 12 | B20: ='FRIT FV 090.540 - FTA'!B20 -> 46246 | C20: Không | G20: =F20 -> 0 | H20: =SUM($F$8:F20)/A20 -> 0 | I20: =SUM($G$8:G20)/A20 -> 0 | J20: =J19+D20-F20 -> 0 | K20: =K19+E20-G20 -> 0 | L20: =J20/H20 -> #DIV/0! | M20: =K20/I20 -> #DIV/0!
... A27: 19 | B27: ='FRIT FV 090.540 - FTA'!B27 -> 46253 | C27: Không | G27: =F27 -> 0 | H27: =SUM($F$8:F27)/A27 -> 0 | I27: =SUM($G$8:G27)/A27 -> 0 | J27: =J26+D27-F27 -> 0 | K27: =K26+E27-G27 -> 0 | L27: =J27/H27 -> #DIV/0! | M27: =K27/I27 -> #DIV/0!
A28: 20 | B28: ='FRIT FV 090.540 - FTA'!B28 -> 46254 | C28: Không | G28: =F28 -> 0 | H28: =SUM($F$8:F28)/A28 -> 0 | I28: =SUM($G$8:G28)/A28 -> 0 | J28: =J27+D28-F28 -> 0 | K28: =K27+E28-G28 -> 0 | L28: =J28/H28 -> #DIV/0! | M28: =K28/I28 -> #DIV/0! | N28: HNP
A29: 21 | B29: ='FRIT FV 090.540 - FTA'!B29 -> 46255 | C29: Không | G29: =F29 -> 0 | H29: =SUM($F$8:F29)/A29 -> 0 | I29: =SUM($G$8:G29)/A29 -> 0 | J29: =J28+D29-F29 -> 0 | K29: =K28+E29-G29 -> 0 | L29: =J29/H29 -> #DIV/0! | M29: =K29/I29 -> #DIV/0!
A30: 22 | B30: ='FRIT FV 090.540 - FTA'!B30 -> 46256 | C30: Không | G30: =F30 -> 0 | H30: =SUM($F$8:F30)/A30 -> 0 | I30: =SUM($G$8:G30)/A30 -> 0 | J30: =J29+D30-F30 -> 0 | K30: =K29+E30-G30 -> 0 | L30: =J30/H30 -> #DIV/0! | M30: =K30/I30 -> #DIV/0!
A31: 23 | B31: ='FRIT FV 090.540 - FTA'!B31 -> 46257 | C31: Không | G31: =F31 -> 0 | H31: =SUM($F$8:F31)/A31 -> 0 | I31: =SUM($G$8:G31)/A31 -> 0 | J31: =J30+D31-F31 -> 0 | K31: =K30+E31-G31 -> 0 | L31: =J31/H31 -> #DIV/0! | M31: =K31/I31 -> #DIV/0!
A32: 24 | B32: ='FRIT FV 090.540 - FTA'!B32 -> 46258 | C32: Không | G32: =F32 -> 0 | H32: =SUM($F$8:F32)/A32 -> 0 | I32: =SUM($G$8:G32)/A32 -> 0 | J32: =J31+D32-F32 -> 0 | K32: =K31+E32-G32 -> 0 | L32: =J32/H32 -> #DIV/0! | M32: =K32/I32 -> #DIV/0!
A33: 25 | B33: ='FRIT FV 090.540 - FTA'!B33 -> 46259 | C33: Không | G33: =F33 -> 0 | H33: =SUM($F$8:F33)/A33 -> 0 | I33: =SUM($G$8:G33)/A33 -> 0 | J33: =J32+D33-F33 -> 0 | K33: =K32+E33-G33 -> 0 | L33: =J33/H33 -> #DIV/0! | M33: =K33/I33 -> #DIV/0!
A34: 26 | B34: ='FRIT FV 090.540 - FTA'!B34 -> 46260 | C34: Không | G34: =F34 -> 0 | H34: =SUM($F$8:F34)/A34 -> 0 | I34: =SUM($G$8:G34)/A34 -> 0 | J34: =J33+D34-F34 -> 0 | K34: =K33+E34-G34 -> 0 | L34: =J34/H34 -> #DIV/0! | M34: =K34/I34 -> #DIV/0!
A35: 27 | B35: ='FRIT FV 090.540 - FTA'!B35 -> 46261 | C35: Không | G35: =F35 -> 0 | H35: =SUM($F$8:F35)/A35 -> 0 | I35: =SUM($G$8:G35)/A35 -> 0 | J35: =J34+D35-F35 -> 0 | K35: =K34+E35-G35 -> 0 | L35: =J35/H35 -> #DIV/0! | M35: =K35/I35 -> #DIV/0!
A36: 28 | B36: ='FRIT FV 090.540 - FTA'!B36 -> 46262 | C36: Không | G36: =F36 -> 0 | H36: =SUM($F$8:F36)/A36 -> 0 | I36: =SUM($G$8:G36)/A36 -> 0 | J36: =J35+D36-F36 -> 0 | K36: =K35+E36-G36 -> 0 | L36: =J36/H36 -> #DIV/0! | M36: =K36/I36 -> #DIV/0!
A37: 29 | B37: ='FRIT FV 090.540 - FTA'!B37 -> 46263 | C37: Không | G37: =F37 -> 0 | H37: =SUM($F$8:F37)/A37 -> 0 | I37: =SUM($G$8:G37)/A37 -> 0 | J37: =J36+D37-F37 -> 0 | K37: =K36+E37-G37 -> 0 | L37: =J37/H37 -> #DIV/0! | M37: =K37/I37 -> #DIV/0!
A38: 30 | B38: ='FRIT FV 090.540 - FTA'!B38 -> 46264 | C38: Không | G38: =F38 -> 0 | H38: =SUM($F$8:F38)/A38 -> 0 | I38: =SUM($G$8:G38)/A38 -> 0 | J38: =J37+D38-F38 -> 0 | K38: =K37+E38-G38 -> 0 | L38: =J38/H38 -> #DIV/0! | M38: =K38/I38 -> #DIV/0!
A39: 31 | B39: ='FRIT FV 090.540 - FTA'!B39 -> 46265 | C39: Không | G39: =F39 -> 0 | H39: =SUM($F$8:F39)/A39 -> 0 | I39: =SUM($G$8:G39)/A39 -> 0 | J39: =J38+D39-F39 -> 0 | K39: =K38+E39-G39 -> 0 | L39: =J39/H39 -> #DIV/0! | M39: =K39/I39 -> #DIV/0!
A40: Cộng nhập xuất | D40: =SUM(D9:D39) -> 0 | E40: =SUM(E9:E39) -> 0 | F40: =SUM(F9:F39) -> 0 | G40: =SUM(G9:G39) -> 0 | J40: =J39 -> 0 | K40: =K39 -> 0
A41: Tổng cộng | D41: =D8+D40 -> 0 | E41: =E8+E40 -> 0 | F41: =F8+F40 -> 0 | G41: =G8+G40 -> 0 | J41: =D41-F41 -> 0 | K41: =E41-G41 -> 0

Sheet CMC FC3828-TQ
A1: ='FRIT FV 090.540 - FTA'!#REF! -> #REF!
A2: ='FRIT FV 090.540 - FTA'!#REF! -> #REF! | K2: ='FRIT FV 090.540 - FTA'!#REF! -> #REF!
A3: THẺ KHO
D4: Tên hàng hóa: | E4: CMC | H4: Mã hàng: | I4: CMC FC3828
B5: ='FRIT FV 090.540 - FTA'!#REF! -> #REF! | C5: ='FRIT FV 090.540 - FTA'!#REF! -> #REF! | D5: ='FRIT FV 090.540 - FTA'!#REF! -> #REF! | E5: ='FRIT FV 090.540 - FTA'!#REF! -> #REF! | F5: ='FRIT FV 090.540 - FTA'!#REF! -> #REF! | G5: ='FRIT FV 090.540 - FTA'!#REF! -> #REF! | H5: ='FRIT FV 090.540 - FTA'!#REF! -> #REF! | I5: ='FRIT FV 090.540 - FTA'!#REF! -> #REF!
L6: Đơn vị tính: Kg | M6: ='FRIT FV 090.540 - FTA'!#REF! -> #REF!
A7: STT | B7: NGÀY | C7: DIỄN GIẢI | D7: SL NHẬP KHO | F7: SL XUẤT KHO | H7: SL XUẤT TRUNG BÌNH | J7: SL TỒN | L7: SỐ NGÀY TRUNG BÌNH CÒN SỬ DỤNG | N7: ĐỘ ẨM
D8: Quy khô | E8: Thực tế | F8: Quy khô | G8: Quy ướt | H8: Quy khô | I8: Quy ướt | J8: Quy khô | K8: Quy ướt | L8: Quy khô | M8: Quy ướt
A9: Tồn đầu kì | D9: =J9 -> 0 | E9: =K9 -> 0 | J9: =K9-K9*N9 -> 0 | K9: 0
A10: 1 | B10: ='FRIT FV 090.540 - FTA'!B9 -> 46235 | C10: Xuất | G10: =F10 -> 0 | H10: =SUM($F$9:F10)/A10 -> 0 | I10: =SUM($G$9:G10)/A10 -> 0 | J10: =J9+D10-F10 -> 0 | K10: =K9+E10-G10 -> 0 | L10: =J10/H10 -> #DIV/0! | M10: =K10/I10 -> #DIV/0!
A11: 2 | B11: ='FRIT FV 090.540 - FTA'!B10 -> 46236 | C11: ='FRIT VF1101N.A-VNF'!C10 -> Không nhập - xuất | G11: =F11 -> 0 | H11: =SUM($F$9:F11)/A11 -> 0 | I11: =SUM($G$9:G11)/A11 -> 0 | J11: =J10+D11-F11 -> 0 | K11: =K10+E11-G11 -> 0 | L11: =J11/H11 -> #DIV/0! | M11: =K11/I11 -> #DIV/0!
A12: 3 | B12: ='FRIT FV 090.540 - FTA'!B11 -> 46237 | C12: ='FRIT VF1101N.A-VNF'!C11 -> Không nhập - xuất | G12: =F12 -> 0 | H12: =SUM($F$9:F12)/A12 -> 0 | I12: =SUM($G$9:G12)/A12 -> 0 | J12: =J11+D12-F12 -> 0 | K12: =K11+E12-G12 -> 0 | L12: =J12/H12 -> #DIV/0! | M12: =K12/I12 -> #DIV/0!
A13: 4 | B13: ='FRIT FV 090.540 - FTA'!B12 -> 46238 | C13: Không phát sinh | G13: =F13 -> 0 | H13: =SUM($F$9:F13)/A13 -> 0 | I13: =SUM($G$9:G13)/A13 -> 0 | J13: =J12+D13-F13 -> 0 | K13: =K12+E13-G13 -> 0 | L13: =J13/H13 -> #DIV/0! | M13: =K13/I13 -> #DIV/0!
A14: 5 | B14: ='FRIT FV 090.540 - FTA'!B13 -> 46239 | C14: Không phát sinh | G14: =F14 -> 0 | H14: =SUM($F$9:F14)/A14 -> 0 | I14: =SUM($G$9:G14)/A14 -> 0 | J14: =J13+D14-F14 -> 0 | K14: =K13+E14-G14 -> 0 | L14: =J14/H14 -> #DIV/0! | M14: =K14/I14 -> #DIV/0!
A15: 6 | B15: ='FRIT FV 090.540 - FTA'!B14 -> 46240 | C15: Không phát sinh | G15: =F15 -> 0 | H15: =SUM($F$9:F15)/A15 -> 0 | I15: =SUM($G$9:G15)/A15 -> 0 | J15: =J14+D15-F15 -> 0 | K15: =K14+E15-G15 -> 0 | L15: =J15/H15 -> #DIV/0! | M15: =K15/I15 -> #DIV/0!
A16: 7 | B16: ='FRIT FV 090.540 - FTA'!B15 -> 46241 | C16: Không phát sinh | G16: =F16 -> 0 | H16: =SUM($F$9:F16)/A16 -> 0 | I16: =SUM($G$9:G16)/A16 -> 0 | J16: =J15+D16-F16 -> 0 | K16: =K15+E16-G16 -> 0 | L16: =J16/H16 -> #DIV/0! | M16: =K16/I16 -> #DIV/0!
A17: 8 | B17: ='FRIT FV 090.540 - FTA'!B16 -> 46242 | C17: Không phát sinh | G17: =F17 -> 0 | H17: =SUM($F$9:F17)/A17 -> 0 | I17: =SUM($G$9:G17)/A17 -> 0 | J17: =J16+D17-F17 -> 0 | K17: =K16+E17-G17 -> 0 | L17: =J17/H17 -> #DIV/0! | M17: =K17/I17 -> #DIV/0!
A18: 9 | B18: ='FRIT FV 090.540 - FTA'!B17 -> 46243 | C18: Không phát sinh | G18: =F18 -> 0 | H18: =SUM($F$9:F18)/A18 -> 0 | I18: =SUM($G$9:G18)/A18 -> 0 | J18: =J17+D18-F18 -> 0 | K18: =K17+E18-G18 -> 0 | L18: =J18/H18 -> #DIV/0! | M18: =K18/I18 -> #DIV/0!
A19: 10 | B19: ='FRIT FV 090.540 - FTA'!B18 -> 46244 | C19: Không phát sinh | G19: =F19 -> 0 | H19: =SUM($F$9:F19)/A19 -> 0 | I19: =SUM($G$9:G19)/A19 -> 0 | J19: =J18+D19-F19 -> 0 | K19: =K18+E19-G19 -> 0 | L19: =J19/H19 -> #DIV/0! | M19: =K19/I19 -> #DIV/0!
A20: 11 | B20: ='FRIT FV 090.540 - FTA'!B19 -> 46245 | C20: Không phát sinh | G20: =F20 -> 0 | H20: =SUM($F$9:F20)/A20 -> 0 | I20: =SUM($G$9:G20)/A20 -> 0 | J20: =J19+D20-F20 -> 0 | K20: =K19+E20-G20 -> 0 | L20: =J20/H20 -> #DIV/0! | M20: =K20/I20 -> #DIV/0!
A21: 12 | B21: ='FRIT FV 090.540 - FTA'!B20 -> 46246 | C21: Không phát sinh | G21: =F21 -> 0 | H21: =SUM($F$9:F21)/A21 -> 0 | I21: =SUM($G$9:G21)/A21 -> 0 | J21: =J20+D21-F21 -> 0 | K21: =K20+E21-G21 -> 0 | L21: =J21/H21 -> #DIV/0! | M21: =K21/I21 -> #DIV/0!
A22: 13 | B22: ='FRIT FV 090.540 - FTA'!B21 -> 46247 | C22: Không phát sinh | G22: =F22 -> 0 | H22: =SUM($F$9:F22)/A22 -> 0 | I22: =SUM($G$9:G22)/A22 -> 0 | J22: =J21+D22-F22 -> 0 | K22: =K21+E22-G22 -> 0 | L22: =J22/H22 -> #DIV/0! | M22: =K22/I22 -> #DIV/0!
A23: 14 | B23: ='FRIT FV 090.540 - FTA'!B22 -> 46248 | C23: Không phát sinh | G23: =F23 -> 0 | H23: =SUM($F$9:F23)/A23 -> 0 | I23: =SUM($G$9:G23)/A23 -> 0 | J23: =J22+D23-F23 -> 0 | K23: =K22+E23-G23 -> 0 | L23: =J23/H23 -> #DIV/0! | M23: =K23/I23 -> #DIV/0!
A24: 15 | B24: ='FRIT FV 090.540 - FTA'!B23 -> 46249 | C24: Không phát sinh | G24: =F24 -> 0 | H24: =SUM($F$9:F24)/A24 -> 0 | I24: =SUM($G$9:G24)/A24 -> 0 | J24: =J23+D24-F24 -> 0 | K24: =K23+E24-G24 -> 0 | L24: =J24/H24 -> #DIV/0! | M24: =K24/I24 -> #DIV/0!
... A33: 24 | B33: ='FRIT FV 090.540 - FTA'!B32 -> 46258 | C33: Không phát sinh | G33: =F33 -> 0 | H33: =SUM($F$9:F33)/A33 -> 0 | I33: =SUM($G$9:G33)/A33 -> 0 | J33: =J32+D33-F33 -> 0 | K33: =K32+E33-G33 -> 0 | L33: =J33/H33 -> #DIV/0! | M33: =K33/I33 -> #DIV/0!
A34: 25 | B34: ='FRIT FV 090.540 - FTA'!B33 -> 46259 | C34: Không phát sinh | G34: =F34 -> 0 | H34: =SUM($F$9:F33)/A34 -> 0 | I34: =SUM($G$9:G33)/A34 -> 0 | J34: =J33+D34-F34 -> 0 | K34: =K33+E34-G34 -> 0 | L34: =J34/H34 -> #DIV/0! | M34: =K34/I34 -> #DIV/0!
A35: 26 | B35: ='FRIT FV 090.540 - FTA'!B34 -> 46260 | C35: Không phát sinh | G35: =F35 -> 0 | H35: =SUM($F$9:F33)/A35 -> 0 | I35: =SUM($G$9:G33)/A35 -> 0 | J35: =J34+D35-F35 -> 0 | K35: =K34+E35-G35 -> 0 | L35: =J35/H35 -> #DIV/0! | M35: =K35/I35 -> #DIV/0!
A36: 27 | B36: ='FRIT FV 090.540 - FTA'!B35 -> 46261 | C36: Không phát sinh | G36: =F36 -> 0 | H36: =SUM($F$9:F33)/A36 -> 0 | I36: =SUM($G$9:G33)/A36 -> 0 | J36: =J35+D36-F36 -> 0 | K36: =K35+E36-G36 -> 0 | L36: =J36/H36 -> #DIV/0! | M36: =K36/I36 -> #DIV/0!
A37: 28 | B37: ='FRIT FV 090.540 - FTA'!B36 -> 46262 | C37: Không phát sinh | G37: =F37 -> 0 | H37: =SUM($F$9:F33)/A37 -> 0 | I37: =SUM($G$9:G33)/A37 -> 0 | J37: =J36+D37-F37 -> 0 | K37: =K36+E37-G37 -> 0 | L37: =J37/H37 -> #DIV/0! | M37: =K37/I37 -> #DIV/0!
A38: 29 | B38: ='FRIT FV 090.540 - FTA'!B37 -> 46263 | C38: Không phát sinh | G38: =F38 -> 0 | H38: =SUM($F$9:F33)/A38 -> 0 | I38: =SUM($G$9:G33)/A38 -> 0 | J38: =J37+D38-F38 -> 0 | K38: =K37+E38-G38 -> 0 | L38: =J38/H38 -> #DIV/0! | M38: =K38/I38 -> #DIV/0!
A39: 30 | B39: ='FRIT FV 090.540 - FTA'!B38 -> 46264 | C39: Không phát sinh | G39: =F39 -> 0 | H39: =SUM($F$9:F33)/A39 -> 0 | I39: =SUM($G$9:G33)/A39 -> 0 | J39: =J38+D39-F39 -> 0 | K39: =K38+E39-G39 -> 0 | L39: =J39/H39 -> #DIV/0! | M39: =K39/I39 -> #DIV/0!
A40: 31 | B40: ='FRIT FV 090.540 - FTA'!B39 -> 46265 | C40: Không phát sinh | G40: =F40 -> 0 | H40: =SUM($F$9:F33)/A40 -> 0 | I40: =SUM($G$9:G33)/A40 -> 0 | J40: =J39+D40-F40 -> 0 | K40: =K39+E40-G40 -> 0 | L40: =J40/H40 -> #DIV/0! | M40: =K40/I40 -> #DIV/0!
A41: Cộng nhập xuất | D41: =SUM(D10:D40) -> 0 | E41: =SUM(E10:E40) -> 0 | F41: =SUM(F10:F40) -> 0 | G41: =SUM(G10:G40) -> 0 | J41: =J40 -> 0 | K41: =K40 -> 0
A42: Tổng cộng | D42: =D9+D41 -> 0 | E42: =E9+E41 -> 0 | F42: =F9+F41 -> 0 | G42: =G9+G41 -> 0 | J42: =D42-F42 -> 0 | K42: =E42-G42 -> 0
K43: Người Lập
K47: Mai Thúy Hoa

Sheet Bi cao nhôm D40
A1: ='FRIT FV 090.540 - FTA'!#REF! -> #REF!
A2: ='FRIT FV 090.540 - FTA'!#REF! -> #REF! | K2: ='FRIT FV 090.540 - FTA'!#REF! -> #REF!
A3: THẺ KHO
D4: Tên hàng hóa: | E4: BI CAO NHÔM | H4: Mã hàng: | I4: ALUMINA BALLS DIA 40MM 92%
B5: ='FRIT FV 090.540 - FTA'!#REF! -> #REF! | C5: ='FRIT FV 090.540 - FTA'!#REF! -> #REF! | D5: ='FRIT FV 090.540 - FTA'!#REF! -> #REF! | E5: ='FRIT FV 090.540 - FTA'!#REF! -> #REF! | F5: ='FRIT FV 090.540 - FTA'!#REF! -> #REF! | G5: ='FRIT FV 090.540 - FTA'!#REF! -> #REF! | H5: ='FRIT FV 090.540 - FTA'!#REF! -> #REF! | I5: ='FRIT FV 090.540 - FTA'!#REF! -> #REF!
L6: Đơn vị tính: Kg | M6: ='FRIT FV 090.540 - FTA'!#REF! -> #REF!
A7: STT | B7: NGÀY | C7: DIỄN GIẢI | D7: SL NHẬP KHO | F7: SL XUẤT KHO | H7: SL XUẤT TRUNG BÌNH | J7: SL TỒN | L7: SỐ NGÀY TRUNG BÌNH CÒN SỬ DỤNG
D8: Quy khô | E8: Thực tế | F8: Quy khô | G8: Quy ướt | H8: Quy khô | I8: Quy ướt | J8: Quy khô | K8: Quy ướt | L8: Quy khô | M8: Quy ướt
A9: Tồn đầu kì | D9: =J9 -> 0 | E9: =K9 -> 0 | J9: =K9 -> 0 | K9: 0
A10: 1 | B10: ='FRIT FV 090.540 - FTA'!B9 -> 46235 | C10: Không phát sinh | H10: =SUM($F$9:F10)/A10 -> 0 | I10: =SUM($G$9:G10)/A10 -> 0 | J10: =J9+D10-F10 -> 0 | K10: =K9+E10-G10 -> 0 | L10: =J10/H10 -> #DIV/0! | M10: =K10/I10 -> #DIV/0!
A11: 2 | B11: ='FRIT FV 090.540 - FTA'!B10 -> 46236 | C11: Không phát sinh | H11: =SUM($F$9:F11)/A11 -> 0 | I11: =SUM($G$9:G11)/A11 -> 0 | J11: =J10+D11-F11 -> 0 | K11: =K10+E11-G11 -> 0 | L11: =J11/H11 -> #DIV/0! | M11: =K11/I11 -> #DIV/0!
A12: 3 | B12: ='FRIT FV 090.540 - FTA'!B11 -> 46237 | C12: Không phát sinh | H12: =SUM($F$9:F12)/A12 -> 0 | I12: =SUM($G$9:G12)/A12 -> 0 | J12: =J11+D12-F12 -> 0 | K12: =K11+E12-G12 -> 0 | L12: =J12/H12 -> #DIV/0! | M12: =K12/I12 -> #DIV/0!
A13: 4 | B13: ='FRIT FV 090.540 - FTA'!B12 -> 46238 | C13: Không phát sinh | H13: =SUM($F$9:F13)/A13 -> 0 | I13: =SUM($G$9:G13)/A13 -> 0 | J13: =J12+D13-F13 -> 0 | K13: =K12+E13-G13 -> 0 | L13: =J13/H13 -> #DIV/0! | M13: =K13/I13 -> #DIV/0!
A14: 5 | B14: ='FRIT FV 090.540 - FTA'!B13 -> 46239 | C14: Không phát sinh | H14: =SUM($F$9:F14)/A14 -> 0 | I14: =SUM($G$9:G14)/A14 -> 0 | J14: =J13+D14-F14 -> 0 | K14: =K13+E14-G14 -> 0 | L14: =J14/H14 -> #DIV/0! | M14: =K14/I14 -> #DIV/0!
A15: 6 | B15: ='FRIT FV 090.540 - FTA'!B14 -> 46240 | C15: Không phát sinh | H15: =SUM($F$9:F15)/A15 -> 0 | I15: =SUM($G$9:G15)/A15 -> 0 | J15: =J14+D15-F15 -> 0 | K15: =K14+E15-G15 -> 0 | L15: =J15/H15 -> #DIV/0! | M15: =K15/I15 -> #DIV/0!
A16: 7 | B16: ='FRIT FV 090.540 - FTA'!B15 -> 46241 | C16: Không phát sinh | H16: =SUM($F$9:F16)/A16 -> 0 | I16: =SUM($G$9:G16)/A16 -> 0 | J16: =J15+D16-F16 -> 0 | K16: =K15+E16-G16 -> 0 | L16: =J16/H16 -> #DIV/0! | M16: =K16/I16 -> #DIV/0!
A17: 8 | B17: ='FRIT FV 090.540 - FTA'!B16 -> 46242 | C17: Không phát sinh | H17: =SUM($F$9:F17)/A17 -> 0 | I17: =SUM($G$9:G17)/A17 -> 0 | J17: =J16+D17-F17 -> 0 | K17: =K16+E17-G17 -> 0 | L17: =J17/H17 -> #DIV/0! | M17: =K17/I17 -> #DIV/0!
A18: 9 | B18: ='FRIT FV 090.540 - FTA'!B17 -> 46243 | C18: Không phát sinh | H18: =SUM($F$9:F18)/A18 -> 0 | I18: =SUM($G$9:G18)/A18 -> 0 | J18: =J17+D18-F18 -> 0 | K18: =K17+E18-G18 -> 0 | L18: =J18/H18 -> #DIV/0! | M18: =K18/I18 -> #DIV/0!
A19: 10 | B19: ='FRIT FV 090.540 - FTA'!B18 -> 46244 | C19: Không phát sinh | H19: =SUM($F$9:F19)/A19 -> 0 | I19: =SUM($G$9:G19)/A19 -> 0 | J19: =J18+D19-F19 -> 0 | K19: =K18+E19-G19 -> 0 | L19: =J19/H19 -> #DIV/0! | M19: =K19/I19 -> #DIV/0!
A20: 11 | B20: ='FRIT FV 090.540 - FTA'!B19 -> 46245 | C20: Không phát sinh | H20: =SUM($F$9:F20)/A20 -> 0 | I20: =SUM($G$9:G20)/A20 -> 0 | J20: =J19+D20-F20 -> 0 | K20: =K19+E20-G20 -> 0 | L20: =J20/H20 -> #DIV/0! | M20: =K20/I20 -> #DIV/0!
A21: 12 | B21: ='FRIT FV 090.540 - FTA'!B20 -> 46246 | C21: Không phát sinh | H21: =SUM($F$9:F21)/A21 -> 0 | I21: =SUM($G$9:G21)/A21 -> 0 | J21: =J20+D21-F21 -> 0 | K21: =K20+E21-G21 -> 0 | L21: =J21/H21 -> #DIV/0! | M21: =K21/I21 -> #DIV/0!
... A40: 31 | B40: ='FRIT FV 090.540 - FTA'!B39 -> 46265 | C40: Không phát sinh | H40: =SUM($F$9:F40)/A40 -> 0 | I40: =SUM($G$9:G40)/A40 -> 0 | J40: =J39+D40-F40 -> 0 | K40: =K39+E40-G40 -> 0 | L40: =J40/H40 -> #DIV/0! | M40: =K40/I40 -> #DIV/0!
A41: Cộng nhập xuất | D41: =SUM(D10:D40) -> 0 | E41: =SUM(E10:E40) -> 0 | F41: =SUM(F10:F40) -> 0 | G41: =SUM(G10:G40) -> 0 | J41: =J40 -> 0 | K41: =K40 -> 0
A42: Tổng cộng | D42: =D9+D41 -> 0 | E42: =E9+E41 -> 0 | F42: =F9+F41 -> 0 | G42: =G9+G41 -> 0 | J42: =D42-F42 -> 0 | K42: =E42-G42 -> 0
K43: Người Lập
K47: Mai Thúy Hoa

Sheet VT GR TIM AN HA 30X60
A1: ='FRIT FV 090.540 - FTA'!#REF! -> #REF!
A2: ='FRIT FV 090.540 - FTA'!#REF! -> #REF! | I2: ='FRIT FV 090.540 - FTA'!#REF! -> #REF!
A3: ='FRIT FV 090.540 - FTA'!#REF! -> #REF!
D4: Tên hàng hóa: | E4: VỎ THÙNG | G4: Mã hàng: | H4: GRANDCERA TÍM-AH
B5: ='FRIT FV 090.540 - FTA'!#REF! -> #REF! | C5: ='FRIT FV 090.540 - FTA'!#REF! -> #REF! | D5: ='FRIT FV 090.540 - FTA'!#REF! -> #REF! | E5: ='FRIT FV 090.540 - FTA'!#REF! -> #REF! | F5: ='FRIT FV 090.540 - FTA'!#REF! -> #REF! | G5: ='FRIT FV 090.540 - FTA'!#REF! -> #REF! | H5: ='FRIT FV 090.540 - FTA'!#REF! -> #REF! | I5: ='FRIT FV 090.540 - FTA'!#REF! -> #REF!
H6: Đơn vị tính: Cái | I6: THA1
A7: STT | B7: NGÀY | C7: DIỄN GIẢI | D7: SL NHẬP KHO | E7: SL XUẤT KHO | F7: SL XUẤT TRUNG BÌNH | G7: SL TỒN | H7: SỐ NGÀY CÒN SỬ DỤNG | I7: GHI CHÚ
A8: Tồn đầu kì | D8: =G8 -> 0 | E8: =E40 -> 0
A9: 1 | B9: ='FRIT FV 090.540 - FTA'!B9 -> 46235 | C9: KHÔNG XUẤT | F9: =SUM($E$8:E9)/A9 -> 0 | G9: =G8+D9-E9 -> 0 | H9: =G9/10417 -> 0
A10: 2 | B10: ='FRIT FV 090.540 - FTA'!B10 -> 46236 | C10: KHÔNG XUẤT | F10: =SUM($E$8:E10)/A10 -> 0 | G10: =G9+D10-E10 -> 0 | H10: =G10/10417 -> 0
A11: 3 | B11: ='FRIT FV 090.540 - FTA'!B11 -> 46237 | C11: KHÔNG XUẤT | F11: =SUM($E$8:E11)/A11 -> 0 | G11: =G10+D11-E11 -> 0 | H11: =G11/10417 -> 0
A12: 4 | B12: ='FRIT FV 090.540 - FTA'!B12 -> 46238 | C12: KHÔNG XUẤT | F12: =SUM($E$8:E12)/A12 -> 0 | G12: =G11+D12-E12 -> 0 | H12: =G12/10417 -> 0
A13: 5 | B13: ='FRIT FV 090.540 - FTA'!B13 -> 46239 | C13: KHÔNG XUẤT | F13: =SUM($E$8:E13)/A13 -> 0 | G13: =G12+D13-E13 -> 0 | H13: =G13/10417 -> 0
A14: 6 | B14: ='FRIT FV 090.540 - FTA'!B14 -> 46240 | C14: KHÔNG XUẤT | F14: =SUM($E$8:E14)/A14 -> 0 | G14: =G13+D14-E14 -> 0 | H14: =G14/10417 -> 0
A15: 7 | B15: ='FRIT FV 090.540 - FTA'!B15 -> 46241 | C15: KHÔNG XUẤT | F15: =SUM($E$8:E15)/A15 -> 0 | G15: =G14+D15-E15 -> 0 | H15: =G15/10417 -> 0
A16: 8 | B16: ='FRIT FV 090.540 - FTA'!B16 -> 46242 | C16: KHÔNG XUẤT | F16: =SUM($E$8:E16)/A16 -> 0 | G16: =G15+D16-E16 -> 0 | H16: =G16/10417 -> 0
A17: 9 | B17: ='FRIT FV 090.540 - FTA'!B17 -> 46243 | C17: KHÔNG XUẤT | F17: =SUM($E$8:E17)/A17 -> 0 | G17: =G16+D17-E17 -> 0 | H17: =G17/10417 -> 0
A18: 10 | B18: ='FRIT FV 090.540 - FTA'!B18 -> 46244 | C18: KHÔNG XUẤT | F18: =SUM($E$8:E18)/A18 -> 0 | G18: =G17+D18-E18 -> 0 | H18: =G18/10417 -> 0
A19: 11 | B19: ='FRIT FV 090.540 - FTA'!B19 -> 46245 | C19: KHÔNG XUẤT | F19: =SUM($E$8:E19)/A19 -> 0 | G19: =G18+D19-E19 -> 0 | H19: =G19/10417 -> 0
A20: 12 | B20: ='FRIT FV 090.540 - FTA'!B20 -> 46246 | C20: KHÔNG XUẤT | F20: =SUM($E$8:E20)/A20 -> 0 | G20: =G19+D20-E20 -> 0 | H20: =G20/10417 -> 0
... A39: 31 | B39: ='FRIT FV 090.540 - FTA'!B39 -> 46265 | C39: KHÔNG XUẤT | F39: =SUM($E$8:E39)/A39 -> 0 | G39: =G38+D39-E39 -> 0 | H39: =G39/10417 -> 0
A40: Cộng nhập xuất | D40: =SUM(D9:D39) -> 0 | E40: =SUM(E9:E39) -> 0 | G40: =G39 -> 0
A41: Tổng cộng | D41: =D8+D40 -> 0 | E41: =E40 -> 0 | G41: =D41-E41 -> 0
H43: Người Lập
H47: Mai Thúy Hoa

Sheet VO PHE DONG TAY 30X60
A1: ='FRIT FV 090.540 - FTA'!#REF! -> #REF!
A2: ='FRIT FV 090.540 - FTA'!#REF! -> #REF! | I2: ='FRIT FV 090.540 - FTA'!#REF! -> #REF!
A3: ='FRIT FV 090.540 - FTA'!#REF! -> #REF!
D4: Tên hàng hóa: | E4: VỎ THÙNG | G4: Mã hàng: | H4: VỎ KHÔNG IN ĐÓNG TAY
B5: ='FRIT FV 090.540 - FTA'!#REF! -> #REF! | C5: ='FRIT FV 090.540 - FTA'!#REF! -> #REF! | D5: ='FRIT FV 090.540 - FTA'!#REF! -> #REF! | E5: ='FRIT FV 090.540 - FTA'!#REF! -> #REF! | F5: ='FRIT FV 090.540 - FTA'!#REF! -> #REF! | G5: ='FRIT FV 090.540 - FTA'!#REF! -> #REF! | H5: ='FRIT FV 090.540 - FTA'!#REF! -> #REF! | I5: ='FRIT FV 090.540 - FTA'!#REF! -> #REF!
H6: Đơn vị tính: Cái | I6: YN!A1
A7: STT | B7: NGÀY | C7: DIỄN GIẢI | D7: SL NHẬP KHO | E7: SL XUẤT KHO | F7: SL XUẤT TRUNG BÌNH | G7: SL TỒN | H7: SỐ NGÀY CÒN SỬ DỤNG | I7: GHI CHÚ
A8: Tồn đầu kì | D8: =G8 -> 0 | G8: 0
A9: 1 | B9: ='FRIT FV 090.540 - FTA'!B9 -> 46235 | C9: Không phát sinh | F9: =SUM($E$8:E9)/A9 -> 0 | G9: =G8+D9-E9 -> 0 | H9: =G9/F9 -> #DIV/0!
A10: 2 | B10: ='FRIT FV 090.540 - FTA'!B10 -> 46236 | C10: Không phát sinh | F10: =SUM($E$8:E10)/A10 -> 0 | G10: =G9+D10-E10 -> 0 | H10: =G10/F10 -> #DIV/0!
A11: 3 | B11: ='FRIT FV 090.540 - FTA'!B11 -> 46237 | C11: Không phát sinh | F11: =SUM($E$8:E11)/A11 -> 0 | G11: =G10+D11-E11 -> 0 | H11: =G11/F11 -> #DIV/0!
A12: 4 | B12: ='FRIT FV 090.540 - FTA'!B12 -> 46238 | C12: Không phát sinh | F12: =SUM($E$8:E12)/A12 -> 0 | G12: =G11+D12-E12 -> 0 | H12: =G12/F12 -> #DIV/0!
A13: 5 | B13: ='FRIT FV 090.540 - FTA'!B13 -> 46239 | C13: Không phát sinh | F13: =SUM($E$8:E13)/A13 -> 0 | G13: =G12+D13-E13 -> 0 | H13: =G13/F13 -> #DIV/0!
A14: 6 | B14: ='FRIT FV 090.540 - FTA'!B14 -> 46240 | C14: Không phát sinh | F14: =SUM($E$8:E14)/A14 -> 0 | G14: =G13+D14-E14 -> 0 | H14: =G14/F14 -> #DIV/0!
A15: 7 | B15: ='FRIT FV 090.540 - FTA'!B15 -> 46241 | C15: Không phát sinh | F15: =SUM($E$8:E15)/A15 -> 0 | G15: =G14+D15-E15 -> 0 | H15: =G15/F15 -> #DIV/0!
A16: 8 | B16: ='FRIT FV 090.540 - FTA'!B16 -> 46242 | C16: Không phát sinh | F16: =SUM($E$8:E16)/A16 -> 0 | G16: =G15+D16-E16 -> 0 | H16: =G16/F16 -> #DIV/0!
A17: 9 | B17: ='FRIT FV 090.540 - FTA'!B17 -> 46243 | C17: Không phát sinh | F17: =SUM($E$8:E17)/A17 -> 0 | G17: =G16+D17-E17 -> 0 | H17: =G17/F17 -> #DIV/0!
A18: 10 | B18: ='FRIT FV 090.540 - FTA'!B18 -> 46244 | C18: Không phát sinh | F18: =SUM($E$8:E18)/A18 -> 0 | G18: =G17+D18-E18 -> 0 | H18: =G18/F18 -> #DIV/0!
A19: 11 | B19: ='FRIT FV 090.540 - FTA'!B19 -> 46245 | C19: Không phát sinh | F19: =SUM($E$8:E19)/A19 -> 0 | G19: =G18+D19-E19 -> 0 | H19: =G19/F19 -> #DIV/0!
A20: 12 | B20: ='FRIT FV 090.540 - FTA'!B20 -> 46246 | C20: Không phát sinh | F20: =SUM($E$8:E20)/A20 -> 0 | G20: =G19+D20-E20 -> 0 | H20: =G20/F20 -> #DIV/0!
... A39: 31 | B39: ='FRIT FV 090.540 - FTA'!B39 -> 46265 | C39: Không phát sinh | F39: =SUM($E$8:E39)/A39 -> 0 | G39: =G38+D39-E39 -> 0 | H39: =G39/F39 -> #DIV/0!
A40: Cộng nhập xuất | D40: =SUM(D9:D39) -> 0 | E40: =SUM(E9:E39) -> 0
A41: Tổng cộng | D41: =D8+D40 -> 0 | E41: =E8+E40 -> 0 | G41: =D41-E41 -> 0
H43: Người Lập
H47: Mai Thúy Hoa

Sheet VO 30X30 GR XANH
A2: THẺ KHO
E3: Tên hàng hóa: | F3: VỎ THÙNG GR 30X30
B4: ='FRIT FV 090.540 - FTA'!#REF! -> #REF! | C4: ='FRIT FV 090.540 - FTA'!#REF! -> #REF! | D4: ='FRIT FV 090.540 - FTA'!#REF! -> #REF! | E4: ='FRIT FV 090.540 - FTA'!#REF! -> #REF! | F4: ='FRIT FV 090.540 - FTA'!#REF! -> #REF! | G4: ='FRIT FV 090.540 - FTA'!#REF! -> #REF! | H4: ='FRIT FV 090.540 - FTA'!#REF! -> #REF! | I4: ='FRIT FV 090.540 - FTA'!#REF! -> #REF!
H5: Đơn vị tính: Cái | I5: YN!A1
A6: STT | B6: NGÀY | C6: DIỄN GIẢI | D6: SL NHẬP KHO | E6: SL XUẤT KHO | F6: SL XUẤT TRUNG BÌNH | G6: SL TỒN | H6: SỐ NGÀY CÒN SỬ DỤNG
A7: Tồn đầu kì | D7: =G7 -> 0 | G7: 0
A8: 1 | B8: ='FRIT FV 090.540 - FTA'!B9 -> 46235 | C8: Không | F8: =SUM($E$7:E8)/A8 -> 0 | G8: =G7+D8-E8 -> 0 | H8: =G8/((SUM($E$7:E8)/A8)) -> #DIV/0!
A9: 2 | B9: ='FRIT FV 090.540 - FTA'!B10 -> 46236 | C9: Không | F9: =SUM($E$7:E9)/A9 -> 0 | G9: =D8+G8-E9 -> 0 | H9: =G9/((SUM($E$7:E9)/A9)) -> #DIV/0!
A10: 3 | B10: ='FRIT FV 090.540 - FTA'!B11 -> 46237 | C10: Không | F10: =SUM($E$7:E10)/A10 -> 0 | G10: =D9+G9-E10 -> 0 | H10: =G10/((SUM($E$7:E10)/A10)) -> #DIV/0!
A11: 4 | B11: ='FRIT FV 090.540 - FTA'!B12 -> 46238 | C11: Không | F11: =SUM($E$7:E11)/A11 -> 0 | G11: =D10+G10-E11 -> 0 | H11: =G11/((SUM($E$7:E11)/A11)) -> #DIV/0!
A12: 5 | B12: ='FRIT FV 090.540 - FTA'!B13 -> 46239 | C12: Không | F12: =SUM($E$7:E12)/A12 -> 0 | G12: =D11+G11-E12 -> 0 | H12: =G12/((SUM($E$7:E12)/A12)) -> #DIV/0!
A13: 6 | B13: ='FRIT FV 090.540 - FTA'!B14 -> 46240 | C13: Không | F13: =SUM($E$7:E13)/A13 -> 0 | G13: =D12+G12-E13 -> 0 | H13: =G13/((SUM($E$7:E13)/A13)) -> #DIV/0!
A14: 7 | B14: ='FRIT FV 090.540 - FTA'!B15 -> 46241 | C14: Không | F14: =SUM($E$7:E14)/A14 -> 0 | G14: =D13+G13-E14 -> 0 | H14: =G14/((SUM($E$7:E14)/A14)) -> #DIV/0!
A15: 8 | B15: ='FRIT FV 090.540 - FTA'!B16 -> 46242 | C15: Không | F15: =SUM($E$7:E15)/A15 -> 0 | G15: =D14+G14-E15 -> 0 | H15: =G15/((SUM($E$7:E15)/A15)) -> #DIV/0!
A16: 9 | B16: ='FRIT FV 090.540 - FTA'!B17 -> 46243 | C16: Không | F16: =SUM($E$7:E16)/A16 -> 0 | G16: =D15+G15-E16 -> 0 | H16: =G16/((SUM($E$7:E16)/A16)) -> #DIV/0!
A17: 10 | B17: ='FRIT FV 090.540 - FTA'!B18 -> 46244 | C17: Không | F17: =SUM($E$7:E17)/A17 -> 0 | G17: =D16+G16-E17 -> 0 | H17: =G17/((SUM($E$7:E17)/A17)) -> #DIV/0!
A18: 11 | B18: ='FRIT FV 090.540 - FTA'!B19 -> 46245 | C18: Không | F18: =SUM($E$7:E18)/A18 -> 0 | G18: =D17+G17-E18 -> 0 | H18: =G18/((SUM($E$7:E18)/A18)) -> #DIV/0!
A19: 12 | B19: ='FRIT FV 090.540 - FTA'!B20 -> 46246 | C19: Không | F19: =SUM($E$7:E19)/A19 -> 0 | G19: =D18+G18-E19 -> 0 | H19: =G19/((SUM($E$7:E19)/A19)) -> #DIV/0!
A20: 13 | B20: ='FRIT FV 090.540 - FTA'!B21 -> 46247 | C20: Không | F20: =SUM($E$7:E20)/A20 -> 0 | G20: =D19+G19-E20 -> 0 | H20: =G20/((SUM($E$7:E20)/A20)) -> #DIV/0!
... A23: 16 | B23: ='FRIT FV 090.540 - FTA'!B24 -> 46250 | C23: Không | F23: =SUM($E$7:E23)/A23 -> 0 | G23: =D22+G22-E23 -> 0 | H23: =G23/((SUM($E$7:E23)/A23)) -> #DIV/0!
A24: 17 | B24: ='FRIT FV 090.540 - FTA'!B25 -> 46251 | F24: =SUM($E$7:E24)/A24 -> 0 | G24: =D23+G23-E24 -> 0 | H24: =G24/((SUM($E$7:E24)/A24)) -> #DIV/0!
A25: 18 | B25: ='FRIT FV 090.540 - FTA'!B26 -> 46252 | C25: Không | F25: =SUM($E$7:E25)/A25 -> 0 | G25: =D24+G24-E25 -> 0 | H25: =G25/((SUM($E$7:E25)/A25)) -> #DIV/0!
A26: 19 | B26: ='FRIT FV 090.540 - FTA'!B27 -> 46253 | C26: Không | F26: =SUM($E$7:E26)/A26 -> 0 | G26: =D25+G25-E26 -> 0 | H26: =G26/((SUM($E$7:E26)/A26)) -> #DIV/0!
