Workbook
Name A: #REF!
Name A: #REF!
Name A: #REF!
Name A: #REF!
Name A: #REF!
Name A: #REF!
Name A: #REF!
Name A: #REF!
Name A: #REF!
Name A: #REF!
Name A: #REF!
Name A: #REF!
Name A: #REF!
Name A: #REF!
Name A: #REF!
Name A: #REF!
Name A: #REF!
Name A: #REF!
Name A: #REF!
Name A: #REF!
Name A: #REF!
Name A: #REF!
Name A: #REF!
Name A: #REF!
Name A: #REF!
Name A: #REF!
Name A: #REF!
Name A: #REF!
Name A: #REF!
Name A: #REF!
Name A: #REF!
Name A: #REF!
Name A40010005: 'TONG HOP'!#REF!
Name A40010005: 'TONG HOP'!#REF!
Name A40010005: 'TONG HOP'!#REF!
Name A40010005: 'TONG HOP'!#REF!
Name A40010005: 'TONG HOP'!#REF!
Name A40010005: 'TONG HOP'!#REF!
Name A40010005: 'TONG HOP'!#REF!
Name A40010005: 'TONG HOP'!#REF!
Name A40010005: 'TONG HOP'!#REF!
Name A40010005: 'TONG HOP'!#REF!
Name A40010005: 'TONG HOP'!#REF!
Name A40010005: 'TONG HOP'!#REF!
Name A40010005: 'TONG HOP'!#REF!
Name A40010005: 'TONG HOP'!#REF!
Name A40010005: 'TONG HOP'!#REF!
Name A40010005: 'TONG HOP'!#REF!
Name A40010005: 'TONG HOP'!#REF!
Name A40010005: 'TONG HOP'!#REF!
Name A40010005: 'TONG HOP'!#REF!
Name A40010005: 'TONG HOP'!#REF!
Name A40010005: 'TONG HOP'!#REF!
Name A40010005: 'TONG HOP'!#REF!
Name A40010005: 'TONG HOP'!#REF!
Name A40010005: 'TONG HOP'!#REF!
Name A40010005: 'TONG HOP'!#REF!
Name A40010005: 'TONG HOP'!#REF!
Name A40010005: 'TONG HOP'!#REF!
Name A40010005: 'TONG HOP'!#REF!

Sheet Nhà cung ứng
A1: CÔNG TY CỔ PHẦN GẠCH MEN PHƯƠNG NAM
A2: PHÒNG KẾ HOẠCH - VẬT TƯ | I2: BM.03.04
A3: DANH SÁCH NHÀ CUNG CẤP 2022
A4: STT | B4: Tên hàng hóa | C4: Đơn vị cung cấp | D4: Người liên hệ/ Chức vụ | E4: Địa chỉ - Mã số thuế | F4: Điện thoại - Email | G4: Số tài khoản | H4: Số lượng | I4: Thời gian liên hệ
A5: I. NGUYÊN LIỆU XƯƠNG
A6: 1 | B6: Đất sét T | C6: CÔNG TY TNHH LONG QUANG LH | D6: Ông Bùi Quang Vinh/ Giám đốc | E6: Số 59 thửa đất số 133, tờ bản đồ số 7, thị trấn Đình Văn, huyện Lâm Hà, Lâm Đồng MST: 5801431670 | F6: 0836115959 - nguyenthithuyduong952@gmail.com | G6: 050131285555 - Ngân hàng Sacmobank, huyện Lâm Hà, tỉnh Lâm Đồng
A7: 2 | B7: Cao lanh lọc - Cao lanh thô | C7: CÔNG TY TNHH ANH KIÊN | D7: Bà Trương Thị Thúy Hằng/ Giám đốc | E7: 319 đường 1/5, phường B'Lao, Tp. Bảo Lộc, tỉnh Lâm Đồng MST: 5800385414 | F7: 02633718215 - ctyanhkienld@gmail.com | G7: 1021770523 - Ngân hàng Vietcombank - CN Tp. Bảo Lộc
A8: 3 | B8: Đất sơ chế làm gạch A1 | C8: CÔNG TY CỔ PHẦN HT NGUYỄN | D8: Ông Nguyễn Khắc Tùng/ Giám đốc | E8: Tầng 6, Tòa nhà Việt Á, Số 9 Duy Tân, Phường Dịch Vọng Hậu, Quận Cầu Giấy, TP.Hà Nội MST: 0108605709 | F8: 0922355555 htnguyen.jsc@gmail.com | G8: 21110001984423 - Ngân hàng BIVD - CN Hà Nội
A9: 4 | B9: BM01 | C9: CÔNG TY TNHH CHUYỂN GIAO CÔNG NGHỆ BÌNH MINH | D9: Ông Trinh Văn Bình/ Giám đốc | E9: Trịnh Văn Bình phòng 2103-nhà N09B2, khu đô thị mới Dịch Vong, phường Dịch vọng, quận Cầu Giấy, TP Hà Nội MST: 0109883667 | F9: 0983656454 (Mr Bình) binhkttlt@gmail.com | G9: 115002904643 - Ngân hàng Viettinbank - CN Tây Hà Nội, Tp. Hà Nội
A10: 5 | B10: Quặng Felsapat PT3 - Cao lanh hàng B nghiền rời - Đất làm gạch màu vàng Phú Thọ (Talc) | C10: CÔNG TY TNHH VẬN TẢI VÀ DỊCH VỤ NGỌC KÝ | D10: Ông Phạm Ngọc Ký/ Giám đốc | E10: Nhà Ông Ký, Xóm 10, xã Đông Cơ, huyện Tiền Hải, tỉnh Thái Bình MST: 1000834198 | F10: 0912872404 - 0918725768 Congtyvantaingocky@gmail.com | G10: 117002634241 - Ngân hàng Vietinbank - CN Thái Bình
A11: 6 | B11: Bột đá D loại 2 | C11: CÔNG TY TNHH NGUYÊN LIỆU THIÊN SƠN | D11: Bà Nguyễn Bảo Ly/ Giám đốc | E11: Thôn Bút Sơn, Xã Thanh Sơn, Huyện Kim Bảng, Tỉnh Hà Nam MST: 0700256381 | F11: 0973571886 - 0918602186 dothusp2@gmail.com | G11: 48210000544097 - Ngân hàng TMCP Đầu tư và Phát triển Việt Nam- CN Hà Nam
A12: 7 | B12: STPP Xương | C12: CÔNG TY TNHH PHÁT TRIỂN TM VÀ XNK HOÀNG DƯƠNG | D12: Bà Phạm Thị Hồng Nhung/Giám đốc | E12: Số 20 đường Lương Ngọc Quyến, Tổ 2, Phường Quang Trung, TP. Thái Nguyên, Tỉnh Thái Nguyên MST: 4601345888 | F12: 0984258358 - hoangduong8817@gmail.com hongnhung0788@gmail.com | G12: 0451000414441 - Ngân hàng TMCP Ngoại thương Việt Nam - CN Thành Công
A13: 8 | B13: Natri Silicate (Thủy tinh lỏng) | C13: CÔNG TY TNHH THƯƠNG MẠI DỊCH VỤ NGỌC ANH ĐẠT | D13: Ông Nguyễn Bá Ngọc/ Giám đốc | E13: Thửa đất số 814, Tờ bản đồ số 49, Tổ 4, Khu phố 2, Phường Thới Hòa, Thị Xã Bến Cát, Tỉnh Bình Dương MST: 3702061802 | F13: 0979956835 - 0979088179 ngocanhdat79@gmail.com | G13: 7966656599999 - Ngân hàng MB - CN Mỹ Phước - Bình Dương
A14: 9 | B14: =B13 -> Natri Silicate (Thủy tinh lỏng) | C14: CÔNG TY TNHH SX TM THỦY TINH PHẠM GIA | D14: Bà Lê Thị Hoài Thanh/ Giám đốc | E14: Số 17E/8A, KP.2, Phường Long Bình, TP. Biên Hòa, Tỉnh Đồng Nai MST: 3603650814 | F14: 0911628999 chinhpham1704@gmail.com | G14: 19134477214018 - Ngân hàng TMCP Kỹ Thương Việt Nam - CN Đồng Nai
A15: II. NHIÊN LIỆU
A16: 1 | B16: Than cục 4 | C16: CÔNG TY TNHH SX & TM ĐỨC ANH | D16: Ông Phí Đức Đại/ Giám đốc | E16: Số 215 , Đường Minh Tân, Khu Bích Nhôi 3, Phường Minh Tân, Thị Xã Kinh Môn, Tỉnh Hải Dương MST: 0801366020 | F16: 0903279050 - tmducanh01@gmail.com | G16: 115601525666 - Ngân hàng Vietinbank - CN Đông Hải Dương
A17: 2 | B17: Than cục 4 | C17: CÔNG TY TNHH THAN NAM LỘC PHÁT | D17: Bà Trịnh Thị Hòa/ Giám đốc | E17: 762/36/45A, QL 1A, P.Bình Hưng Hòa, Quận Bình Tân, Tp.HCM MST: 0315772465 | F17: 02838293179 congtythannamlocphat@gmail.com | G17: 6867537 - Ngân hàng ACB - Tp.Hồ Chí Minh
A18: 3 | B18: Than cục 4A2 | C18: CÔNG TY CP THƯƠNG MẠI XNK HƯNG TAM LONG | D18: Bà Nguyễn Thu Hồng/ Giám đốc | E18: 567, Khu phố 7, Huỳnh Tấn Phát, Thị trấn Nhà Bè, Huyện Nhà Bè, Tp.Hồ Chí Minh MST: 0308928383 | F18: 02837770777 hungtamlongcty@gmail.com | G18: 1029397548 - Ngân hàng Vietcombank - CN Nam Sài Gòn, Tp.HCM
A19: 4 | B19: Than cục 4 | C19: CÔNG TY CỔ PHẦN GẠCH MEN PHƯƠNG NAM | D19: Ông Đinh Khắc Trung/ Tổng giám đốc | E19: 135/37/74 Nguyễn Hữu Cảnh, Phường 22, Quận Bình Thạnh, Tp.Hồ Chí Minh MST: 3602227109 | F19: 02513684039 kehoachvattu.pnc@gmail.com | G19: 6300201026920 - Ngân hàng Agribank - CN9, Tp.HCM
A20: 5 | B20: Than cục 1C | C20: CÔNG TY CỔ PHẦN ĐẦU TƯ TOÀN AN | D20: Bà Phạm Thị Thoa/ Giám đốc | E20: 12G Nguyễn Quang Bích, Phường 13, Quận Tân Bình, Tp. Hồ Chí Minh MST: 0304245844 | F20: 02838498442 phamhung.toanan@gmail.com | G20: 6300201033948 - Ngân hàng Agribank - CN 9, Tp. HCM
A21: 6 | B21: Than cục 4 | C21: CÔNG TY TNHH THƯƠNG MẠI KHOÁNG SẢN HẢI MINH | D21: Ông Trần Văn Trúc/ Giám đốc | E21: Số 2B210, Tổ 3, Phường Thành Tô, Quận Hải An, TP. Hải Phòng MST: 0201750549 | F21: 02253569314 maichau1978@gmail.com | G21: 2511142688688 - Ngân hàng TMCP Quân Đội - CN Hải Phòng
A22: 7 | B22: Bã vỏ điều | C22: CÔNG TY TNHH MTV GIA PHÚC HÂN | D22: Bà Trương Thị Huỳnh Như/ Giám đốc | E22: Thửa đất số 392, tờ bản đồ số 36, tổ 1, ấp bàu bàng, xã lai uyên Huyện Bàu Bàng, Tỉnh Bình Dương MST: 3702492051 | F22: 0913668489 giaphuchan2016@gmail.com | G22: 050 066 533 521 - Ngân hàng Sacombank - CN Bàu Bàng, Huyện Bàu Bàng, Tỉnh Bình Dương
A23: 8 | B23: Bã vỏ điều | C23: CÔNG TY TNHH DUY PHÁT TÂY NGUYÊN | D23: Ông Trần Phạm Tiến/ Giám đốc | E23: Số 0.50, Đường Đồng Khởi, KP 3, Phường Tam Hòa, TP. Biên Hòa, Tỉnh Đồng Nai MST: 3603866690 | F23: 0969417470 duyphattaynguyen@gmail.com | G23: 5912238666679 - Ngân hàng Agribank - CN TP Biên Hòa - Bắc Đồng Nai
A24: 9 | B24: Xăng dầu | C24: CÔNG TY TNHH TÍN THỊNH PHÁT ĐỒNG NAI | D24: Ông Huỳnh Văn Lâm/ Phó Giám đốc | E24: E17, Cư xá Tỉnh ủy, KP.1, P.Quyết Thắng, Biên Hòa, Đồng Nai MST: 3602442963 | F24: 02513947680 tinthinhphatdn@gmail.com | G24: 050028898311 - Ngân hàng Sacombank - CN Đồng Nai
A25: 10 | B25: Dầu DO | C25: CÔNG TY TNHH MTV TM XĂNG DẦU NAM TRUNG PHONG | D25: Ông Trần Quang Trung/ Giám đốc | E25: Km 119, Quốc lộ 20, Xã Phú Lợi , Huyện Định Quán, Đồng Nai MST: 3600642702 | F25: 0934118888 anhan.tptb2016@gmail.com | G25: 67010000640950 - Ngân hàng BIDV - PGD Long Khánh, Đồng Nai
A26: III. NGUYÊN LIỆU MEN - MÀU
A27: 1 | B27: Men gốm sứ FO102, FO113, Fo118, Nguyên liệu Engobe FT3 | C27: CÔNG TY TNHH KINH DOANH FRIT THỪA THIÊN HUẾ | D27: Ông Nguyễn Văn Hùng/ Giám đốc | E27: Lô 1A KCN Phú Bài, Phường Phú Bài, TT Hương Thủy, Tỉnh Thừa Thiên Huế MST: 3300350297 | F27: 0234-3851423 frithue1999@gmail.com | G27: 0161000011208 - Ngân hàng TMCP Ngoại Thương Việt Nam - CN Huế
A28: 2 | B28: Men Frit HGE91 | C28: CÔNG TY CỔ PHẦN FRIT HƯƠNG GIANG | D28: Ông Nguyễn Thanh Hải/ Giám đốc | E28: Lô CN07, Khu B, KCN Phong Điền, TT. Phong Điền, Huyện Phong Điền, Tỉnh Thừa Thiên Huế MST: 3301642694 | F28: 02343595695 huonggiangfrit@gmail.com | G28: 110002681337 - Ngân hàng Vietinbank - CN Thừa Thiên Huế
A29: 3 | B29: Bột nhôm oxit AL2O3, STPP Men | C29: CÔNG TY TNHH ĐẦU TƯ HOÀNG NAM PHÁT | D29: Ông Hoàng Văn Ngân/ Giám đốc | E29: Số A24, Đường ĐT 747B, KP. Ông Đông, Phường Tân Hiệp, TX. Tân Uyên, Tỉnh Bình Dương MST: 3702210148 | F29: 0937340999-0969701707 hoangnamphat_chem@yahoo.com.vn | G29: 0281000327486 - Ngân hàng Vietcombank - CN Bình Dương
A30: 4 | B30: Nhôm oxit | C30: CÔNG TY TNHH THƯƠNG MẠI VÀ XUẤT NHẬP KHẨU QUỐC BẢO | D30: Ông Đỗ Công Nguyên/ Giám đốc | E30: TT2-34, Khu đấu giá Tứ Hiệp- Ngũ Hiệp, Xã Tứ Hiệp, Huyện Thanh Trì, TP. Hà Nội MST: 0102817087 | F30: 02462927654 honggiangquocbao1978@gmail.com | G30: 7087888888 - Ngân hàng ACB - CN Thanh Trì, Hà Nội
A31: 5 | B31: Zircon ZS-012 | C31: CÔNG TY CỔ PHẦN LỤC GIA PHÁT | D31: Ông Nguyễn Văn Thắng/ Giám đốc | E31: 674 Lê Duẩn, Phường An Hòa, TP Huế, Tỉnh Thừa Thiên Huế MST: 3301323401 | F31: 02343588828 lucgiaphat@gmail.com | G31: 113000114549 - Ngân hàng Vietinbank - CN Thừa Thiên Huế
A32: 6 | B32: Kaolin AA Indo | C32: PT ALTER ABADI TBK | E32: GD Asean Tower 5th FL, JL KH Samanhudi No 10, Pasar Baru, Sawah Besar - DKI Jakarta, Indonesia | F32: 6221 -380-28651 | G32: 0023027523 - Ngân hàng BCA KCU PASAR BARU
A33: 7 | B33: Cao lanh men | C33: CÔNG TY CỔ PHẦN KHOÁNG SẢN-HÓA CHẤT PHÚ THỌ | D33: Ông Lê Trung Kiên/ Giám đốc | E33: Khu 7, Xã Giáp Lai, Huyện Thanh Sơn, Tỉnh Phú Thọ MST: 2600968438 | F33: 02103873239 thuyninhtspt@gmail.com | G33: 2715201004191 - Ngân hàng Agribank - CN Thanh Sơn, Phú Thọ
A34: 8 | B34: Rocima 623 | C34: CÔNG TY TNHH XUẤT NHẬP KHẨU THIÊN HÒA ĐẤT VIỆT | D34: Ông Ngô Văn Trào/ Giám đốc | E34: Thôn Thụy Lôi, Xã Thụy Lâm, Huyện Đông Anh, TP.Hà Nội MST: 0106614680 | F34: 0986068339 kaotrao@gmail.com | G34: 0541102813007 - Ngân hàng TMCP Quân đội - CN Thăng Long
A35: 9 | B35: Chất chống đông men PQ-601 | C35: CÔNG TY TNHH DV KT VÀ TM THÁI DƯƠNG | D35: Bà Nguyễn Thị Thanh Hà/ Giám đốc | E35: P406, Tòa nhà The Garden, Đường Mễ Trì, Phường Mỹ Đình 1, Quận Nam Từ Liêm, TP Hà Nội MST: 0101525606 | F35: 02437854014 nguyetntm@thanhdattrading.com.vn | G35: 0791001734005 -Ngân hàng ABBANK - Hà Nội
A36: 10 | B36: Men VTMKD | C36: CÔNG TY TNHH VITTO | D36: Ông Nguyễn Xuân Quang/ Giám đốc | E36: Lô CN 11-13, KCN La Sơn, Xã Lộc Sơn, Huyện Phú Lộc, Tỉnh Thừa Thiên Huế MST: 3301518915 | F36: 02343688545 thuongl@vthmgroup.vn | G36: 0361000111999 - Ngân hàng TMCP Ngoại Thương Việt Nam - CN Vĩnh Phúc
A37: 11 | B37: Men VF1205 | C37: CÔNG TY CỔ PHẦN VINAFRIT | D37: Ông Hà Mạnh Tuấn/ Giám đốc | E37: Lô đất diện tích 26.080,2 m2 KCN Tiền Hải, Xã Đông Cơ, Huyện Tiền Hải, Tỉnh Thái Bình MST: 1000398537 | F37: 02273653461 Huanmkd@gmail.com | G37: 47110000041251 - Ngân hàng TMCP Đầu tư & Phát triển Việt Nam - CN Thái Bình
A38: 12 | B38: Carboxymethyl cellulose (CMC) - USK70TN514, Men chống dính con lăn | C38: CÔNG TY TNHH VẬT TƯ KỸ THUẬT GỐM SỨ CERATECH | D38: Ông Nguyễn Minh Tuấn/ Giám đốc | E38: Thôn 8, Xã Xuân Quan, Huyện Văn Giang, Tỉnh Hưng Yên MST: 0900855382 | F38: 0904683835 Gomsuceratech@gmail.com | G38: 03101010662686 - Ngân hàng TMCP Hàng Hải Việt Nam - CN Đống Đa, Hà Nội
A39: 13 | B39: Phụ gia ổn định độ nhớt của men Fluicast N 40 | C39: CÔNG TY TNHH THƯƠNG MẠI KỸ THUẬT THẠCH QUANG | D39: Ông Nguyễn Xuân Quyết/ Giám đốc | E39: 195/12 Xô Viết Nghệ Tĩnh, P.17, Quận Bình Thạnh, TP.HCM MST: 0309064993 | F39: 02838411405 sales@thachquang.com.vn | G39: 0371000508427 - Ngân hàng Vietcombank - CN Tân Định, TP.HCM
A40: 14 | B40: Bột màu AL-83340, Men mài VNK00061CB | C40: CÔNG TY TNHH TORRECID VIỆT NAM | D40: Mr. Fernando Pellicer Brumos/ Managing Director | E40: KCN Long Thành, Xã Tam An, Huyện Long Thành, Tỉnh Đồng Nai MST: 3603153435 | F40: 02513514103 salesvn01@torrecid.com | G40: 7201101234003 - Ngân hàng TMCP Quân đội - CN Đồng Nai
...

Sheet TONG HOP
A1: CÔNG TY CỔ PHẦN GẠCH MEN PHƯƠNG NAM
A2: PHÒNG KẾ HOẠCH TỔNG HỢP | T2: BM. 03.14
A3: BÁO CÁO TỔNG HỢP NHẬP XUẤT TỒN NGUYÊN LIỆU XƯƠNG Tháng 07 năm 2026 (Trích xuất vào ngày 25 hàng tháng)
P4: =P25+(P25*78%) -> 0
A5: STT | B5: TÊN SP | C5: Mã hàng | E5: Mã NCC | F5: ĐVT | J5: SL tồn đầu kỳ | L5: SL nhập kho | N5: SL xuất kho | P5: SL tồn cuối kỳ | R5: Lượng dùng trung bình/ngày | S5: Số ngày còn sử dụng | T5: Ghi chú | U5: Ngày SD | V5: in
J6: Quy khô | K6: Quy ướt | L6: Quy khô | M6: Quy ướt | N6: Quy khô | O6: Quy ướt | P6: Quy khô | Q6: Quy ướt
A7: I | B7: NGUYÊN LIỆU XƯƠNG | F7: Kg | G7: Kg | H7: Kg | I7: Kg | J7: Kg | K7: Kg | L7: Kg | M7: Kg | N7: Kg | O7: Kg | P7: Kg | Q7: Kg | R7: Kg | S7: Kg | T7: TB
A8: =ROW()-7 -> 1 | B8: Bột đá nghiền (VLXDTT) loại A2 (HN01) | C8: NVLKX01.044 | D8: Bột đá nghiền (VLXDTT) loại A2 (HN01) | E8: =IF(C8="","",VLOOKUP(D8,'Danh mục CODE'!$A$2:$I$1966,2,0)) -> NCC01639 | F8: =IF(D8="","",VLOOKUP(B8,'Danh mục CODE'!$A$2:$F$790,6,0)) -> kg | J8: 0 | K8: 0 | L8: =SUMIF('NHAP - NVL'!$G$5:$G$3001,C8,'NHAP - NVL'!$J$5:$J$1207) -> 0 | M8: =SUMIF('NHAP - NVL'!$G$5:$G$3001,C8,'NHAP - NVL'!$K$5:$K$1207) -> 0 | N8: =SUMIF('XUAT - NVL'!$H$5:$H$5199,D8,'XUAT - NVL'!$K$5:$K$5199) -> 0 | O8: =SUMIF('XUAT - NVL'!$H$5:$H$5840,D8,'XUAT - NVL'!$L$5:$L$5840) -> 0 | P8: =+J8+L8-N8 -> 0 | Q8: =+K8+M8-O8 -> 0 | R8: 22000 | S8: =IF(R8="","",P8/R8) -> 0 | T8: =N8/U8 -> 0 | U8: 17 | V8: =IF(SUM(J8:P8)<>0,"in","")
A9: =ROW()-7 -> 2 | B9: Đất sét Hồng Lâm Đồng mới (PND-KL-BL01) - LQ | C9: NVLKX01.032 | D9: Đất sét Hồng Lâm Đồng mới (PND-KL-BL01) - LQ | E9: =IF(C9="","",VLOOKUP(D9,'Danh mục CODE'!$A$2:$I$1966,2,0)) -> NCC01210 | F9: =IF(D9="","",VLOOKUP(B9,'Danh mục CODE'!$A$2:$F$790,6,0)) -> kg | J9: 8914267 | K9: 11361587 | L9: =SUMIF('NHAP - NVL'!$G$5:$G$3001,C9,'NHAP - NVL'!$J$5:$J$1207) -> 0 | M9: =SUMIF('NHAP - NVL'!$G$5:$G$3001,C9,'NHAP - NVL'!$K$5:$K$1207) -> 0 | N9: =SUMIF('XUAT - NVL'!$H$5:$H$5199,D9,'XUAT - NVL'!$K$5:$K$5199) -> 292050 | O9: =SUMIF('XUAT - NVL'!$H$5:$H$5840,D9,'XUAT - NVL'!$L$5:$L$5840) -> 361120 | P9: =+J9+L9-N9 -> 8622217 | Q9: =+K9+M9-O9 -> 11000467 | R9: 19000 | S9: =IF(R9="","",P9/R9) -> 453.80089 | T9: =N9/U9 -> 17179.412 | U9: =U8 -> 17 | V9: =IF(SUM(J9:P9)<>0,"in","") -> in | W9: =IF(E9="","",VLOOKUP(E9,'Danh mục CODE'!$B$2:$C$2063,2,0)) -> CÔNG TY TNHH LONG QUANG LH
A10: =ROW()-7 -> 3 | B10: Đất sét Hoa đào (DTL) BD01 | C10: NVLKX01.033 | D10: Đất sét Hoa đào (DTL) BD01 | E10: =IF(C10="","",VLOOKUP(D10,'Danh mục CODE'!$A$2:$I$1966,2,0)) -> NCC01126 | F10: =IF(D10="","",VLOOKUP(B10,'Danh mục CODE'!$A$2:$F$790,6,0)) -> kg | J10: 7290925.4 | K10: 9414525.5 | L10: =SUMIF('NHAP - NVL'!$G$5:$G$3001,C10,'NHAP - NVL'!$J$5:$J$1207) -> 830842.5 | M10: =SUMIF('NHAP - NVL'!$G$5:$G$3001,C10,'NHAP - NVL'!$K$5:$K$1207) -> 1107790 | N10: =SUMIF('XUAT - NVL'!$H$5:$H$5199,D10,'XUAT - NVL'!$K$5:$K$5199) -> 1118700 | O10: =SUMIF('XUAT - NVL'!$H$5:$H$5840,D10,'XUAT - NVL'!$L$5:$L$5840) -> 1333780 | P10: =+J10+L10-N10 -> 7003067.9 | Q10: =+K10+M10-O10 -> 9188535.5 | R10: 73000 | S10: =IF(R10="","",P10/R10) -> 95.932437 | T10: =N10/U10 -> 65805.882 | U10: =U9 -> 17 | V10: =IF(SUM(J10:P10)<>0,"in","") -> in | W10: =IF(E10="","",VLOOKUP(E10,'Danh mục CODE'!$B$2:$C$2063,2,0)) -> CÔNG TY TNHH MTV DUY THANH LƯƠNG
A11: =ROW()-7 -> 4 | B11: Bột đá Phước Hoà 03 (PH03) DTL | C11: NVLKX01.052 | D11: Bột đá Phước Hoà 03 (PH03) DTL | E11: =IF(C11="","",VLOOKUP(D11,'Danh mục CODE'!$A$2:$I$1966,2,0)) -> NCC01126 | F11: =IF(D11="","",VLOOKUP(B11,'Danh mục CODE'!$A$2:$F$790,6,0)) -> kg | J11: 12797011 | K11: 13612212 | L11: =SUMIF('NHAP - NVL'!$G$5:$G$3001,C11,'NHAP - NVL'!$J$5:$J$1207) -> 1295458 | M11: =SUMIF('NHAP - NVL'!$G$5:$G$3001,C11,'NHAP - NVL'!$K$5:$K$1207) -> 1363640 | N11: =SUMIF('XUAT - NVL'!$H$5:$H$5199,D11,'XUAT - NVL'!$K$5:$K$5199) -> 1629925 | O11: =SUMIF('XUAT - NVL'!$H$5:$H$5840,D11,'XUAT - NVL'!$L$5:$L$5840) -> 1715720 | P11: =+J11+L11-N11 -> 12462544 | Q11: =+K11+M11-O11 -> 13260132 | R11: 94000 | S11: =IF(R11="","",P11/R11) -> 132.58026 | T11: =N11/U11 -> 95877.941 | U11: =U10 -> 17 | V11: =IF(SUM(J11:P11)<>0,"in","") -> in | W11: =IF(E11="","",VLOOKUP(E11,'Danh mục CODE'!$B$2:$C$2063,2,0)) -> CÔNG TY TNHH MTV DUY THANH LƯƠNG
A12: =ROW()-7 -> 5 | B12: Đá vôi (PND-HT01) | C12: NVLKX01.005 | D12: Đá vôi (PND-HT01) | E12: =IF(C12="","",VLOOKUP(D12,'Danh mục CODE'!$A$2:$I$1966,2,0)) -> NCC00756 | F12: =IF(D12="","",VLOOKUP(B12,'Danh mục CODE'!$A$2:$F$790,6,0)) -> kg | J12: 689591.21 | K12: 725498.5 | L12: =SUMIF('NHAP - NVL'!$G$5:$G$3001,C12,'NHAP - NVL'!$J$5:$J$1207) -> 1113752.5 | M12: =SUMIF('NHAP - NVL'!$G$5:$G$3001,C12,'NHAP - NVL'!$K$5:$K$1207) -> 1172371.1 | N12: =SUMIF('XUAT - NVL'!$H$5:$H$5199,D12,'XUAT - NVL'!$K$5:$K$5199) -> 524975 | O12: =SUMIF('XUAT - NVL'!$H$5:$H$5840,D12,'XUAT - NVL'!$L$5:$L$5840) -> 557340 | P12: =+J12+L12-N12 -> 1278368.8 | Q12: =+K12+M12-O12 -> 1340529.6 | R12: 43000 | S12: =IF(R12="","",P12/R12) -> 29.729506 | T12: =N12/U12 -> 30880.882 | U12: =U11 -> 17 | V12: =IF(SUM(J12:P12)<>0,"in","") -> in | W12: =IF(E12="","",VLOOKUP(E12,'Danh mục CODE'!$B$2:$C$2063,2,0)) -> CÔNG TY TNHH SX THƯƠNG MẠI VÀ DỊCH VỤ PHAN QUÂN
A13: =ROW()-7 -> 6 | B13: Bột đá 0-5 (PH02) | C13: NVLKX01.025 | D13: Bột đá 0-5 (PH02) | E13: =IF(C13="","",VLOOKUP(D13,'Danh mục CODE'!$A$2:$I$1966,2,0)) -> NCC01684 | F13: =IF(D13="","",VLOOKUP(B13,'Danh mục CODE'!$A$2:$F$790,6,0)) -> kg | J13: 17014842 | K13: 18155913 | L13: =SUMIF('NHAP - NVL'!$G$5:$G$3001,C13,'NHAP - NVL'!$J$5:$J$1207) -> 1328005 | M13: =SUMIF('NHAP - NVL'!$G$5:$G$3001,C13,'NHAP - NVL'!$K$5:$K$1207) -> 1397900 | N13: =SUMIF('XUAT - NVL'!$H$5:$H$5199,D13,'XUAT - NVL'!$K$5:$K$5199) -> 1892550 | O13: =SUMIF('XUAT - NVL'!$H$5:$H$5840,D13,'XUAT - NVL'!$L$5:$L$5840) -> 1969570 | P13: =+J13+L13-N13 -> 16450297 | Q13: =+K13+M13-O13 -> 17584243 | R13: 109000 | S13: =IF(R13="","",P13/R13) -> 150.92016 | T13: =N13/U13 -> 111326.47 | U13: =U12 -> 17 | V13: =IF(SUM(J13:P13)<>0,"in","") -> in | W13: =IF(E13="","",VLOOKUP(E13,'Danh mục CODE'!$B$2:$C$2063,2,0)) -> CÔNG TY TNHH DỊCH VỤ VẬN TẢI LIÊN HOÀNG PHÚC
A14: =ROW()-7 -> 7 | B14: Đất Đỏ Hoa Đào (BD02) LHP | C14: NVLKX01.043 | D14: Đất Đỏ Hoa Đào (BD02) LHP | E14: =IF(C14="","",VLOOKUP(D14,'Danh mục CODE'!$A$2:$I$1966,2,0)) -> NCC01684 | F14: =IF(D14="","",VLOOKUP(B14,'Danh mục CODE'!$A$2:$F$790,6,0)) -> kg | J14: 20608499 | K14: 25835354 | L14: =SUMIF('NHAP - NVL'!$G$5:$G$3001,C14,'NHAP - NVL'!$J$5:$J$1207) -> 2281432.5 | M14: =SUMIF('NHAP - NVL'!$G$5:$G$3001,C14,'NHAP - NVL'!$K$5:$K$1207) -> 3041910 | N14: =SUMIF('XUAT - NVL'!$H$5:$H$5199,D14,'XUAT - NVL'!$K$5:$K$5199) -> 1141800 | O14: =SUMIF('XUAT - NVL'!$H$5:$H$5840,D14,'XUAT - NVL'!$L$5:$L$5840) -> 1359330 | P14: =+J14+L14-N14 -> 21748132 | Q14: =+K14+M14-O14 -> 27517934 | R14: 73000 | S14: =IF(R14="","",P14/R14) -> 297.91961 | T14: =N14/U14 -> 67164.706 | U14: =U13 -> 17 | V14: =IF(SUM(J14:P14)<>0,"in","") -> in | W14: =IF(E14="","",VLOOKUP(E14,'Danh mục CODE'!$B$2:$C$2063,2,0)) -> CÔNG TY TNHH DỊCH VỤ VẬN TẢI LIÊN HOÀNG PHÚC
A15: =ROW()-7 -> 8 | B15: Đất sét hoa đào BD02 DTL | C15: NVLKX01.053 | D15: Đất sét hoa đào BD02 DTL | E15: =IF(C15="","",VLOOKUP(D15,'Danh mục CODE'!$A$2:$I$1966,2,0)) -> NCC01126 | F15: =IF(D15="","",VLOOKUP(B15,'Danh mục CODE'!$A$2:$F$790,6,0)) -> kg | J15: 0 | K15: 0 | L15: =SUMIF('NHAP - NVL'!$G$5:$G$3001,C15,'NHAP - NVL'!$J$5:$J$1207) -> 0 | M15: =SUMIF('NHAP - NVL'!$G$5:$G$3001,C15,'NHAP - NVL'!$K$5:$K$1207) -> 0 | N15: =SUMIF('XUAT - NVL'!$H$5:$H$5199,D15,'XUAT - NVL'!$K$5:$K$5199) -> 0 | O15: =SUMIF('XUAT - NVL'!$H$5:$H$5840,D15,'XUAT - NVL'!$L$5:$L$5840) -> 0 | P15: =+J15+L15-N15 -> 0 | Q15: =+K15+M15-O15 -> 0 | S15: =IF(R15="","",P15/R15) | T15: =N15/U15 -> 0 | U15: =U14 -> 17 | V15: =IF(SUM(J15:P15)<>0,"in","") | W15: =IF(E15="","",VLOOKUP(E15,'Danh mục CODE'!$B$2:$C$2063,2,0)) -> CÔNG TY TNHH MTV DUY THANH LƯƠNG
A16: =ROW()-7 -> 9 | B16: Thủy tinh lỏng - Nam Trường Thịnh (Natri silicate) | C16: NVLKX01.0061 | D16: Thủy tinh lỏng - Nam Trường Thịnh (Natri silicate) | E16: =IF(C16="","",VLOOKUP(D16,'Danh mục CODE'!$A$2:$I$1966,2,0)) -> NCC01412 | F16: =IF(D16="","",VLOOKUP(B16,'Danh mục CODE'!$A$2:$F$790,6,0)) -> kg | J16: 0 | K16: 0 | L16: =SUMIF('NHAP - NVL'!$G$5:$G$3001,C16,'NHAP - NVL'!$J$5:$J$1207) -> 0 | M16: =SUMIF('NHAP - NVL'!$G$5:$G$3001,C16,'NHAP - NVL'!$K$5:$K$1207) -> 0 | N16: =SUMIF('XUAT - NVL'!$H$5:$H$5199,D16,'XUAT - NVL'!$K$5:$K$5199) -> 0 | O16: =SUMIF('XUAT - NVL'!$H$5:$H$5840,D16,'XUAT - NVL'!$L$5:$L$5840) -> 0 | P16: =+J16+L16-N16 -> 0 | Q16: =+K16+M16-O16 -> 0 | R16: 8600 | S16: =IF(R16="","",P16/R16) -> 0 | T16: =N16/U16 -> 0 | U16: =U15 -> 17 | V16: =IF(SUM(J16:P16)<>0,"in","") | W16: =IF(E16="","",VLOOKUP(E16,'Danh mục CODE'!$B$2:$C$2063,2,0)) -> CÔNG TY TNHH THỦY TINH NAM TRƯỜNG THỊNH
A17: =ROW()-7 -> 10 | B17: Thủy tinh lỏng - Hóa chất Biên Hòa (Natri silicate) | C17: NVLKX01.0062 | D17: Thủy tinh lỏng - Hóa chất Biên Hòa (Natri silicate) | E17: =IF(C17="","",VLOOKUP(D17,'Danh mục CODE'!$A$2:$I$1966,2,0)) -> NCC00484 | F17: =IF(D17="","",VLOOKUP(B17,'Danh mục CODE'!$A$2:$F$790,6,0)) -> kg | J17: 0 | K17: 0 | L17: =SUMIF('NHAP - NVL'!$G$5:$G$3001,C17,'NHAP - NVL'!$J$5:$J$1207) -> 0 | M17: =SUMIF('NHAP - NVL'!$G$5:$G$3001,C17,'NHAP - NVL'!$K$5:$K$1207) -> 0 | N17: =SUMIF('XUAT - NVL'!$H$5:$H$5199,D17,'XUAT - NVL'!$K$5:$K$5199) -> 0 | O17: =SUMIF('XUAT - NVL'!$H$5:$H$5840,D17,'XUAT - NVL'!$L$5:$L$5840) -> 0 | P17: =+J17+L17-N17 -> 0 | Q17: =+K17+M17-O17 -> 0 | R17: =R16 -> 8600 | S17: =IF(R17="","",P17/R17) -> 0 | T17: =N17/U17 -> 0 | U17: =U16 -> 17 | V17: =IF(SUM(J17:P17)<>0,"in","") | W17: =IF(E17="","",VLOOKUP(E17,'Danh mục CODE'!$B$2:$C$2063,2,0)) -> NHÀ MÁY HÓA CHẤT BIÊN HÒA - CHI NHÁNH CÔNG TY CỔ PHẦN HÓA CHẤT CƠ BẢN MIỀN NAM
A18: =ROW()-7 -> 11 | B18: Thủy tinh lỏng - Ngọc Anh Đạt (Natri silicate) | C18: NVLKX01.0063 | D18: Thủy tinh lỏng - Ngọc Anh Đạt (Natri silicate) | E18: =IF(C18="","",VLOOKUP(D18,'Danh mục CODE'!$A$2:$I$1966,2,0)) -> NCC01741 | F18: =IF(D18="","",VLOOKUP(B18,'Danh mục CODE'!$A$2:$F$790,6,0)) -> kg | J18: 19518 | K18: 19518 | L18: =SUMIF('NHAP - NVL'!$G$5:$G$3001,C18,'NHAP - NVL'!$J$5:$J$1207) -> 130660 | M18: =SUMIF('NHAP - NVL'!$G$5:$G$3001,C18,'NHAP - NVL'!$K$5:$K$1207) -> 130660 | N18: =SUMIF('XUAT - NVL'!$H$5:$H$5199,D18,'XUAT - NVL'!$K$5:$K$5199) -> 138322 | O18: =SUMIF('XUAT - NVL'!$H$5:$H$5840,D18,'XUAT - NVL'!$L$5:$L$5840) -> 138322 | P18: =+J18+L18-N18 -> 11856 | Q18: =+K18+M18-O18 -> 11856 | R18: =R17 -> 8600 | S18: =IF(R18="","",P18/R18) -> 1.3786047 | T18: =N18/U18 -> 8136.5882 | U18: =U17 -> 17 | V18: =IF(SUM(J18:P18)<>0,"in","") -> in | W18: =IF(E18="","",VLOOKUP(E18,'Danh mục CODE'!$B$2:$C$2063,2,0)) -> CÔNG TY TNHH THƯƠNG MẠI DỊCH VỤ NGỌC ANH ĐẠT
A19: =ROW()-7 -> 12 | B19: Đất sét VT01 (Đất TT) | C19: NVLKX01.055 | D19: Đất sét VT01 (Đất TT) | E19: =IF(C19="","",VLOOKUP(D19,'Danh mục CODE'!$A$2:$I$1966,2,0)) -> NCC00497 | F19: =IF(D19="","",VLOOKUP(B19,'Danh mục CODE'!$A$2:$F$790,6,0)) -> kg | J19: 1901849 | K19: 2091462.9 | L19: =SUMIF('NHAP - NVL'!$G$5:$G$3001,C19,'NHAP - NVL'!$J$5:$J$1207) -> 0 | M19: =SUMIF('NHAP - NVL'!$G$5:$G$3001,C19,'NHAP - NVL'!$K$5:$K$1207) -> 0 | N19: =SUMIF('XUAT - NVL'!$H$5:$H$5199,D19,'XUAT - NVL'!$K$5:$K$5199) -> 0 | O19: =SUMIF('XUAT - NVL'!$H$5:$H$5840,D19,'XUAT - NVL'!$L$5:$L$5840) -> 0 | P19: =+J19+L19-N19 -> 1901849 | Q19: =+K19+M19-O19 -> 2091462.9 | R19: 16000 | S19: =IF(R19="","",P19/R19) -> 118.86556 | T19: =N19/U19 -> 0 | U19: =U18 -> 17 | V19: =IF(SUM(J19:P19)<>0,"in","") -> in | W19: =IF(E19="","",VLOOKUP(E19,'Danh mục CODE'!$B$2:$C$2063,2,0)) -> CÔNG TY TNHH THẠCH THÀNH KIM
A20: =ROW()-7 -> 13 | B20: Đá Tràng Thạch An Giang(AG01) | C20: NVLKX01.056 | D20: Đá Tràng Thạch An Giang(AG01) | E20: =IF(C20="","",VLOOKUP(D20,'Danh mục CODE'!$A$2:$I$1966,2,0)) -> NCC01684 | F20: =IF(D20="","",VLOOKUP(B20,'Danh mục CODE'!$A$2:$F$790,6,0)) -> kg | J20: 0 | K20: 0 | L20: =SUMIF('NHAP - NVL'!$G$5:$G$3001,C20,'NHAP - NVL'!$J$5:$J$1207) -> 0 | M20: =SUMIF('NHAP - NVL'!$G$5:$G$3001,C20,'NHAP - NVL'!$K$5:$K$1207) -> 0 | N20: =SUMIF('XUAT - NVL'!$H$5:$H$5199,D20,'XUAT - NVL'!$K$5:$K$5199) -> 0 | O20: =SUMIF('XUAT - NVL'!$H$5:$H$5840,D20,'XUAT - NVL'!$L$5:$L$5840) -> 0 | P20: =+J20+L20-N20 -> 0 | Q20: =+K20+M20-O20 -> 0 | R20: 28000 | S20: =IF(R20="","",P20/R20) -> 0 | T20: =N20/U20 -> 0 | U20: =U19 -> 17 | V20: =IF(SUM(J20:P20)<>0,"in","") | W20: =IF(E20="","",VLOOKUP(E20,'Danh mục CODE'!$B$2:$C$2063,2,0)) -> CÔNG TY TNHH DỊCH VỤ VẬN TẢI LIÊN HOÀNG PHÚC
A21: =ROW()-7 -> 14 | B21: Đất TALC | C21: NVLKX01.010 | D21: Đất TALC | E21: =IF(C21="","",VLOOKUP(D21,'Danh mục CODE'!$A$2:$I$1966,2,0)) -> NCC00498 | F21: =IF(D21="","",VLOOKUP(B21,'Danh mục CODE'!$A$2:$F$790,6,0)) -> kg | J21: 0 | K21: 0 | L21: =SUMIF('NHAP - NVL'!$G$5:$G$3001,C21,'NHAP - NVL'!$J$5:$J$1207) -> 0 | M21: =SUMIF('NHAP - NVL'!$G$5:$G$3001,C21,'NHAP - NVL'!$K$5:$K$1207) -> 0 | N21: =SUMIF('XUAT - NVL'!$H$5:$H$5199,D21,'XUAT - NVL'!$K$5:$K$5199) -> 0 | O21: =SUMIF('XUAT - NVL'!$H$5:$H$5840,D21,'XUAT - NVL'!$L$5:$L$5840) -> 0 | P21: =+J21+L21-N21 -> 0 | Q21: =+K21+M21-O21 -> 0 | R21: 11000 | S21: =IF(R21="","",P21/R21) -> 0 | T21: =N21/U21 -> 0 | U21: =U20 -> 17 | V21: =IF(SUM(J21:P21)<>0,"in","") | W21: =IF(E21="","",VLOOKUP(E21,'Danh mục CODE'!$B$2:$C$2063,2,0)) -> CÔNG TY CỔ PHẦN VLXD VIDONA
A22: =ROW()-7 -> 15 | B22: Đá Tràng Thạch An Giang(AG02) | C22: NVLKX01.058 | D22: Đá Tràng Thạch An Giang(AG02) | E22: =IF(C22="","",VLOOKUP(D22,'Danh mục CODE'!$A$2:$I$1966,2,0)) -> NCC01126 | F22: =IF(D22="","",VLOOKUP(B22,'Danh mục CODE'!$A$2:$F$790,6,0)) -> kg | J22: 0 | K22: 0 | L22: =SUMIF('NHAP - NVL'!$G$5:$G$3001,C22,'NHAP - NVL'!$J$5:$J$1207) -> 0 | M22: =SUMIF('NHAP - NVL'!$G$5:$G$3001,C22,'NHAP - NVL'!$K$5:$K$1207) -> 0 | N22: =SUMIF('XUAT - NVL'!$H$5:$H$5199,D22,'XUAT - NVL'!$K$5:$K$5199) -> 0 | O22: =SUMIF('XUAT - NVL'!$H$5:$H$5840,D22,'XUAT - NVL'!$L$5:$L$5840) -> 0 | P22: =+J22+L22-N22 -> 0 | Q22: =+K22+M22-O22 -> 0 | R22: =R20 -> 28000 | S22: =IF(R22="","",P22/R22) -> 0 | T22: =N22/U22 -> 0 | U22: =U21 -> 17 | V22: =IF(SUM(J22:P22)<>0,"in","") | W22: =IF(E22="","",VLOOKUP(E22,'Danh mục CODE'!$B$2:$C$2063,2,0)) -> CÔNG TY TNHH MTV DUY THANH LƯƠNG
A23: =ROW()-7 -> 16 | B23: Đất VT02 | C23: NVLKX01.059 | D23: Đất VT02 | E23: =IF(C23="","",VLOOKUP(D23,'Danh mục CODE'!$A$2:$I$1966,2,0)) -> NCC00499 | F23: =IF(D23="","",VLOOKUP(B23,'Danh mục CODE'!$A$2:$F$790,6,0)) -> kg | J23: 9033334 | K23: 11056743 | L23: =SUMIF('NHAP - NVL'!$G$5:$G$3001,C23,'NHAP - NVL'!$J$5:$J$1207) -> 0 | M23: =SUMIF('NHAP - NVL'!$G$5:$G$3001,C23,'NHAP - NVL'!$K$5:$K$1207) -> 0 | N23: =SUMIF('XUAT - NVL'!$H$5:$H$5199,D23,'XUAT - NVL'!$K$5:$K$5199) -> 1183600 | O23: =SUMIF('XUAT - NVL'!$H$5:$H$5840,D23,'XUAT - NVL'!$L$5:$L$5840) -> 1412880 | P23: =+J23+L23-N23 -> 7849734 | Q23: =+K23+M23-O23 -> 9643863.5 | R23: 85000 | S23: =IF(R23="","",P23/R23) -> 92.349812 | T23: =N23/U23 -> 69623.529 | U23: =U22 -> 17 | V23: =IF(SUM(J23:P23)<>0,"in","") -> in | W23: =IF(E23="","",VLOOKUP(E23,'Danh mục CODE'!$B$2:$C$2063,2,0)) -> CÔNG TY TNHH NGÂN HÙNG PHÚC
A24: =IF(B24="","",A23+1) -> 17 | B24: Dolomite (Đất làm gạch A2) | C24: NVLKX01.009 | D24: Dolomite (Đất làm gạch A2) | E24: =IF(C24="","",VLOOKUP(D24,'Danh mục CODE'!$A$2:$I$1966,2,0)) -> NCC00500 | F24: =IF(D24="","",VLOOKUP(B24,'Danh mục CODE'!$A$2:$F$790,6,0)) -> kg | J24: 1657845 | K24: 1974974 | L24: =SUMIF('NHAP - NVL'!$G$5:$G$3001,C24,'NHAP - NVL'!$J$5:$J$1207) -> 0 | M24: =SUMIF('NHAP - NVL'!$G$5:$G$3001,C24,'NHAP - NVL'!$K$5:$K$1207) -> 0 | N24: =SUMIF('XUAT - NVL'!$H$5:$H$5199,D24,'XUAT - NVL'!$K$5:$K$5199) -> 99000 | O24: =SUMIF('XUAT - NVL'!$H$5:$H$5840,D24,'XUAT - NVL'!$L$5:$L$5840) -> 119310 | P24: =+J24+L24-N24 -> 1558845 | Q24: =+K24+M24-O24 -> 1855664 | R24: 15000 | S24: =IF(R24="","",P24/R24) -> 103.923 | T24: =N24/U24 -> 5823.5294 | U24: =U23 -> 17 | V24: =IF(SUM(J24:P24)<>0,"in","") -> in | W24: =IF(E24="","",VLOOKUP(E24,'Danh mục CODE'!$B$2:$C$2063,2,0)) -> CÔNG TY TNHH PT HẠ TẦNG ĐỨC ANH
A25: =ROW()-7 -> 18 | B25: Đất TT (VC01) | C25: NVLKX01.061 | D25: Đất TT (VC01) | E25: =IF(C25="","",VLOOKUP(D25,'Danh mục CODE'!$A$2:$I$1966,2,0)) -> NCC00501 | F25: =IF(D25="","",VLOOKUP(B25,'Danh mục CODE'!$A$2:$F$790,6,0)) -> kg | J25: 0 | K25: 0 | L25: =SUMIF('NHAP - NVL'!$G$5:$G$3001,C25,'NHAP - NVL'!$J$5:$J$1207) -> 0 | M25: =SUMIF('NHAP - NVL'!$G$5:$G$3001,C25,'NHAP - NVL'!$K$5:$K$1207) -> 0 | N25: =SUMIF('XUAT - NVL'!$H$5:$H$5199,D25,'XUAT - NVL'!$K$5:$K$5199) -> 0 | O25: =SUMIF('XUAT - NVL'!$H$5:$H$5840,D25,'XUAT - NVL'!$L$5:$L$5840) -> 0 | P25: =+J25+L25-N25 -> 0 | Q25: =+K25+M25-O25 -> 0 | R25: 125000 | S25: =IF(R25="","",P25/R25) -> 0 | T25: =N25/U25 -> 0 | U25: =U24 -> 17 | V25: =IF(SUM(J25:P25)<>0,"in","") | W25: =IF(E25="","",VLOOKUP(E25,'Danh mục CODE'!$B$2:$C$2063,2,0)) -> CÔNG TY CP GẠCH MEN SA HA DO
A26: =ROW()-7 -> 19 | B26: Đất VC08 | C26: NVLKX01.068 | D26: Đất VC08 | E26: =IF(C26="","",VLOOKUP(D26,'Danh mục CODE'!$A$2:$I$1966,2,0)) -> NCC04896 | F26: =IF(D26="","",VLOOKUP(B26,'Danh mục CODE'!$A$2:$F$790,6,0)) -> kg | J26: 13373 | K26: 17830 | L26: =SUMIF('NHAP - NVL'!$G$5:$G$3001,C26,'NHAP - NVL'!$J$5:$J$1207) -> 0 | M26: =SUMIF('NHAP - NVL'!$G$5:$G$3001,C26,'NHAP - NVL'!$K$5:$K$1207) -> 0 | N26: =SUMIF('XUAT - NVL'!$H$5:$H$5199,D26,'XUAT - NVL'!$K$5:$K$5199) -> 0 | O26: =SUMIF('XUAT - NVL'!$H$5:$H$5840,D26,'XUAT - NVL'!$L$5:$L$5840) -> 0 | P26: =+J26+L26-N26 -> 13373 | Q26: =+K26+M26-O26 -> 17830 | R26: 176000 | S26: =IF(R26="","",P26/R26) -> 0.075982955 | T26: =N26/U26 -> 0 | U26: =U25 -> 17 | V26: =IF(SUM(J26:P26)<>0,"in","") -> in | W26: =IF(E26="","",VLOOKUP(E26,'Danh mục CODE'!$B$2:$C$2063,2,0)) -> CÔNG TY TNHH DỊCH VỤ THƯƠNG MẠI VẬN TẢI NAM TUẤN PHÁT
A27: =ROW()-7 -> 20 | B27: Đất NTP01 | C27: NVLKX01.067 | D27: Đất NTP01 | E27: =IF(C27="","",VLOOKUP(D27,'Danh mục CODE'!$A$2:$I$1966,2,0)) -> NCC04896 | F27: =IF(D27="","",VLOOKUP(B27,'Danh mục CODE'!$A$2:$F$790,6,0)) -> kg | J27: 0 | K27: 0 | L27: =SUMIF('NHAP - NVL'!$G$5:$G$3001,C27,'NHAP - NVL'!$J$5:$J$1207) -> 0 | M27: =SUMIF('NHAP - NVL'!$G$5:$G$3001,C27,'NHAP - NVL'!$K$5:$K$1207) -> 0 | N27: =SUMIF('XUAT - NVL'!$H$5:$H$5199,D27,'XUAT - NVL'!$K$5:$K$5199) -> 0 | O27: =SUMIF('XUAT - NVL'!$H$5:$H$5840,D27,'XUAT - NVL'!$L$5:$L$5840) -> 0 | P27: =+J27+L27-N27 -> 0 | Q27: =+K27+M27-O27 -> 0 | R27: 38000 | S27: =IF(R27="","",P27/R27) -> 0 | T27: =N27/U27 -> 0 | U27: =U26 -> 17 | V27: =IF(SUM(J27:P27)<>0,"in","") | W27: =IF(E27="","",VLOOKUP(E27,'Danh mục CODE'!$B$2:$C$2063,2,0)) -> CÔNG TY TNHH DỊCH VỤ THƯƠNG MẠI VẬN TẢI NAM TUẤN PHÁT
A28: =ROW()-7 -> 21 | B28: Đất VC02 (Đất TT) | C28: NVLKX01.064 | D28: Đất VC02 (Đất TT) | E28: =IF(C28="","",VLOOKUP(D28,'Danh mục CODE'!$A$2:$I$1966,2,0)) -> NCC00503 | F28: =IF(D28="","",VLOOKUP(B28,'Danh mục CODE'!$A$2:$F$790,6,0)) -> kg | J28: 12418317 | K28: 12483053 | L28: =SUMIF('NHAP - NVL'!$G$5:$G$3001,C28,'NHAP - NVL'!$J$5:$J$1207) -> 0 | M28: =SUMIF('NHAP - NVL'!$G$5:$G$3001,C28,'NHAP - NVL'!$K$5:$K$1207) -> 0 | N28: =SUMIF('XUAT - NVL'!$H$5:$H$5199,D28,'XUAT - NVL'!$K$5:$K$5199) -> 1371975 | O28: =SUMIF('XUAT - NVL'!$H$5:$H$5840,D28,'XUAT - NVL'!$L$5:$L$5840) -> 1664090 | P28: =+J28+L28-N28 -> 11046342 | Q28: =+K28+M28-O28 -> 10818963 | R28: 91000 | S28: =IF(R28="","",P28/R28) -> 121.38838 | T28: =N28/U28 -> 80704.412 | U28: =U27 -> 17 | V28: =IF(SUM(J28:P28)<>0,"in","") -> in | W28: =IF(E28="","",VLOOKUP(E28,'Danh mục CODE'!$B$2:$C$2063,2,0)) -> CÔNG TY TNHH GẠCH THÀNH PHÁT
A29: =ROW()-7 -> 22 | B29: Đá 0.5 mm3 (Bột đá PH04) | C29: NVLKX01.069 | D29: Đá 0.5 mm3 (Bột đá PH04) | E29: =IF(C29="","",VLOOKUP(D29,'Danh mục CODE'!$A$2:$I$1966,2,0)) -> NCC04947 | F29: =IF(D29="","",VLOOKUP(B29,'Danh mục CODE'!$A$2:$F$790,6,0)) -> kg | J29: 0 | K29: 0 | L29: =SUMIF('NHAP - NVL'!$G$5:$G$3001,C29,'NHAP - NVL'!$J$5:$J$1207) -> 86269.5 | M29: =SUMIF('NHAP - NVL'!$G$5:$G$3001,C29,'NHAP - NVL'!$K$5:$K$1207) -> 90810 | N29: =SUMIF('XUAT - NVL'!$H$5:$H$5199,D29,'XUAT - NVL'!$K$5:$K$5199) -> 0 | O29: =SUMIF('XUAT - NVL'!$H$5:$H$5840,D29,'XUAT - NVL'!$L$5:$L$5840) -> 0 | P29: =+J29+L29-N29 -> 86269.5 | Q29: =+K29+M29-O29 -> 90810 | R29: 16500 | S29: =IF(R29="","",P29/R29) -> 5.2284545 | T29: =N29/U29 -> 0 | U29: =U28 -> 17 | V29: =IF(SUM(J29:P29)<>0,"in","") -> in | W29: =IF(E29="","",VLOOKUP(E29,'Danh mục CODE'!$B$2:$C$2063,2,0)) -> CÔNG TY TNHH DỊCH VỤ THƯƠNG MẠI VẬN TẢI NAM PHÚC KHANG
A30: II | B30: NHIÊN LIỆU | E30: Kg | F30: =IF(D30="","",VLOOKUP(B30,'Danh mục CODE'!$A$2:$F$790,6,0)) | G30: Kg | H30: Kg | I30: Kg | J30: Kg | K30: Kg | L30: Kg | M30: Kg | N30: Kg | O30: Kg | P30: Kg | Q30: Kg | R30: Kg | S30: Kg | V30: =IF(SUM(J30:P30)<>0,"in","") | W30: =IF(E30="","",VLOOKUP(E30,'Danh mục CODE'!$B$2:$C$2063,2,0)) -> #N/A
A31: =ROW()-30 -> 1 | B31: Than cục 4- Hải Giang | C31: NLT4.HG01 | D31: Than cục 4- Hải Giang | E31: =IF(C31="","",VLOOKUP(D31,'Danh mục CODE'!$A$2:$I$1966,2,0)) -> NCC01729 | F31: =IF(D31="","",VLOOKUP(B31,'Danh mục CODE'!$A$2:$F$790,6,0)) -> kg | J31: 0 | K31: 0 | L31: =SUMIF('NHAP - NVL'!$G$5:$G$3001,C31,'NHAP - NVL'!$J$5:$J$2001) -> 0 | M31: =SUMIF('NHAP - NVL'!$G$5:$G$3001,C31,'NHAP - NVL'!$K$5:$K$2001) -> 0 | N31: =SUMIF('XUAT - NVL'!$H$5:$H$5199,D31,'XUAT - NVL'!$K$5:$K$5199) -> 0 | O31: =SUMIF('XUAT - NVL'!$H$5:$H$5199,D31,'XUAT - NVL'!$L$5:$L$5199) -> 0 | P31: =+J31+L31-N31 -> 0 | Q31: =+K31+M31-O31 -> 0 | R31: 72000 | S31: =IF(R31="","",Q31/R31) -> 0 | T31: =O31/U31 -> 0 | U31: =U28 -> 17 | V31: =IF(SUM(J31:P31)<>0,"in","") | W31: =IF(E31="","",VLOOKUP(E31,'Danh mục CODE'!$B$2:$C$2063,2,0)) -> CÔNG TY CỔ PHẦN HẢI GIANG
A32: =ROW()-30 -> 2 | B32: Than cục 4- Huyền Trang Lô 1 | C32: NLT4.HT01 | D32: Than cục 4- Huyền Trang Lô 1 | E32: =IF(C32="","",VLOOKUP(D32,'Danh mục CODE'!$A$2:$I$1966,2,0)) -> NCC00824 | F32: =IF(D32="","",VLOOKUP(B32,'Danh mục CODE'!$A$2:$F$790,6,0)) -> kg | J32: 0 | K32: 0 | L32: =SUMIF('NHAP - NVL'!$G$5:$G$3001,C32,'NHAP - NVL'!$J$5:$J$2001) -> 0 | M32: =SUMIF('NHAP - NVL'!$G$5:$G$3001,C32,'NHAP - NVL'!$K$5:$K$2001) -> 0 | N32: =SUMIF('XUAT - NVL'!$H$5:$H$5199,D32,'XUAT - NVL'!$K$5:$K$5199) -> 0 | O32: =SUMIF('XUAT - NVL'!$H$5:$H$5199,D32,'XUAT - NVL'!$L$5:$L$5199) -> 0 | P32: 0 | Q32: =+K32+M32-O32 -> 0 | R32: 65000 | S32: =IF(R32="","",Q32/R32) -> 0 | T32: =O32/U32 -> 0 | U32: =U31 -> 17 | V32: =IF(SUM(J32:P32)<>0,"in","") | W32: =IF(E32="","",VLOOKUP(E32,'Danh mục CODE'!$B$2:$C$2063,2,0)) -> CÔNG TY CỔ PHẦN KHOÁNG SẢN HUYỀN TRANG
A33: =ROW()-30 -> 3 | B33: Than cục 4- Huyền Trang Lô 2 | C33: NLT4.HT02 | D33: Than cục 4- Huyền Trang Lô 2 | E33: =IF(C33="","",VLOOKUP(D33,'Danh mục CODE'!$A$2:$I$1966,2,0)) -> NCC00824 | F33: =IF(D33="","",VLOOKUP(B33,'Danh mục CODE'!$A$2:$F$790,6,0)) -> kg | J33: 0 | K33: 0 | L33: =SUMIF('NHAP - NVL'!$G$5:$G$3001,C33,'NHAP - NVL'!$J$5:$J$2001) -> 0 | M33: =SUMIF('NHAP - NVL'!$G$5:$G$3001,C33,'NHAP - NVL'!$K$5:$K$2001) -> 0 | N33: =SUMIF('XUAT - NVL'!$H$5:$H$5199,D33,'XUAT - NVL'!$K$5:$K$5199) -> 0 | O33: =SUMIF('XUAT - NVL'!$H$5:$H$5199,D33,'XUAT - NVL'!$L$5:$L$5199) -> 0 | P33: =+J33+L33-N33 -> 0 | Q33: =+K33+M33-O33 -> 0 | R33: 80000 | S33: =IF(R33="","",Q33/R33) -> 0 | T33: =O33/U33 -> 0 | U33: =U32 -> 17 | V33: =IF(SUM(J33:P33)<>0,"in","") | W33: =IF(E33="","",VLOOKUP(E33,'Danh mục CODE'!$B$2:$C$2063,2,0)) -> CÔNG TY CỔ PHẦN KHOÁNG SẢN HUYỀN TRANG
A34: =ROW()-30 -> 4 | B34: Than cục 4- Huyền Trang Lô 3 | C34: NLT4.HT03 | D34: Than cục 4- Huyền Trang Lô 3 | E34: =IF(C34="","",VLOOKUP(D34,'Danh mục CODE'!$A$2:$I$1966,2,0)) -> NCC00824 | F34: =IF(D34="","",VLOOKUP(B34,'Danh mục CODE'!$A$2:$F$790,6,0)) -> kg | J34: 0 | K34: 0 | L34: =SUMIF('NHAP - NVL'!$G$5:$G$3001,C34,'NHAP - NVL'!$J$5:$J$2001) -> 0 | M34: =SUMIF('NHAP - NVL'!$G$5:$G$3001,C34,'NHAP - NVL'!$K$5:$K$2001) -> 0 | N34: =SUMIF('XUAT - NVL'!$H$5:$H$5199,D34,'XUAT - NVL'!$K$5:$K$5199) -> 0 | O34: =SUMIF('XUAT - NVL'!$H$5:$H$5199,D34,'XUAT - NVL'!$L$5:$L$5199) -> 0 | P34: =+J34+L34-N34 -> 0 | Q34: =+K34+M34-O34 -> 0 | R34: 73000 | S34: =IF(R34="","",Q34/R34) -> 0 | T34: =O34/U34 -> 0 | U34: =U33 -> 17
A35: =ROW()-30 -> 5 | B35: Than cục 4- Thịnh Huyền Lô 1 | C35: NLT4.TH01 | D35: Than cục 4- Thịnh Huyền Lô 1 | E35: =IF(C35="","",VLOOKUP(D35,'Danh mục CODE'!$A$2:$I$1966,2,0)) -> KH00166 | F35: =IF(D35="","",VLOOKUP(B35,'Danh mục CODE'!$A$2:$F$790,6,0)) -> kg | J35: 0 | K35: 0 | L35: =SUMIF('NHAP - NVL'!$G$5:$G$3001,C35,'NHAP - NVL'!$J$5:$J$2001) -> 0 | M35: =SUMIF('NHAP - NVL'!$G$5:$G$3001,C35,'NHAP - NVL'!$K$5:$K$2001) -> 0 | N35: =SUMIF('XUAT - NVL'!$H$5:$H$5199,D35,'XUAT - NVL'!$K$5:$K$5199) -> 0 | O35: =SUMIF('XUAT - NVL'!$H$5:$H$5199,D35,'XUAT - NVL'!$L$5:$L$5199) -> 0 | P35: 0 | Q35: =+K35+M35-O35 -> 0 | R35: 85000 | S35: =IF(R35="","",Q35/R35) -> 0 | T35: =O35/U35 -> 0 | U35: =U34 -> 17 | V35: =IF(SUM(J35:P35)<>0,"in","") | W35: =IF(E35="","",VLOOKUP(E35,'Danh mục CODE'!$B$2:$C$2063,2,0)) -> CÔNG TY TNHH THAN THỊNH HUYỀN
A36: =ROW()-30 -> 6 | B36: Than cục 4- Thịnh Huyền Lô 2 | C36: NLT4.TH02 | D36: Than cục 4- Thịnh Huyền Lô 2 | E36: =IF(C36="","",VLOOKUP(D36,'Danh mục CODE'!$A$2:$I$1966,2,0)) -> KH00166 | F36: =IF(D36="","",VLOOKUP(B36,'Danh mục CODE'!$A$2:$F$790,6,0)) -> kg | J36: 0 | K36: 0 | L36: =SUMIF('NHAP - NVL'!$G$5:$G$3001,C36,'NHAP - NVL'!$J$5:$J$2001) -> 0 | M36: =SUMIF('NHAP - NVL'!$G$5:$G$3001,C36,'NHAP - NVL'!$K$5:$K$2001) -> 0 | N36: =SUMIF('XUAT - NVL'!$H$5:$H$5199,D36,'XUAT - NVL'!$K$5:$K$5199) -> 0 | O36: =SUMIF('XUAT - NVL'!$H$5:$H$5199,D36,'XUAT - NVL'!$L$5:$L$5199) -> 0 | P36: 0 | Q36: =+K36+M36-O36 -> 0 | R36: 77000 | S36: =IF(R36="","",Q36/R36) -> 0 | T36: =O36/U36 -> 0 | U36: =U35 -> 17
A37: =ROW()-30 -> 7 | B37: Than cục 4- Đông Bắc 01 | C37: NLT4.DB01 | D37: Than cục 4- Đông Bắc 01 | E37: =IF(C37="","",VLOOKUP(D37,'Danh mục CODE'!$A$2:$I$1966,2,0)) -> NCC00721 | F37: =IF(D37="","",VLOOKUP(B37,'Danh mục CODE'!$A$2:$F$790,6,0)) -> kg | J37: 0 | K37: 0 | L37: =SUMIF('NHAP - NVL'!$G$5:$G$3001,C37,'NHAP - NVL'!$J$5:$J$2001) -> 0 | M37: =SUMIF('NHAP - NVL'!$G$5:$G$3001,C37,'NHAP - NVL'!$K$5:$K$2001) -> 0 | N37: =SUMIF('XUAT - NVL'!$H$5:$H$5199,D37,'XUAT - NVL'!$K$5:$K$5199) -> 0 | O37: =SUMIF('XUAT - NVL'!$H$5:$H$5199,D37,'XUAT - NVL'!$L$5:$L$5199) -> 0 | P37: 0 | Q37: =+K37+M37-O37 -> 0 | R37: 71000 | S37: =IF(R37="","",Q37/R37) -> 0 | T37: =O37/U37 -> 0 | U37: =U36 -> 17 | V37: =IF(SUM(J37:P37)<>0,"in","") | W37: =IF(E37="","",VLOOKUP(E37,'Danh mục CODE'!$B$2:$C$2063,2,0)) -> CÔNG TY TNHH TM KHOÁNG SẢN ĐÔNG BẮC
A38: =ROW()-30 -> 8 | B38: Than cục 4- Đông Bắc 02 | C38: NLT4.DB02 | D38: Than cục 4- Đông Bắc 02 | E38: =IF(C38="","",VLOOKUP(D38,'Danh mục CODE'!$A$2:$I$1966,2,0)) -> NCC00721 | F38: =IF(D38="","",VLOOKUP(B38,'Danh mục CODE'!$A$2:$F$790,6,0)) -> kg | J38: 0 | K38: 0 | L38: =SUMIF('NHAP - NVL'!$G$5:$G$3001,C38,'NHAP - NVL'!$J$5:$J$2001) -> 0 | M38: =SUMIF('NHAP - NVL'!$G$5:$G$3001,C38,'NHAP - NVL'!$K$5:$K$2001) -> 0 | N38: =SUMIF('XUAT - NVL'!$H$5:$H$5199,D38,'XUAT - NVL'!$K$5:$K$5199) -> 0 | O38: =SUMIF('XUAT - NVL'!$H$5:$H$5199,D38,'XUAT - NVL'!$L$5:$L$5199) -> 0 | P38: 0 | Q38: =+K38+M38-O38 -> 0 | R38: 71000 | S38: =IF(R38="","",Q38/R38) -> 0 | T38: =O38/U38 -> 0 | U38: =U37 -> 17 | V38: =IF(SUM(J38:P38)<>0,"in","") | W38: =IF(E38="","",VLOOKUP(E38,'Danh mục CODE'!$B$2:$C$2063,2,0)) -> CÔNG TY TNHH TM KHOÁNG SẢN ĐÔNG BẮC
A39: =ROW()-30 -> 9 | B39: Than cục 4- Hải Minh | C39: NLT4.HM01 | D39: Than cục 4- Hải Minh | E39: =IF(C39="","",VLOOKUP(D39,'Danh mục CODE'!$A$2:$I$1966,2,0)) -> NCC00843 | F39: =IF(D39="","",VLOOKUP(B39,'Danh mục CODE'!$A$2:$F$790,6,0)) -> kg | J39: 0 | K39: 0 | L39: =SUMIF('NHAP - NVL'!$G$5:$G$3001,C39,'NHAP - NVL'!$J$5:$J$2001) -> 0 | M39: =SUMIF('NHAP - NVL'!$G$5:$G$3001,C39,'NHAP - NVL'!$K$5:$K$2001) -> 0 | N39: =SUMIF('XUAT - NVL'!$H$5:$H$5199,D39,'XUAT - NVL'!$K$5:$K$5199) -> 0 | O39: =SUMIF('XUAT - NVL'!$H$5:$H$5199,D39,'XUAT - NVL'!$L$5:$L$5199) -> 0 | P39: =+J39+L39-N39 -> 0 | Q39: =+K39+M39-O39 -> 0 | R39: 72000 | S39: =IF(R39="","",Q39/R39) -> 0 | T39: =O39/U39 -> 0 | U39: =U38 -> 17 | V39: =IF(SUM(J39:P39)<>0,"in","") | W39: =IF(E39="","",VLOOKUP(E39,'Danh mục CODE'!$B$2:$C$2063,2,0)) -> CÔNG TY TNHH THƯƠNG MẠI KHOÁNG SẢN HẢI MINH
A40: =ROW()-30 -> 10 | B40: Than cục 4- Đức Anh 01 | C40: NLT4.DA01 | D40: Than cục 4- Đức Anh 01 | E40: =IF(C40="","",VLOOKUP(D40,'Danh mục CODE'!$A$2:$I$1966,2,0)) -> NCC01651 | F40: =IF(D40="","",VLOOKUP(B40,'Danh mục CODE'!$A$2:$F$790,6,0)) -> kg | J40: 0 | K40: 0 | L40: =SUMIF('NHAP - NVL'!$G$5:$G$3001,C40,'NHAP - NVL'!$J$5:$J$2001) -> 0 | M40: =SUMIF('NHAP - NVL'!$G$5:$G$3001,C40,'NHAP - NVL'!$K$5:$K$2001) -> 0 | N40: =SUMIF('XUAT - NVL'!$H$5:$H$5199,D40,'XUAT - NVL'!$K$5:$K$5199) -> 0 | O40: =SUMIF('XUAT - NVL'!$H$5:$H$5199,D40,'XUAT - NVL'!$L$5:$L$5199) -> 0 | P40: 0 | Q40: =+K40+M40-O40 -> 0 | R40: 85000 | S40: =IF(R40="","",Q40/R40) -> 0 | T40: =O40/U40 -> 0 | U40: =U39 -> 17 | V40: =IF(SUM(J40:P40)<>0,"in","") | W40: =IF(E40="","",VLOOKUP(E40,'Danh mục CODE'!$B$2:$C$2063,2,0)) -> CÔNG TY TNHH SX&TM ĐỨC ANH
...

Sheet NHAP - NVL
E1: NHẬP NGUYÊN LIỆU
F3: =NOW() -> 46252.412 | J3: =SUBTOTAL(9,J5:J4001) -> 10735907 | K3: =SUBTOTAL(9,K5:K4001) -> 12226370 | T3: =SUBTOTAL(9,T5:T2001) -> 404175.01 | U3: =SUBTOTAL(9,U5:U2001) -> 0
A4: STT | B4: Số PN | C4: Kho | D4: NGÀY | E4: MKH | F4: TÊN KHÁCH HÀNG | G4: Mã hàng | H4: Tên hàng | I4: ĐVT | J4: Nhập kho quy khô | K4: Nhập kho quy ướt | L4: Trọng lượng hàng qua cân | M4: Độ ẩm HĐ | N4: Độ ẩm kiểm tra | O4: Độ ẩm vượt TC | P4: Tỷ lệ cám HĐ | Q4: Tỷ lệ cám kiểm tra | R4: Tỷ lệ cám vượt tiêu chuẩn | S4: Than cục | T4: Trọng lượng cám tiêu chuẩn | U4: Trọng lượng cám vượt tiêu chuẩn | W4: Tháng | X4: Trọng lượng cân vào | Y4: Trọng lượng cân ra | Z4: Mã Phiếu | AA4: Số xe | AC4: Tên nguyên vật liệu | AD4: Mã KH | AE4: Tên khách hàng | AF4: MÃ HÓA | AG4: Mã hàng | AH4: ĐVT tính
A5: 1 | B5: KX/08/01 | C5: Kho xương | D5: 01/08/2026 | E5: =IF(G5="","",VLOOKUP(G5,'Danh mục CODE'!$D$2:$J$20064,7,0)) -> NCC01126 | F5: =IF(E5="","",VLOOKUP(E5,'TONG HOP'!$E$8:$W$1883,19,0)) -> CÔNG TY TNHH MTV DUY THANH LƯƠNG | G5: NVLKX01.052 | H5: =IF(E5="","",VLOOKUP(G5,'TONG HOP'!$C$8:$E$799,2,0)) -> Bột đá Phước Hoà 03 (PH03) DTL | I5: =IF(B5="","",VLOOKUP(G5,'TONG HOP'!$C$8:$F$799,4,0)) -> kg | J5: =IF(X5="","",K5-K5*M5) -> 29402.5 | K5: =IF(AND(X5="",N5="",Q5="",R5=""),"",L5-L5*O5-(L5-L5*O5)*R5) -> 30950 | L5: =X5-Y5 -> 30950 | M5: =IF(Y5="","",VLOOKUP(G5,'Danh mục CODE'!$D$2:$I$1880,4,0)) -> 0.05 | N5: 0.044 | O5: =IF(X5="","",IF(M5-N5<0,-(M5-N5),0)) -> 0 | P5: =IF(Y5="","",VLOOKUP(G5,'Danh mục CODE'!$D$2:$I$1880,5,0)) -> 0 | R5: =IF(X5="","",IF(P5-Q5<0,-(P5-Q5),0)) -> 0 | S5: =IF(T5=0,"",J5-T5-U5) | T5: =IF(X5="","",IF(Q5<P5,K5*Q5,K5*P5)) -> 0 | U5: =IF(X5="","",K5*R5) -> 0 | V5: =IF(X5="","",J5-S5-T5-U5) -> #VALUE! | X5: 47390 | Y5: 16440 | Z5: 1162 | AA5: 60C-21187 | AC5: Đất sét Vĩnh Cửu (PND-VC01) | AD5: NCC00841 | AE5: CÔNG TY CP GẠCH MEN SA HA DO | AG5: NVLKX01.001 | AH5: kg
A6: =A5+1 -> 2 | B6: KX/08/01 | C6: Kho xương | D6: 01/08/2026 | E6: =IF(G6="","",VLOOKUP(G6,'Danh mục CODE'!$D$2:$J$20064,7,0)) -> NCC01126 | F6: =IF(E6="","",VLOOKUP(E6,'TONG HOP'!$E$8:$W$1883,19,0)) -> CÔNG TY TNHH MTV DUY THANH LƯƠNG | G6: NVLKX01.052 | H6: =IF(E6="","",VLOOKUP(G6,'TONG HOP'!$C$8:$E$799,2,0)) -> Bột đá Phước Hoà 03 (PH03) DTL | I6: =IF(B6="","",VLOOKUP(G6,'TONG HOP'!$C$8:$F$799,4,0)) -> kg | J6: =IF(X6="","",K6-K6*M6) -> 32585 | K6: =IF(AND(X6="",N6="",Q6="",R6=""),"",L6-L6*O6-(L6-L6*O6)*R6) -> 34300 | L6: =X6-Y6 -> 34300 | M6: =IF(Y6="","",VLOOKUP(G6,'Danh mục CODE'!$D$2:$I$1880,4,0)) -> 0.05 | N6: 0.044 | O6: =IF(X6="","",IF(M6-N6<0,-(M6-N6),0)) -> 0 | P6: =IF(Y6="","",VLOOKUP(G6,'Danh mục CODE'!$D$2:$I$1880,5,0)) -> 0 | R6: =IF(X6="","",IF(P6-Q6<0,-(P6-Q6),0)) -> 0 | S6: =IF(T6=0,"",J6-T6-U6) | T6: =IF(X6="","",IF(Q6<P6,K6*Q6,K6*P6)) -> 0 | U6: =IF(X6="","",K6*R6) -> 0 | V6: =IF(X6="","",J6-S6-T6-U6) -> #VALUE! | X6: 51020 | Y6: 16720 | Z6: 1182 | AA6: 60C-22878 | AC6: PND-VC01NB07 | AD6: NCC00842 | AE6: CÔNG TY CP GẠCH MEN SA HA DO | AG6: NVLKX01.001 | AH6: kg
A7: =A6+1 -> 3 | B7: KX/08/01 | C7: Kho xương | D7: 01/08/2026 | E7: =IF(G7="","",VLOOKUP(G7,'Danh mục CODE'!$D$2:$J$20064,7,0)) -> NCC01126 | F7: =IF(E7="","",VLOOKUP(E7,'TONG HOP'!$E$8:$W$1883,19,0)) -> CÔNG TY TNHH MTV DUY THANH LƯƠNG | G7: NVLKX01.052 | H7: =IF(E7="","",VLOOKUP(G7,'TONG HOP'!$C$8:$E$799,2,0)) -> Bột đá Phước Hoà 03 (PH03) DTL | I7: =IF(B7="","",VLOOKUP(G7,'TONG HOP'!$C$8:$F$799,4,0)) -> kg | J7: =IF(X7="","",K7-K7*M7) -> 30960.5 | K7: =IF(AND(X7="",N7="",Q7="",R7=""),"",L7-L7*O7-(L7-L7*O7)*R7) -> 32590 | L7: =X7-Y7 -> 32590 | M7: =IF(Y7="","",VLOOKUP(G7,'Danh mục CODE'!$D$2:$I$1880,4,0)) -> 0.05 | N7: 0.044 | O7: =IF(X7="","",IF(M7-N7<0,-(M7-N7),0)) -> 0 | P7: =IF(Y7="","",VLOOKUP(G7,'Danh mục CODE'!$D$2:$I$1880,5,0)) -> 0 | R7: =IF(X7="","",IF(P7-Q7<0,-(P7-Q7),0)) -> 0 | S7: =IF(T7=0,"",J7-T7-U7) | T7: =IF(X7="","",IF(Q7<P7,K7*Q7,K7*P7)) -> 0 | U7: =IF(X7="","",K7*R7) -> 0 | V7: =IF(X7="","",J7-S7-T7-U7) -> #VALUE! | X7: 49680 | Y7: 17090 | Z7: 1183 | AA7: 60K-73617 | AC7: PND-VC02 NB | AD7: NCC00843 | AE7: CÔNG TY CP GẠCH MEN SA HA DO | AG7: NVLKX01.001 | AH7: kg
A8: =A7+1 -> 4 | B8: KX/08/01 | C8: Kho xương | D8: 01/08/2026 | E8: =IF(G8="","",VLOOKUP(G8,'Danh mục CODE'!$D$2:$J$20064,7,0)) -> NCC01126 | F8: =IF(E8="","",VLOOKUP(E8,'TONG HOP'!$E$8:$W$1883,19,0)) -> CÔNG TY TNHH MTV DUY THANH LƯƠNG | G8: NVLKX01.052 | H8: =IF(E8="","",VLOOKUP(G8,'TONG HOP'!$C$8:$E$799,2,0)) -> Bột đá Phước Hoà 03 (PH03) DTL | I8: =IF(B8="","",VLOOKUP(G8,'TONG HOP'!$C$8:$F$799,4,0)) -> kg | J8: =IF(X8="","",K8-K8*M8) -> 32936.5 | K8: =IF(AND(X8="",N8="",Q8="",R8=""),"",L8-L8*O8-(L8-L8*O8)*R8) -> 34670 | L8: =X8-Y8 -> 34670 | M8: =IF(Y8="","",VLOOKUP(G8,'Danh mục CODE'!$D$2:$I$1880,4,0)) -> 0.05 | N8: 0.044 | O8: =IF(X8="","",IF(M8-N8<0,-(M8-N8),0)) -> 0 | P8: =IF(Y8="","",VLOOKUP(G8,'Danh mục CODE'!$D$2:$I$1880,5,0)) -> 0 | R8: =IF(X8="","",IF(P8-Q8<0,-(P8-Q8),0)) -> 0 | S8: =IF(T8=0,"",J8-T8-U8) | T8: =IF(X8="","",IF(Q8<P8,K8*Q8,K8*P8)) -> 0 | U8: =IF(X8="","",K8*R8) -> 0 | V8: =IF(X8="","",J8-S8-T8-U8) -> #VALUE! | X8: 53070 | Y8: 18400 | Z8: 1191 | AA8: 60K-96870 | AC8: Đất sét Vĩnh Cửu (PND-VC02) | AD8: NCC00844 | AE8: CÔNG TY CP GẠCH MEN SA HA DO | AG8: NVLKX01.001 | AH8: kg
A9: =A8+1 -> 5 | B9: KX/08/01 | C9: Kho xương | D9: 01/08/2026 | E9: =IF(G9="","",VLOOKUP(G9,'Danh mục CODE'!$D$2:$J$20064,7,0)) -> NCC01126 | F9: =IF(E9="","",VLOOKUP(E9,'TONG HOP'!$E$8:$W$1883,19,0)) -> CÔNG TY TNHH MTV DUY THANH LƯƠNG | G9: NVLKX01.052 | H9: =IF(E9="","",VLOOKUP(G9,'TONG HOP'!$C$8:$E$799,2,0)) -> Bột đá Phước Hoà 03 (PH03) DTL | I9: =IF(B9="","",VLOOKUP(G9,'TONG HOP'!$C$8:$F$799,4,0)) -> kg | J9: =IF(X9="","",K9-K9*M9) -> 29298 | K9: =IF(AND(X9="",N9="",Q9="",R9=""),"",L9-L9*O9-(L9-L9*O9)*R9) -> 30840 | L9: =X9-Y9 -> 30840 | M9: =IF(Y9="","",VLOOKUP(G9,'Danh mục CODE'!$D$2:$I$1880,4,0)) -> 0.05 | N9: 0.044 | O9: =IF(X9="","",IF(M9-N9<0,-(M9-N9),0)) -> 0 | P9: =IF(Y9="","",VLOOKUP(G9,'Danh mục CODE'!$D$2:$I$1880,5,0)) -> 0 | R9: =IF(X9="","",IF(P9-Q9<0,-(P9-Q9),0)) -> 0 | S9: =IF(T9=0,"",J9-T9-U9) | T9: =IF(X9="","",IF(Q9<P9,K9*Q9,K9*P9)) -> 0 | U9: =IF(X9="","",K9*R9) -> 0 | V9: =IF(X9="","",J9-S9-T9-U9) -> #VALUE! | X9: 49460 | Y9: 18620 | Z9: 1196 | AA9: 60K-70605 | AC9: Đất sét Vĩnh Cửu (PND-VC04) | AD9: NCC00845 | AE9: CÔNG TY CP GẠCH MEN SA HA DO | AG9: NVLKX01.001 | AH9: kg
A10: =A9+1 -> 6 | B10: KX/08/01 | C10: Kho xương | D10: 01/08/2026 | E10: =IF(G10="","",VLOOKUP(G10,'Danh mục CODE'!$D$2:$J$20064,7,0)) -> NCC01126 | F10: =IF(E10="","",VLOOKUP(E10,'TONG HOP'!$E$8:$W$1883,19,0)) -> CÔNG TY TNHH MTV DUY THANH LƯƠNG | G10: NVLKX01.052 | H10: =IF(E10="","",VLOOKUP(G10,'TONG HOP'!$C$8:$E$799,2,0)) -> Bột đá Phước Hoà 03 (PH03) DTL | I10: =IF(B10="","",VLOOKUP(G10,'TONG HOP'!$C$8:$F$799,4,0)) -> kg | J10: =IF(X10="","",K10-K10*M10) -> 29991.5 | K10: =IF(AND(X10="",N10="",Q10="",R10=""),"",L10-L10*O10-(L10-L10*O10)*R10) -> 31570 | L10: =X10-Y10 -> 31570 | M10: =IF(Y10="","",VLOOKUP(G10,'Danh mục CODE'!$D$2:$I$1880,4,0)) -> 0.05 | N10: 0.044 | O10: =IF(X10="","",IF(M10-N10<0,-(M10-N10),0)) -> 0 | P10: =IF(Y10="","",VLOOKUP(G10,'Danh mục CODE'!$D$2:$I$1880,5,0)) -> 0 | R10: =IF(X10="","",IF(P10-Q10<0,-(P10-Q10),0)) -> 0 | S10: =IF(T10=0,"",J10-T10-U10) | T10: =IF(X10="","",IF(Q10<P10,K10*Q10,K10*P10)) -> 0 | U10: =IF(X10="","",K10*R10) -> 0 | V10: =IF(X10="","",J10-S10-T10-U10) -> #VALUE! | X10: 49530 | Y10: 17960 | Z10: 1198 | AA10: 60H-33761 | AC10: Đất sét Vĩnh Cửu 06 | AD10: NCC00846 | AE10: CÔNG TY CP GẠCH MEN SA HA DO | AG10: NVLKX01.001 | AH10: kg
A11: =A10+1 -> 7 | B11: KX/08/02 | C11: Kho xương | D11: 01/08/2026 | E11: =IF(G11="","",VLOOKUP(G11,'Danh mục CODE'!$D$2:$J$20064,7,0)) -> NCC01126 | F11: =IF(E11="","",VLOOKUP(E11,'TONG HOP'!$E$8:$W$1883,19,0)) -> CÔNG TY TNHH MTV DUY THANH LƯƠNG | G11: NVLKX01.033 | H11: =IF(E11="","",VLOOKUP(G11,'TONG HOP'!$C$8:$E$799,2,0)) -> Đất sét Hoa đào (DTL) BD01 | I11: =IF(B11="","",VLOOKUP(G11,'TONG HOP'!$C$8:$F$799,4,0)) -> kg | J11: =IF(X11="","",K11-K11*M11) -> 26580 | K11: =IF(AND(X11="",N11="",Q11="",R11=""),"",L11-L11*O11-(L11-L11*O11)*R11) -> 35440 | L11: =X11-Y11 -> 35440 | M11: =IF(Y11="","",VLOOKUP(G11,'Danh mục CODE'!$D$2:$I$1880,4,0)) -> 0.25 | N11: 0.19 | O11: =IF(X11="","",IF(M11-N11<0,-(M11-N11),0)) -> 0 | P11: =IF(Y11="","",VLOOKUP(G11,'Danh mục CODE'!$D$2:$I$1880,5,0)) -> 0 | R11: =IF(X11="","",IF(P11-Q11<0,-(P11-Q11),0)) -> 0 | S11: =IF(T11=0,"",J11-T11-U11) | T11: =IF(X11="","",IF(Q11<P11,K11*Q11,K11*P11)) -> 0 | U11: =IF(X11="","",K11*R11) -> 0 | V11: =IF(X11="","",J11-S11-T11-U11) -> #VALUE! | X11: 51800 | Y11: 16360 | Z11: 1193 | AA11: 60C-21187 | AC11: Đất sét Vĩnh Cửu 07 | AD11: NCC00847 | AE11: CÔNG TY CP GẠCH MEN SA HA DO | AG11: NVLKX01.001 | AH11: kg
A12: =A11+1 -> 8 | B12: KX/08/02 | C12: Kho xương | D12: 01/08/2026 | E12: =IF(G12="","",VLOOKUP(G12,'Danh mục CODE'!$D$2:$J$20064,7,0)) -> NCC01126 | F12: =IF(E12="","",VLOOKUP(E12,'TONG HOP'!$E$8:$W$1883,19,0)) -> CÔNG TY TNHH MTV DUY THANH LƯƠNG | G12: NVLKX01.033 | H12: =IF(E12="","",VLOOKUP(G12,'TONG HOP'!$C$8:$E$799,2,0)) -> Đất sét Hoa đào (DTL) BD01 | I12: =IF(B12="","",VLOOKUP(G12,'TONG HOP'!$C$8:$F$799,4,0)) -> kg | J12: =IF(X12="","",K12-K12*M12) -> 27360 | K12: =IF(AND(X12="",N12="",Q12="",R12=""),"",L12-L12*O12-(L12-L12*O12)*R12) -> 36480 | L12: =X12-Y12 -> 36480 | M12: =IF(Y12="","",VLOOKUP(G12,'Danh mục CODE'!$D$2:$I$1880,4,0)) -> 0.25 | N12: 0.19 | O12: =IF(X12="","",IF(M12-N12<0,-(M12-N12),0)) -> 0 | P12: =IF(Y12="","",VLOOKUP(G12,'Danh mục CODE'!$D$2:$I$1880,5,0)) -> 0 | R12: =IF(X12="","",IF(P12-Q12<0,-(P12-Q12),0)) -> 0 | S12: =IF(T12=0,"",J12-T12-U12) | T12: =IF(X12="","",IF(Q12<P12,K12*Q12,K12*P12)) -> 0 | U12: =IF(X12="","",K12*R12) -> 0 | V12: =IF(X12="","",J12-S12-T12-U12) -> #VALUE! | X12: 54390 | Y12: 17910 | Z12: 1200 | AA12: 60C-68268 | AC12: Đất sét Vĩnh Cửu 05 | AD12: NCC00848 | AE12: CÔNG TY CP GẠCH MEN SA HA DO | AG12: NVLKX01.001 | AH12: kg
A13: =A12+1 -> 9 | B13: KX/08/02 | C13: Kho xương | D13: 01/08/2026 | E13: =IF(G13="","",VLOOKUP(G13,'Danh mục CODE'!$D$2:$J$20064,7,0)) -> NCC01126 | F13: =IF(E13="","",VLOOKUP(E13,'TONG HOP'!$E$8:$W$1883,19,0)) -> CÔNG TY TNHH MTV DUY THANH LƯƠNG | G13: NVLKX01.033 | H13: =IF(E13="","",VLOOKUP(G13,'TONG HOP'!$C$8:$E$799,2,0)) -> Đất sét Hoa đào (DTL) BD01 | I13: =IF(B13="","",VLOOKUP(G13,'TONG HOP'!$C$8:$F$799,4,0)) -> kg | J13: =IF(X13="","",K13-K13*M13) -> 25612.5 | K13: =IF(AND(X13="",N13="",Q13="",R13=""),"",L13-L13*O13-(L13-L13*O13)*R13) -> 34150 | L13: =X13-Y13 -> 34150 | M13: =IF(Y13="","",VLOOKUP(G13,'Danh mục CODE'!$D$2:$I$1880,4,0)) -> 0.25 | N13: 0.19 | O13: =IF(X13="","",IF(M13-N13<0,-(M13-N13),0)) -> 0 | P13: =IF(Y13="","",VLOOKUP(G13,'Danh mục CODE'!$D$2:$I$1880,5,0)) -> 0 | R13: =IF(X13="","",IF(P13-Q13<0,-(P13-Q13),0)) -> 0 | S13: =IF(T13=0,"",J13-T13-U13) | T13: =IF(X13="","",IF(Q13<P13,K13*Q13,K13*P13)) -> 0 | U13: =IF(X13="","",K13*R13) -> 0 | V13: =IF(X13="","",J13-S13-T13-U13) -> #VALUE! | X13: 53890 | Y13: 19740 | Z13: 1201 | AA13: 60H-05962 | AC13: Đất sét Vĩnh Cửu NỘI BỘ 1 | AD13: NCC00849 | AE13: CÔNG TY CP GẠCH MEN SA HA DO | AG13: NVLKX01.001 | AH13: kg
A14: =A13+1 -> 10 | B14: KX/08/03 | C14: Kho xương | D14: 01/08/2026 | E14: =IF(G14="","",VLOOKUP(G14,'Danh mục CODE'!$D$2:$J$20064,7,0)) -> NCC01126 | F14: =IF(E14="","",VLOOKUP(E14,'TONG HOP'!$E$8:$W$1883,19,0)) -> CÔNG TY TNHH MTV DUY THANH LƯƠNG | G14: NVLKX01.052 | H14: =IF(E14="","",VLOOKUP(G14,'TONG HOP'!$C$8:$E$799,2,0)) -> Bột đá Phước Hoà 03 (PH03) DTL | I14: =IF(B14="","",VLOOKUP(G14,'TONG HOP'!$C$8:$F$799,4,0)) -> kg | J14: =IF(X14="","",K14-K14*M14) -> 31559 | K14: =IF(AND(X14="",N14="",Q14="",R14=""),"",L14-L14*O14-(L14-L14*O14)*R14) -> 33220 | L14: =X14-Y14 -> 33220 | M14: =IF(Y14="","",VLOOKUP(G14,'Danh mục CODE'!$D$2:$I$1880,4,0)) -> 0.05 | N14: 0.043 | O14: =IF(X14="","",IF(M14-N14<0,-(M14-N14),0)) -> 0 | P14: =IF(Y14="","",VLOOKUP(G14,'Danh mục CODE'!$D$2:$I$1880,5,0)) -> 0 | R14: =IF(X14="","",IF(P14-Q14<0,-(P14-Q14),0)) -> 0 | S14: =IF(T14=0,"",J14-T14-U14) | T14: =IF(X14="","",IF(Q14<P14,K14*Q14,K14*P14)) -> 0 | U14: =IF(X14="","",K14*R14) -> 0 | V14: =IF(X14="","",J14-S14-T14-U14) -> #VALUE! | X14: 51760 | Y14: 18540 | Z14: 1212 | AA14: 60K-70605 | AC14: Đất sét làm gạch (PND-LD01) | AG14: NVLKX01.022 | AH14: kg
A15: =A14+1 -> 11 | B15: KX/08/03 | C15: Kho xương | D15: 01/08/2026 | E15: =IF(G15="","",VLOOKUP(G15,'Danh mục CODE'!$D$2:$J$20064,7,0)) -> NCC01126 | F15: =IF(E15="","",VLOOKUP(E15,'TONG HOP'!$E$8:$W$1883,19,0)) -> CÔNG TY TNHH MTV DUY THANH LƯƠNG | G15: NVLKX01.052 | H15: =IF(E15="","",VLOOKUP(G15,'TONG HOP'!$C$8:$E$799,2,0)) -> Bột đá Phước Hoà 03 (PH03) DTL | I15: =IF(B15="","",VLOOKUP(G15,'TONG HOP'!$C$8:$F$799,4,0)) -> kg | J15: =IF(X15="","",K15-K15*M15) -> 33250 | K15: =IF(AND(X15="",N15="",Q15="",R15=""),"",L15-L15*O15-(L15-L15*O15)*R15) -> 35000 | L15: =X15-Y15 -> 35000 | M15: =IF(Y15="","",VLOOKUP(G15,'Danh mục CODE'!$D$2:$I$1880,4,0)) -> 0.05 | N15: 0.043 | O15: =IF(X15="","",IF(M15-N15<0,-(M15-N15),0)) -> 0 | P15: =IF(Y15="","",VLOOKUP(G15,'Danh mục CODE'!$D$2:$I$1880,5,0)) -> 0 | R15: =IF(X15="","",IF(P15-Q15<0,-(P15-Q15),0)) -> 0 | S15: =IF(T15=0,"",J15-T15-U15) | T15: =IF(X15="","",IF(Q15<P15,K15*Q15,K15*P15)) -> 0 | U15: =IF(X15="","",K15*R15) -> 0 | V15: =IF(X15="","",J15-S15-T15-U15) -> #VALUE! | X15: 53650 | Y15: 18650 | Z15: 1215 | AA15: 60K-96870 | AC15: Đất sét làm gạch (PND-LD04) | AG15: NVLKX01.022 | AH15: kg
A16: =A15+1 -> 12 | B16: KX/08/03 | C16: Kho xương | D16: 01/08/2026 | E16: =IF(G16="","",VLOOKUP(G16,'Danh mục CODE'!$D$2:$J$20064,7,0)) -> NCC01126 | F16: =IF(E16="","",VLOOKUP(E16,'TONG HOP'!$E$8:$W$1883,19,0)) -> CÔNG TY TNHH MTV DUY THANH LƯƠNG | G16: NVLKX01.052 | H16: =IF(E16="","",VLOOKUP(G16,'TONG HOP'!$C$8:$E$799,2,0)) -> Bột đá Phước Hoà 03 (PH03) DTL | I16: =IF(B16="","",VLOOKUP(G16,'TONG HOP'!$C$8:$F$799,4,0)) -> kg | J16: =IF(X16="","",K16-K16*M16) -> 33069.5 | K16: =IF(AND(X16="",N16="",Q16="",R16=""),"",L16-L16*O16-(L16-L16*O16)*R16) -> 34810 | L16: =X16-Y16 -> 34810 | M16: =IF(Y16="","",VLOOKUP(G16,'Danh mục CODE'!$D$2:$I$1880,4,0)) -> 0.05 | N16: 0.043 | O16: =IF(X16="","",IF(M16-N16<0,-(M16-N16),0)) -> 0 | P16: =IF(Y16="","",VLOOKUP(G16,'Danh mục CODE'!$D$2:$I$1880,5,0)) -> 0 | R16: =IF(X16="","",IF(P16-Q16<0,-(P16-Q16),0)) -> 0 | S16: =IF(T16=0,"",J16-T16-U16) | T16: =IF(X16="","",IF(Q16<P16,K16*Q16,K16*P16)) -> 0 | U16: =IF(X16="","",K16*R16) -> 0 | V16: =IF(X16="","",J16-S16-T16-U16) -> #VALUE! | X16: 52690 | Y16: 17880 | Z16: 1217 | AA16: 60C-68268 | AC16: Đất sét làm gạch (PND-LD05) | AG16: NVLKX01.022 | AH16: kg
A17: =A16+1 -> 13 | B17: KX/08/03 | C17: Kho xương | D17: 01/08/2026 | E17: =IF(G17="","",VLOOKUP(G17,'Danh mục CODE'!$D$2:$J$20064,7,0)) -> NCC01126 | F17: =IF(E17="","",VLOOKUP(E17,'TONG HOP'!$E$8:$W$1883,19,0)) -> CÔNG TY TNHH MTV DUY THANH LƯƠNG | G17: NVLKX01.052 | H17: =IF(E17="","",VLOOKUP(G17,'TONG HOP'!$C$8:$E$799,2,0)) -> Bột đá Phước Hoà 03 (PH03) DTL | I17: =IF(B17="","",VLOOKUP(G17,'TONG HOP'!$C$8:$F$799,4,0)) -> kg | J17: =IF(X17="","",K17-K17*M17) -> 32034 | K17: =IF(AND(X17="",N17="",Q17="",R17=""),"",L17-L17*O17-(L17-L17*O17)*R17) -> 33720 | L17: =X17-Y17 -> 33720 | M17: =IF(Y17="","",VLOOKUP(G17,'Danh mục CODE'!$D$2:$I$1880,4,0)) -> 0.05 | N17: 0.043 | O17: =IF(X17="","",IF(M17-N17<0,-(M17-N17),0)) -> 0 | P17: =IF(Y17="","",VLOOKUP(G17,'Danh mục CODE'!$D$2:$I$1880,5,0)) -> 0 | R17: =IF(X17="","",IF(P17-Q17<0,-(P17-Q17),0)) -> 0 | S17: =IF(T17=0,"",J17-T17-U17) | T17: =IF(X17="","",IF(Q17<P17,K17*Q17,K17*P17)) -> 0 | U17: =IF(X17="","",K17*R17) -> 0 | V17: =IF(X17="","",J17-S17-T17-U17) -> #VALUE! | X17: 52140 | Y17: 18420 | Z17: 1220 | AA17: 60H-05534 | AC17: ĐẤT SÉT HỒNG LQ (PND-BL01) | AD17: NCC01210 | AE17: CÔNG TY TNHH LONG QUANG LH | AG17: NVLKX01.032 | AH17: kg
A18: =A17+1 -> 14 | B18: KX/08/04 | C18: Kho xương | D18: 01/08/2026 | E18: =IF(G18="","",VLOOKUP(G18,'Danh mục CODE'!$D$2:$J$20064,7,0)) -> NCC01126 | F18: =IF(E18="","",VLOOKUP(E18,'TONG HOP'!$E$8:$W$1883,19,0)) -> CÔNG TY TNHH MTV DUY THANH LƯƠNG | G18: NVLKX01.052 | H18: =IF(E18="","",VLOOKUP(G18,'TONG HOP'!$C$8:$E$799,2,0)) -> Bột đá Phước Hoà 03 (PH03) DTL | I18: =IF(B18="","",VLOOKUP(G18,'TONG HOP'!$C$8:$F$799,4,0)) -> kg | J18: =IF(X18="","",K18-K18*M18) -> 28490.5 | K18: =IF(AND(X18="",N18="",Q18="",R18=""),"",L18-L18*O18-(L18-L18*O18)*R18) -> 29990 | L18: =X18-Y18 -> 29990 | M18: =IF(Y18="","",VLOOKUP(G18,'Danh mục CODE'!$D$2:$I$1880,4,0)) -> 0.05 | N18: 0.042 | O18: =IF(X18="","",IF(M18-N18<0,-(M18-N18),0)) -> 0 | P18: =IF(Y18="","",VLOOKUP(G18,'Danh mục CODE'!$D$2:$I$1880,5,0)) -> 0 | R18: =IF(X18="","",IF(P18-Q18<0,-(P18-Q18),0)) -> 0 | S18: =IF(T18=0,"",J18-T18-U18) | T18: =IF(X18="","",IF(Q18<P18,K18*Q18,K18*P18)) -> 0 | U18: =IF(X18="","",K18*R18) -> 0 | V18: =IF(X18="","",J18-S18-T18-U18) -> #VALUE! | X18: 49700 | Y18: 19710 | Z18: 1272 | AA18: 60H-05962 | AC18: ĐẤT SÉT HOA ĐÀO (PND-BD01) | AD18: NCC01126 | AE18: DOANH NGHIỆP TƯ NHÂN DUY THANH LƯƠNG | AG18: NVLKX01.043 | AH18: kg
A19: =A18+1 -> 15 | B19: KX/08/04 | C19: Kho xương | D19: 01/08/2026 | E19: =IF(G19="","",VLOOKUP(G19,'Danh mục CODE'!$D$2:$J$20064,7,0)) -> NCC01126 | F19: =IF(E19="","",VLOOKUP(E19,'TONG HOP'!$E$8:$W$1883,19,0)) -> CÔNG TY TNHH MTV DUY THANH LƯƠNG | G19: NVLKX01.052 | H19: =IF(E19="","",VLOOKUP(G19,'TONG HOP'!$C$8:$E$799,2,0)) -> Bột đá Phước Hoà 03 (PH03) DTL | I19: =IF(B19="","",VLOOKUP(G19,'TONG HOP'!$C$8:$F$799,4,0)) -> kg | J19: =IF(X19="","",K19-K19*M19) -> 30941.5 | K19: =IF(AND(X19="",N19="",Q19="",R19=""),"",L19-L19*O19-(L19-L19*O19)*R19) -> 32570 | L19: =X19-Y19 -> 32570 | M19: =IF(Y19="","",VLOOKUP(G19,'Danh mục CODE'!$D$2:$I$1880,4,0)) -> 0.05 | N19: 0.042 | O19: =IF(X19="","",IF(M19-N19<0,-(M19-N19),0)) -> 0 | P19: =IF(Y19="","",VLOOKUP(G19,'Danh mục CODE'!$D$2:$I$1880,5,0)) -> 0 | R19: =IF(X19="","",IF(P19-Q19<0,-(P19-Q19),0)) -> 0 | S19: =IF(T19=0,"",J19-T19-U19) | T19: =IF(X19="","",IF(Q19<P19,K19*Q19,K19*P19)) -> 0 | U19: =IF(X19="","",K19*R19) -> 0 | V19: =IF(X19="","",J19-S19-T19-U19) -> #VALUE! | X19: 48910 | Y19: 16340 | Z19: 1273 | AA19: 60C-21187 | AC19: Đất sét hoa đào(BD02) LHP | AD19: NCC01126 | AE19: DOANH NGHIỆP TƯ NHÂN DUY THANH LƯƠNG | AG19: NVLKX01.043 | AH19: kg
